<mujoco>
    <include file="materials.xml"/>
    <compiler angle="degree" coordinate="local" inertiafromgeom="true"/>
    <option iterations="50" timestep="0.005000" tolerance="0.000000" cone="pyramidal" jacobian="dense" solver="Newton"/>
    <size nconmax="4000" njmax="8000"/>
    <statistic extent="2.000000" center="0.000000 0.000000 1.000000"/>
    <asset>
        <texture height="512" width="512" rgb1="0.300000 0.500000 0.700000" rgb2="0.000000 0.000000 0.000000" builtin="gradient" type="skybox"/>
        <texture height="512" width="512" markrgb="0.800000 0.800000 0.800000" rgb1="0.200000 0.300000 0.400000" rgb2="0.100000 0.150000 0.200000" builtin="checker" mark="cross" name="texplane" type="2d"/>
        <texture height="1278" width="127" random="0.010000" markrgb="1.000000 1.000000 1.000000" rgb1="0.800000 0.600000 0.400000" rgb2="0.800000 0.600000 0.400000" builtin="flat" mark="cross" name="texgeom" type="cube"/>
        <material reflectance="0.300000" texrepeat="1.000000 1.000000" name="matplane" texture="texplane" texuniform="true"/>
        <material rgba="0.800000 0.600000 0.400000 1.000000" name="matgeom" texture="texgeom" texuniform="true"/>
    </asset>
    <contact/>
    <visual>
        <map force="0.100000" zfar="30.000000"/>
        <rgba haze="0.150000 0.250000 0.350000 1.000000"/>
        <quality shadowsize="2048"/>
        <global offheight="800" offwidth="800"/>
    </visual>
    <worldbody>
        <body pos="0.000000 0.000000 100.000000" quat="0.000000 0.000000 0.000000 1.000000" name="terrainGen_terrain_proc0_0">
            <geom conaffinity="1" contype="0" mass="1.000000" pos="0.000000 0.000000 0.000000" quat="0.000000 0.000000 0.000000 1.000000" size="0.250000 1.000000 0.012500" name="terrainGen_terrain_proc0_0" type="box"/>
        </body>
        <body pos="0.000000 0.000000 101.025002" quat="0.000000 0.000000 0.000000 1.000000" name="terrainGen_terrain_proc0_1">
            <geom conaffinity="1" contype="0" mass="1.000000" pos="0.000000 0.000000 0.000000" quat="0.000000 0.000000 0.000000 1.000000" size="0.250000 1.000000 0.012500" name="terrainGen_terrain_proc0_1" type="box"/>
        </body>
        <body pos="0.000000 0.000000 102.050003" quat="0.000000 0.000000 0.000000 1.000000" name="terrainGen_terrain_proc0_2">
            <geom conaffinity="1" contype="0" mass="1.000000" pos="0.000000 0.000000 0.000000" quat="0.000000 0.000000 0.000000 1.000000" size="0.250000 1.000000 0.012500" name="terrainGen_terrain_proc0_2" type="box"/>
        </body>
        <body pos="0.000000 0.000000 103.074997" quat="0.000000 0.000000 0.000000 1.000000" name="terrainGen_terrain_proc0_3">
            <geom conaffinity="1" contype="0" mass="1.000000" pos="0.000000 0.000000 0.000000" quat="0.000000 0.000000 0.000000 1.000000" size="0.250000 1.000000 0.012500" name="terrainGen_terrain_proc0_3" type="box"/>
        </body>
        <body pos="0.000000 0.000000 104.099998" quat="0.000000 0.000000 0.000000 1.000000" name="terrainGen_terrain_proc0_4">
            <geom conaffinity="1" contype="0" mass="1.000000" pos="0.000000 0.000000 0.000000" quat="0.000000 0.000000 0.000000 1.000000" size="0.250000 1.000000 0.012500" name="terrainGen_terrain_proc0_4" type="box"/>
        </body>
        <body pos="0.000000 0.000000 105.125000" quat="0.000000 0.000000 0.000000 1.000000" name="terrainGen_terrain_proc0_5">
            <geom conaffinity="1" contype="0" mass="1.000000" pos="0.000000 0.000000 0.000000" quat="0.000000 0.000000 0.000000 1.000000" size="0.250000 1.000000 0.012500" name="terrainGen_terrain_proc0_5" type="box"/>
        </body>
        <body pos="0.000000 0.000000 106.150002" quat="0.000000 0.000000 0.000000 1.000000" name="terrainGen_terrain_proc0_6">
            <geom conaffinity="1" contype="0" mass="1.000000" pos="0.000000 0.000000 0.000000" quat="0.000000 0.000000 0.000000 1.000000" size="0.250000 1.000000 0.012500" name="terrainGen_terrain_proc0_6" type="box"/>
        </body>
        <body pos="0.000000 0.000000 107.175003" quat="0.000000 0.000000 0.000000 1.000000" name="terrainGen_terrain_proc0_7">
            <geom conaffinity="1" contype="0" mass="1.000000" pos="0.000000 0.000000 0.000000" quat="0.000000 0.000000 0.000000 1.000000" size="0.250000 1.000000 0.012500" name="terrainGen_terrain_proc0_7" type="box"/>
        </body>
        <body pos="0.000000 0.000000 108.199997" quat="0.000000 0.000000 0.000000 1.000000" name="terrainGen_terrain_proc0_8">
            <geom conaffinity="1" contype="0" mass="1.000000" pos="0.000000 0.000000 0.000000" quat="0.000000 0.000000 0.000000 1.000000" size="0.250000 1.000000 0.012500" name="terrainGen_terrain_proc0_8" type="box"/>
        </body>
        <body pos="0.000000 0.000000 109.224998" quat="0.000000 0.000000 0.000000 1.000000" name="terrainGen_terrain_proc0_9">
            <geom conaffinity="1" contype="0" mass="1.000000" pos="0.000000 0.000000 0.000000" quat="0.000000 0.000000 0.000000 1.000000" size="0.250000 1.000000 0.012500" name="terrainGen_terrain_proc0_9" type="box"/>
        </body>
        <body pos="0.000000 0.000000 110.250000" quat="0.000000 0.000000 0.000000 1.000000" name="terrainGen_terrain_proc0_10">
            <geom conaffinity="1" contype="0" mass="1.000000" pos="0.000000 0.000000 0.000000" quat="0.000000 0.000000 0.000000 1.000000" size="0.250000 1.000000 0.012500" name="terrainGen_terrain_proc0_10" type="box"/>
        </body>
        <body pos="0.000000 0.000000 111.275002" quat="0.000000 0.000000 0.000000 1.000000" name="terrainGen_terrain_proc0_11">
            <geom conaffinity="1" contype="0" mass="1.000000" pos="0.000000 0.000000 0.000000" quat="0.000000 0.000000 0.000000 1.000000" size="0.250000 1.000000 0.012500" name="terrainGen_terrain_proc0_11" type="box"/>
        </body>
        <body pos="0.000000 0.000000 112.300003" quat="0.000000 0.000000 0.000000 1.000000" name="terrainGen_terrain_proc0_12">
            <geom conaffinity="1" contype="0" mass="1.000000" pos="0.000000 0.000000 0.000000" quat="0.000000 0.000000 0.000000 1.000000" size="0.250000 1.000000 0.012500" name="terrainGen_terrain_proc0_12" type="box"/>
        </body>
        <body pos="0.000000 0.000000 113.324997" quat="0.000000 0.000000 0.000000 1.000000" name="terrainGen_terrain_proc0_13">
            <geom conaffinity="1" contype="0" mass="1.000000" pos="0.000000 0.000000 0.000000" quat="0.000000 0.000000 0.000000 1.000000" size="0.250000 1.000000 0.012500" name="terrainGen_terrain_proc0_13" type="box"/>
        </body>
        <body pos="0.000000 0.000000 114.349998" quat="0.000000 0.000000 0.000000 1.000000" name="terrainGen_terrain_proc0_14">
            <geom conaffinity="1" contype="0" mass="1.000000" pos="0.000000 0.000000 0.000000" quat="0.000000 0.000000 0.000000 1.000000" size="0.250000 1.000000 0.012500" name="terrainGen_terrain_proc0_14" type="box"/>
        </body>
        <body pos="0.000000 0.000000 115.375000" quat="0.000000 0.000000 0.000000 1.000000" name="terrainGen_terrain_proc0_15">
            <geom conaffinity="1" contype="0" mass="1.000000" pos="0.000000 0.000000 0.000000" quat="0.000000 0.000000 0.000000 1.000000" size="0.250000 1.000000 0.012500" name="terrainGen_terrain_proc0_15" type="box"/>
        </body>
        <body pos="0.000000 0.000000 116.400002" quat="0.000000 0.000000 0.000000 1.000000" name="terrainGen_terrain_proc0_16">
            <geom conaffinity="1" contype="0" mass="1.000000" pos="0.000000 0.000000 0.000000" quat="0.000000 0.000000 0.000000 1.000000" size="0.250000 1.000000 0.012500" name="terrainGen_terrain_proc0_16" type="box"/>
        </body>
        <body pos="0.000000 0.000000 117.425003" quat="0.000000 0.000000 0.000000 1.000000" name="terrainGen_terrain_proc0_17">
            <geom conaffinity="1" contype="0" mass="1.000000" pos="0.000000 0.000000 0.000000" quat="0.000000 0.000000 0.000000 1.000000" size="0.250000 1.000000 0.012500" name="terrainGen_terrain_proc0_17" type="box"/>
        </body>
        <body pos="0.000000 0.000000 118.449997" quat="0.000000 0.000000 0.000000 1.000000" name="terrainGen_terrain_proc0_18">
            <geom conaffinity="1" contype="0" mass="1.000000" pos="0.000000 0.000000 0.000000" quat="0.000000 0.000000 0.000000 1.000000" size="0.250000 1.000000 0.012500" name="terrainGen_terrain_proc0_18" type="box"/>
        </body>
        <body pos="0.000000 0.000000 119.474998" quat="0.000000 0.000000 0.000000 1.000000" name="terrainGen_terrain_proc0_19">
            <geom conaffinity="1" contype="0" mass="1.000000" pos="0.000000 0.000000 0.000000" quat="0.000000 0.000000 0.000000 1.000000" size="0.250000 1.000000 0.012500" name="terrainGen_terrain_proc0_19" type="box"/>
        </body>
        <body pos="0.000000 0.000000 120.500000" quat="0.000000 0.000000 0.000000 1.000000" name="terrainGen_terrain_proc0_20">
            <geom conaffinity="1" contype="0" mass="1.000000" pos="0.000000 0.000000 0.000000" quat="0.000000 0.000000 0.000000 1.000000" size="0.250000 1.000000 0.012500" name="terrainGen_terrain_proc0_20" type="box"/>
        </body>
        <body pos="0.000000 0.000000 121.525002" quat="0.000000 0.000000 0.000000 1.000000" name="terrainGen_terrain_proc0_21">
            <geom conaffinity="1" contype="0" mass="1.000000" pos="0.000000 0.000000 0.000000" quat="0.000000 0.000000 0.000000 1.000000" size="0.250000 1.000000 0.012500" name="terrainGen_terrain_proc0_21" type="box"/>
        </body>
        <body pos="0.000000 0.000000 122.550003" quat="0.000000 0.000000 0.000000 1.000000" name="terrainGen_terrain_proc0_22">
            <geom conaffinity="1" contype="0" mass="1.000000" pos="0.000000 0.000000 0.000000" quat="0.000000 0.000000 0.000000 1.000000" size="0.250000 1.000000 0.012500" name="terrainGen_terrain_proc0_22" type="box"/>
        </body>
        <body pos="0.000000 0.000000 123.574997" quat="0.000000 0.000000 0.000000 1.000000" name="terrainGen_terrain_proc0_23">
            <geom conaffinity="1" contype="0" mass="1.000000" pos="0.000000 0.000000 0.000000" quat="0.000000 0.000000 0.000000 1.000000" size="0.250000 1.000000 0.012500" name="terrainGen_terrain_proc0_23" type="box"/>
        </body>
        <body pos="0.000000 0.000000 124.599998" quat="0.000000 0.000000 0.000000 1.000000" name="terrainGen_terrain_proc0_24">
            <geom conaffinity="1" contype="0" mass="1.000000" pos="0.000000 0.000000 0.000000" quat="0.000000 0.000000 0.000000 1.000000" size="0.250000 1.000000 0.012500" name="terrainGen_terrain_proc0_24" type="box"/>
        </body>
        <body pos="0.000000 0.000000 125.625000" quat="0.000000 0.000000 0.000000 1.000000" name="terrainGen_terrain_proc0_25">
            <geom conaffinity="1" contype="0" mass="1.000000" pos="0.000000 0.000000 0.000000" quat="0.000000 0.000000 0.000000 1.000000" size="0.250000 1.000000 0.012500" name="terrainGen_terrain_proc0_25" type="box"/>
        </body>
        <body pos="0.000000 0.000000 126.650002" quat="0.000000 0.000000 0.000000 1.000000" name="terrainGen_terrain_proc0_26">
            <geom conaffinity="1" contype="0" mass="1.000000" pos="0.000000 0.000000 0.000000" quat="0.000000 0.000000 0.000000 1.000000" size="0.250000 1.000000 0.012500" name="terrainGen_terrain_proc0_26" type="box"/>
        </body>
        <body pos="0.000000 0.000000 127.675003" quat="0.000000 0.000000 0.000000 1.000000" name="terrainGen_terrain_proc0_27">
            <geom conaffinity="1" contype="0" mass="1.000000" pos="0.000000 0.000000 0.000000" quat="0.000000 0.000000 0.000000 1.000000" size="0.250000 1.000000 0.012500" name="terrainGen_terrain_proc0_27" type="box"/>
        </body>
        <body pos="0.000000 0.000000 128.699997" quat="0.000000 0.000000 0.000000 1.000000" name="terrainGen_terrain_proc0_28">
            <geom conaffinity="1" contype="0" mass="1.000000" pos="0.000000 0.000000 0.000000" quat="0.000000 0.000000 0.000000 1.000000" size="0.250000 1.000000 0.012500" name="terrainGen_terrain_proc0_28" type="box"/>
        </body>
        <body pos="0.000000 0.000000 129.725006" quat="0.000000 0.000000 0.000000 1.000000" name="terrainGen_terrain_proc0_29">
            <geom conaffinity="1" contype="0" mass="1.000000" pos="0.000000 0.000000 0.000000" quat="0.000000 0.000000 0.000000 1.000000" size="0.250000 1.000000 0.012500" name="terrainGen_terrain_proc0_29" type="box"/>
        </body>
        <body pos="0.000000 0.000000 130.750000" quat="0.000000 0.000000 0.000000 1.000000" name="terrainGen_terrain_proc0_30">
            <geom conaffinity="1" contype="0" mass="1.000000" pos="0.000000 0.000000 0.000000" quat="0.000000 0.000000 0.000000 1.000000" size="0.250000 1.000000 0.012500" name="terrainGen_terrain_proc0_30" type="box"/>
        </body>
        <body pos="0.000000 0.000000 131.774994" quat="0.000000 0.000000 0.000000 1.000000" name="terrainGen_terrain_proc0_31">
            <geom conaffinity="1" contype="0" mass="1.000000" pos="0.000000 0.000000 0.000000" quat="0.000000 0.000000 0.000000 1.000000" size="0.250000 1.000000 0.012500" name="terrainGen_terrain_proc0_31" type="box"/>
        </body>
        <body pos="0.000000 0.000000 132.800003" quat="0.000000 0.000000 0.000000 1.000000" name="terrainGen_terrain_proc0_32">
            <geom conaffinity="1" contype="0" mass="1.000000" pos="0.000000 0.000000 0.000000" quat="0.000000 0.000000 0.000000 1.000000" size="0.250000 1.000000 0.012500" name="terrainGen_terrain_proc0_32" type="box"/>
        </body>
        <body pos="0.000000 0.000000 133.824997" quat="0.000000 0.000000 0.000000 1.000000" name="terrainGen_terrain_proc0_33">
            <geom conaffinity="1" contype="0" mass="1.000000" pos="0.000000 0.000000 0.000000" quat="0.000000 0.000000 0.000000 1.000000" size="0.250000 1.000000 0.012500" name="terrainGen_terrain_proc0_33" type="box"/>
        </body>
        <body pos="0.000000 0.000000 134.850006" quat="0.000000 0.000000 0.000000 1.000000" name="terrainGen_terrain_proc0_34">
            <geom conaffinity="1" contype="0" mass="1.000000" pos="0.000000 0.000000 0.000000" quat="0.000000 0.000000 0.000000 1.000000" size="0.250000 1.000000 0.012500" name="terrainGen_terrain_proc0_34" type="box"/>
        </body>
        <body pos="0.000000 0.000000 135.875000" quat="0.000000 0.000000 0.000000 1.000000" name="terrainGen_terrain_proc0_35">
            <geom conaffinity="1" contype="0" mass="1.000000" pos="0.000000 0.000000 0.000000" quat="0.000000 0.000000 0.000000 1.000000" size="0.250000 1.000000 0.012500" name="terrainGen_terrain_proc0_35" type="box"/>
        </body>
        <body pos="0.000000 0.000000 136.899994" quat="0.000000 0.000000 0.000000 1.000000" name="terrainGen_terrain_proc0_36">
            <geom conaffinity="1" contype="0" mass="1.000000" pos="0.000000 0.000000 0.000000" quat="0.000000 0.000000 0.000000 1.000000" size="0.250000 1.000000 0.012500" name="terrainGen_terrain_proc0_36" type="box"/>
        </body>
        <body pos="0.000000 0.000000 137.925003" quat="0.000000 0.000000 0.000000 1.000000" name="terrainGen_terrain_proc0_37">
            <geom conaffinity="1" contype="0" mass="1.000000" pos="0.000000 0.000000 0.000000" quat="0.000000 0.000000 0.000000 1.000000" size="0.250000 1.000000 0.012500" name="terrainGen_terrain_proc0_37" type="box"/>
        </body>
        <body pos="0.000000 0.000000 138.949997" quat="0.000000 0.000000 0.000000 1.000000" name="terrainGen_terrain_proc0_38">
            <geom conaffinity="1" contype="0" mass="1.000000" pos="0.000000 0.000000 0.000000" quat="0.000000 0.000000 0.000000 1.000000" size="0.250000 1.000000 0.012500" name="terrainGen_terrain_proc0_38" type="box"/>
        </body>
        <body pos="0.000000 0.000000 139.975006" quat="0.000000 0.000000 0.000000 1.000000" name="terrainGen_terrain_proc0_39">
            <geom conaffinity="1" contype="0" mass="1.000000" pos="0.000000 0.000000 0.000000" quat="0.000000 0.000000 0.000000 1.000000" size="0.250000 1.000000 0.012500" name="terrainGen_terrain_proc0_39" type="box"/>
        </body>
        <body pos="0.000000 0.000000 141.000000" quat="0.000000 0.000000 0.000000 1.000000" name="terrainGen_terrain_proc0_40">
            <geom conaffinity="1" contype="0" mass="1.000000" pos="0.000000 0.000000 0.000000" quat="0.000000 0.000000 0.000000 1.000000" size="0.250000 1.000000 0.012500" name="terrainGen_terrain_proc0_40" type="box"/>
        </body>
        <body pos="0.000000 0.000000 142.024994" quat="0.000000 0.000000 0.000000 1.000000" name="terrainGen_terrain_proc0_41">
            <geom conaffinity="1" contype="0" mass="1.000000" pos="0.000000 0.000000 0.000000" quat="0.000000 0.000000 0.000000 1.000000" size="0.250000 1.000000 0.012500" name="terrainGen_terrain_proc0_41" type="box"/>
        </body>
        <body pos="0.000000 0.000000 143.050003" quat="0.000000 0.000000 0.000000 1.000000" name="terrainGen_terrain_proc0_42">
            <geom conaffinity="1" contype="0" mass="1.000000" pos="0.000000 0.000000 0.000000" quat="0.000000 0.000000 0.000000 1.000000" size="0.250000 1.000000 0.012500" name="terrainGen_terrain_proc0_42" type="box"/>
        </body>
        <body pos="0.000000 0.000000 144.074997" quat="0.000000 0.000000 0.000000 1.000000" name="terrainGen_terrain_proc0_43">
            <geom conaffinity="1" contype="0" mass="1.000000" pos="0.000000 0.000000 0.000000" quat="0.000000 0.000000 0.000000 1.000000" size="0.250000 1.000000 0.012500" name="terrainGen_terrain_proc0_43" type="box"/>
        </body>
        <body pos="0.000000 0.000000 145.100006" quat="0.000000 0.000000 0.000000 1.000000" name="terrainGen_terrain_proc0_44">
            <geom conaffinity="1" contype="0" mass="1.000000" pos="0.000000 0.000000 0.000000" quat="0.000000 0.000000 0.000000 1.000000" size="0.250000 1.000000 0.012500" name="terrainGen_terrain_proc0_44" type="box"/>
        </body>
        <body pos="0.000000 0.000000 146.125000" quat="0.000000 0.000000 0.000000 1.000000" name="terrainGen_terrain_proc0_45">
            <geom conaffinity="1" contype="0" mass="1.000000" pos="0.000000 0.000000 0.000000" quat="0.000000 0.000000 0.000000 1.000000" size="0.250000 1.000000 0.012500" name="terrainGen_terrain_proc0_45" type="box"/>
        </body>
        <body pos="0.000000 0.000000 147.149994" quat="0.000000 0.000000 0.000000 1.000000" name="terrainGen_terrain_proc0_46">
            <geom conaffinity="1" contype="0" mass="1.000000" pos="0.000000 0.000000 0.000000" quat="0.000000 0.000000 0.000000 1.000000" size="0.250000 1.000000 0.012500" name="terrainGen_terrain_proc0_46" type="box"/>
        </body>
        <body pos="0.000000 0.000000 148.175003" quat="0.000000 0.000000 0.000000 1.000000" name="terrainGen_terrain_proc0_47">
            <geom conaffinity="1" contype="0" mass="1.000000" pos="0.000000 0.000000 0.000000" quat="0.000000 0.000000 0.000000 1.000000" size="0.250000 1.000000 0.012500" name="terrainGen_terrain_proc0_47" type="box"/>
        </body>
        <body pos="0.000000 0.000000 149.199997" quat="0.000000 0.000000 0.000000 1.000000" name="terrainGen_terrain_proc0_48">
            <geom conaffinity="1" contype="0" mass="1.000000" pos="0.000000 0.000000 0.000000" quat="0.000000 0.000000 0.000000 1.000000" size="0.250000 1.000000 0.012500" name="terrainGen_terrain_proc0_48" type="box"/>
        </body>
        <body pos="0.000000 0.000000 150.225006" quat="0.000000 0.000000 0.000000 1.000000" name="terrainGen_terrain_proc0_49">
            <geom conaffinity="1" contype="0" mass="1.000000" pos="0.000000 0.000000 0.000000" quat="0.000000 0.000000 0.000000 1.000000" size="0.250000 1.000000 0.012500" name="terrainGen_terrain_proc0_49" type="box"/>
        </body>
        <body pos="0.000000 0.000000 151.250000" quat="0.000000 0.000000 0.000000 1.000000" name="terrainGen_terrain_proc0_50">
            <geom conaffinity="1" contype="0" mass="1.000000" pos="0.000000 0.000000 0.000000" quat="0.000000 0.000000 0.000000 1.000000" size="0.250000 1.000000 0.012500" name="terrainGen_terrain_proc0_50" type="box"/>
        </body>
        <body pos="0.000000 0.000000 152.274994" quat="0.000000 0.000000 0.000000 1.000000" name="terrainGen_terrain_proc0_51">
            <geom conaffinity="1" contype="0" mass="1.000000" pos="0.000000 0.000000 0.000000" quat="0.000000 0.000000 0.000000 1.000000" size="0.250000 1.000000 0.012500" name="terrainGen_terrain_proc0_51" type="box"/>
        </body>
        <body pos="0.000000 0.000000 153.300003" quat="0.000000 0.000000 0.000000 1.000000" name="terrainGen_terrain_proc0_52">
            <geom conaffinity="1" contype="0" mass="1.000000" pos="0.000000 0.000000 0.000000" quat="0.000000 0.000000 0.000000 1.000000" size="0.250000 1.000000 0.012500" name="terrainGen_terrain_proc0_52" type="box"/>
        </body>
        <body pos="0.000000 0.000000 154.324997" quat="0.000000 0.000000 0.000000 1.000000" name="terrainGen_terrain_proc0_53">
            <geom conaffinity="1" contype="0" mass="1.000000" pos="0.000000 0.000000 0.000000" quat="0.000000 0.000000 0.000000 1.000000" size="0.250000 1.000000 0.012500" name="terrainGen_terrain_proc0_53" type="box"/>
        </body>
        <body pos="0.000000 0.000000 155.350006" quat="0.000000 0.000000 0.000000 1.000000" name="terrainGen_terrain_proc0_54">
            <geom conaffinity="1" contype="0" mass="1.000000" pos="0.000000 0.000000 0.000000" quat="0.000000 0.000000 0.000000 1.000000" size="0.250000 1.000000 0.012500" name="terrainGen_terrain_proc0_54" type="box"/>
        </body>
        <body pos="0.000000 0.000000 156.375000" quat="0.000000 0.000000 0.000000 1.000000" name="terrainGen_terrain_proc0_55">
            <geom conaffinity="1" contype="0" mass="1.000000" pos="0.000000 0.000000 0.000000" quat="0.000000 0.000000 0.000000 1.000000" size="0.250000 1.000000 0.012500" name="terrainGen_terrain_proc0_55" type="box"/>
        </body>
        <body pos="0.000000 0.000000 157.399994" quat="0.000000 0.000000 0.000000 1.000000" name="terrainGen_terrain_proc0_56">
            <geom conaffinity="1" contype="0" mass="1.000000" pos="0.000000 0.000000 0.000000" quat="0.000000 0.000000 0.000000 1.000000" size="0.250000 1.000000 0.012500" name="terrainGen_terrain_proc0_56" type="box"/>
        </body>
        <body pos="0.000000 0.000000 158.425003" quat="0.000000 0.000000 0.000000 1.000000" name="terrainGen_terrain_proc0_57">
            <geom conaffinity="1" contype="0" mass="1.000000" pos="0.000000 0.000000 0.000000" quat="0.000000 0.000000 0.000000 1.000000" size="0.250000 1.000000 0.012500" name="terrainGen_terrain_proc0_57" type="box"/>
        </body>
        <body pos="0.000000 0.000000 159.449997" quat="0.000000 0.000000 0.000000 1.000000" name="terrainGen_terrain_proc0_58">
            <geom conaffinity="1" contype="0" mass="1.000000" pos="0.000000 0.000000 0.000000" quat="0.000000 0.000000 0.000000 1.000000" size="0.250000 1.000000 0.012500" name="terrainGen_terrain_proc0_58" type="box"/>
        </body>
        <body pos="0.000000 0.000000 160.475006" quat="0.000000 0.000000 0.000000 1.000000" name="terrainGen_terrain_proc0_59">
            <geom conaffinity="1" contype="0" mass="1.000000" pos="0.000000 0.000000 0.000000" quat="0.000000 0.000000 0.000000 1.000000" size="0.250000 1.000000 0.012500" name="terrainGen_terrain_proc0_59" type="box"/>
        </body>
        <body pos="0.000000 0.000000 161.500000" quat="0.000000 0.000000 0.000000 1.000000" name="terrainGen_terrain_proc0_60">
            <geom conaffinity="1" contype="0" mass="1.000000" pos="0.000000 0.000000 0.000000" quat="0.000000 0.000000 0.000000 1.000000" size="0.250000 1.000000 0.012500" name="terrainGen_terrain_proc0_60" type="box"/>
        </body>
        <body pos="0.000000 0.000000 162.524994" quat="0.000000 0.000000 0.000000 1.000000" name="terrainGen_terrain_proc0_61">
            <geom conaffinity="1" contype="0" mass="1.000000" pos="0.000000 0.000000 0.000000" quat="0.000000 0.000000 0.000000 1.000000" size="0.250000 1.000000 0.012500" name="terrainGen_terrain_proc0_61" type="box"/>
        </body>
        <body pos="0.000000 0.000000 163.550003" quat="0.000000 0.000000 0.000000 1.000000" name="terrainGen_terrain_proc0_62">
            <geom conaffinity="1" contype="0" mass="1.000000" pos="0.000000 0.000000 0.000000" quat="0.000000 0.000000 0.000000 1.000000" size="0.250000 1.000000 0.012500" name="terrainGen_terrain_proc0_62" type="box"/>
        </body>
        <body pos="0.000000 0.000000 164.574997" quat="0.000000 0.000000 0.000000 1.000000" name="terrainGen_terrain_proc0_63">
            <geom conaffinity="1" contype="0" mass="1.000000" pos="0.000000 0.000000 0.000000" quat="0.000000 0.000000 0.000000 1.000000" size="0.250000 1.000000 0.012500" name="terrainGen_terrain_proc0_63" type="box"/>
        </body>
        <body pos="0.000000 0.000000 165.600006" quat="0.000000 0.000000 0.000000 1.000000" name="terrainGen_terrain_proc0_64">
            <geom conaffinity="1" contype="0" mass="1.000000" pos="0.000000 0.000000 0.000000" quat="0.000000 0.000000 0.000000 1.000000" size="0.250000 1.000000 0.012500" name="terrainGen_terrain_proc0_64" type="box"/>
        </body>
        <body pos="0.000000 0.000000 166.625000" quat="0.000000 0.000000 0.000000 1.000000" name="terrainGen_terrain_proc0_65">
            <geom conaffinity="1" contype="0" mass="1.000000" pos="0.000000 0.000000 0.000000" quat="0.000000 0.000000 0.000000 1.000000" size="0.250000 1.000000 0.012500" name="terrainGen_terrain_proc0_65" type="box"/>
        </body>
        <body pos="0.000000 0.000000 167.649994" quat="0.000000 0.000000 0.000000 1.000000" name="terrainGen_terrain_proc0_66">
            <geom conaffinity="1" contype="0" mass="1.000000" pos="0.000000 0.000000 0.000000" quat="0.000000 0.000000 0.000000 1.000000" size="0.250000 1.000000 0.012500" name="terrainGen_terrain_proc0_66" type="box"/>
        </body>
        <body pos="0.000000 0.000000 168.674988" quat="0.000000 0.000000 0.000000 1.000000" name="terrainGen_terrain_proc0_67">
            <geom conaffinity="1" contype="0" mass="1.000000" pos="0.000000 0.000000 0.000000" quat="0.000000 0.000000 0.000000 1.000000" size="0.250000 1.000000 0.012500" name="terrainGen_terrain_proc0_67" type="box"/>
        </body>
        <body pos="0.000000 0.000000 169.699997" quat="0.000000 0.000000 0.000000 1.000000" name="terrainGen_terrain_proc0_68">
            <geom conaffinity="1" contype="0" mass="1.000000" pos="0.000000 0.000000 0.000000" quat="0.000000 0.000000 0.000000 1.000000" size="0.250000 1.000000 0.012500" name="terrainGen_terrain_proc0_68" type="box"/>
        </body>
        <body pos="0.000000 0.000000 170.725006" quat="0.000000 0.000000 0.000000 1.000000" name="terrainGen_terrain_proc0_69">
            <geom conaffinity="1" contype="0" mass="1.000000" pos="0.000000 0.000000 0.000000" quat="0.000000 0.000000 0.000000 1.000000" size="0.250000 1.000000 0.012500" name="terrainGen_terrain_proc0_69" type="box"/>
        </body>
        <body pos="0.000000 0.000000 171.750000" quat="0.000000 0.000000 0.000000 1.000000" name="terrainGen_terrain_proc0_70">
            <geom conaffinity="1" contype="0" mass="1.000000" pos="0.000000 0.000000 0.000000" quat="0.000000 0.000000 0.000000 1.000000" size="0.250000 1.000000 0.012500" name="terrainGen_terrain_proc0_70" type="box"/>
        </body>
        <body pos="0.000000 0.000000 172.774994" quat="0.000000 0.000000 0.000000 1.000000" name="terrainGen_terrain_proc0_71">
            <geom conaffinity="1" contype="0" mass="1.000000" pos="0.000000 0.000000 0.000000" quat="0.000000 0.000000 0.000000 1.000000" size="0.250000 1.000000 0.012500" name="terrainGen_terrain_proc0_71" type="box"/>
        </body>
        <body pos="0.000000 0.000000 173.799988" quat="0.000000 0.000000 0.000000 1.000000" name="terrainGen_terrain_proc0_72">
            <geom conaffinity="1" contype="0" mass="1.000000" pos="0.000000 0.000000 0.000000" quat="0.000000 0.000000 0.000000 1.000000" size="0.250000 1.000000 0.012500" name="terrainGen_terrain_proc0_72" type="box"/>
        </body>
        <body pos="0.000000 0.000000 174.824997" quat="0.000000 0.000000 0.000000 1.000000" name="terrainGen_terrain_proc0_73">
            <geom conaffinity="1" contype="0" mass="1.000000" pos="0.000000 0.000000 0.000000" quat="0.000000 0.000000 0.000000 1.000000" size="0.250000 1.000000 0.012500" name="terrainGen_terrain_proc0_73" type="box"/>
        </body>
        <body pos="0.000000 0.000000 175.850006" quat="0.000000 0.000000 0.000000 1.000000" name="terrainGen_terrain_proc0_74">
            <geom conaffinity="1" contype="0" mass="1.000000" pos="0.000000 0.000000 0.000000" quat="0.000000 0.000000 0.000000 1.000000" size="0.250000 1.000000 0.012500" name="terrainGen_terrain_proc0_74" type="box"/>
        </body>
        <body pos="0.000000 0.000000 176.875000" quat="0.000000 0.000000 0.000000 1.000000" name="terrainGen_terrain_proc0_75">
            <geom conaffinity="1" contype="0" mass="1.000000" pos="0.000000 0.000000 0.000000" quat="0.000000 0.000000 0.000000 1.000000" size="0.250000 1.000000 0.012500" name="terrainGen_terrain_proc0_75" type="box"/>
        </body>
        <body pos="0.000000 0.000000 177.899994" quat="0.000000 0.000000 0.000000 1.000000" name="terrainGen_terrain_proc0_76">
            <geom conaffinity="1" contype="0" mass="1.000000" pos="0.000000 0.000000 0.000000" quat="0.000000 0.000000 0.000000 1.000000" size="0.250000 1.000000 0.012500" name="terrainGen_terrain_proc0_76" type="box"/>
        </body>
        <body pos="0.000000 0.000000 178.924988" quat="0.000000 0.000000 0.000000 1.000000" name="terrainGen_terrain_proc0_77">
            <geom conaffinity="1" contype="0" mass="1.000000" pos="0.000000 0.000000 0.000000" quat="0.000000 0.000000 0.000000 1.000000" size="0.250000 1.000000 0.012500" name="terrainGen_terrain_proc0_77" type="box"/>
        </body>
        <body pos="0.000000 0.000000 179.949997" quat="0.000000 0.000000 0.000000 1.000000" name="terrainGen_terrain_proc0_78">
            <geom conaffinity="1" contype="0" mass="1.000000" pos="0.000000 0.000000 0.000000" quat="0.000000 0.000000 0.000000 1.000000" size="0.250000 1.000000 0.012500" name="terrainGen_terrain_proc0_78" type="box"/>
        </body>
        <body pos="0.000000 0.000000 180.975006" quat="0.000000 0.000000 0.000000 1.000000" name="terrainGen_terrain_proc0_79">
            <geom conaffinity="1" contype="0" mass="1.000000" pos="0.000000 0.000000 0.000000" quat="0.000000 0.000000 0.000000 1.000000" size="0.250000 1.000000 0.012500" name="terrainGen_terrain_proc0_79" type="box"/>
        </body>
        <body pos="0.000000 0.000000 182.000000" quat="0.000000 0.000000 0.000000 1.000000" name="terrainGen_terrain_proc0_80">
            <geom conaffinity="1" contype="0" mass="1.000000" pos="0.000000 0.000000 0.000000" quat="0.000000 0.000000 0.000000 1.000000" size="0.250000 1.000000 0.012500" name="terrainGen_terrain_proc0_80" type="box"/>
        </body>
        <body pos="0.000000 0.000000 183.024994" quat="0.000000 0.000000 0.000000 1.000000" name="terrainGen_terrain_proc0_81">
            <geom conaffinity="1" contype="0" mass="1.000000" pos="0.000000 0.000000 0.000000" quat="0.000000 0.000000 0.000000 1.000000" size="0.250000 1.000000 0.012500" name="terrainGen_terrain_proc0_81" type="box"/>
        </body>
        <body pos="0.000000 0.000000 184.049988" quat="0.000000 0.000000 0.000000 1.000000" name="terrainGen_terrain_proc0_82">
            <geom conaffinity="1" contype="0" mass="1.000000" pos="0.000000 0.000000 0.000000" quat="0.000000 0.000000 0.000000 1.000000" size="0.250000 1.000000 0.012500" name="terrainGen_terrain_proc0_82" type="box"/>
        </body>
        <body pos="0.000000 0.000000 185.074997" quat="0.000000 0.000000 0.000000 1.000000" name="terrainGen_terrain_proc0_83">
            <geom conaffinity="1" contype="0" mass="1.000000" pos="0.000000 0.000000 0.000000" quat="0.000000 0.000000 0.000000 1.000000" size="0.250000 1.000000 0.012500" name="terrainGen_terrain_proc0_83" type="box"/>
        </body>
        <body pos="0.000000 0.000000 186.100006" quat="0.000000 0.000000 0.000000 1.000000" name="terrainGen_terrain_proc0_84">
            <geom conaffinity="1" contype="0" mass="1.000000" pos="0.000000 0.000000 0.000000" quat="0.000000 0.000000 0.000000 1.000000" size="0.250000 1.000000 0.012500" name="terrainGen_terrain_proc0_84" type="box"/>
        </body>
        <body pos="0.000000 0.000000 187.125000" quat="0.000000 0.000000 0.000000 1.000000" name="terrainGen_terrain_proc0_85">
            <geom conaffinity="1" contype="0" mass="1.000000" pos="0.000000 0.000000 0.000000" quat="0.000000 0.000000 0.000000 1.000000" size="0.250000 1.000000 0.012500" name="terrainGen_terrain_proc0_85" type="box"/>
        </body>
        <body pos="0.000000 0.000000 188.149994" quat="0.000000 0.000000 0.000000 1.000000" name="terrainGen_terrain_proc0_86">
            <geom conaffinity="1" contype="0" mass="1.000000" pos="0.000000 0.000000 0.000000" quat="0.000000 0.000000 0.000000 1.000000" size="0.250000 1.000000 0.012500" name="terrainGen_terrain_proc0_86" type="box"/>
        </body>
        <body pos="0.000000 0.000000 189.174988" quat="0.000000 0.000000 0.000000 1.000000" name="terrainGen_terrain_proc0_87">
            <geom conaffinity="1" contype="0" mass="1.000000" pos="0.000000 0.000000 0.000000" quat="0.000000 0.000000 0.000000 1.000000" size="0.250000 1.000000 0.012500" name="terrainGen_terrain_proc0_87" type="box"/>
        </body>
        <body pos="0.000000 0.000000 190.199997" quat="0.000000 0.000000 0.000000 1.000000" name="terrainGen_terrain_proc0_88">
            <geom conaffinity="1" contype="0" mass="1.000000" pos="0.000000 0.000000 0.000000" quat="0.000000 0.000000 0.000000 1.000000" size="0.250000 1.000000 0.012500" name="terrainGen_terrain_proc0_88" type="box"/>
        </body>
        <body pos="0.000000 0.000000 191.225006" quat="0.000000 0.000000 0.000000 1.000000" name="terrainGen_terrain_proc0_89">
            <geom conaffinity="1" contype="0" mass="1.000000" pos="0.000000 0.000000 0.000000" quat="0.000000 0.000000 0.000000 1.000000" size="0.250000 1.000000 0.012500" name="terrainGen_terrain_proc0_89" type="box"/>
        </body>
        <body pos="0.000000 0.000000 192.250000" quat="0.000000 0.000000 0.000000 1.000000" name="terrainGen_terrain_proc0_90">
            <geom conaffinity="1" contype="0" mass="1.000000" pos="0.000000 0.000000 0.000000" quat="0.000000 0.000000 0.000000 1.000000" size="0.250000 1.000000 0.012500" name="terrainGen_terrain_proc0_90" type="box"/>
        </body>
        <body pos="0.000000 0.000000 193.274994" quat="0.000000 0.000000 0.000000 1.000000" name="terrainGen_terrain_proc0_91">
            <geom conaffinity="1" contype="0" mass="1.000000" pos="0.000000 0.000000 0.000000" quat="0.000000 0.000000 0.000000 1.000000" size="0.250000 1.000000 0.012500" name="terrainGen_terrain_proc0_91" type="box"/>
        </body>
        <body pos="0.000000 0.000000 194.299988" quat="0.000000 0.000000 0.000000 1.000000" name="terrainGen_terrain_proc0_92">
            <geom conaffinity="1" contype="0" mass="1.000000" pos="0.000000 0.000000 0.000000" quat="0.000000 0.000000 0.000000 1.000000" size="0.250000 1.000000 0.012500" name="terrainGen_terrain_proc0_92" type="box"/>
        </body>
        <body pos="0.000000 0.000000 195.324997" quat="0.000000 0.000000 0.000000 1.000000" name="terrainGen_terrain_proc0_93">
            <geom conaffinity="1" contype="0" mass="1.000000" pos="0.000000 0.000000 0.000000" quat="0.000000 0.000000 0.000000 1.000000" size="0.250000 1.000000 0.012500" name="terrainGen_terrain_proc0_93" type="box"/>
        </body>
        <body pos="0.000000 0.000000 196.350006" quat="0.000000 0.000000 0.000000 1.000000" name="terrainGen_terrain_proc0_94">
            <geom conaffinity="1" contype="0" mass="1.000000" pos="0.000000 0.000000 0.000000" quat="0.000000 0.000000 0.000000 1.000000" size="0.250000 1.000000 0.012500" name="terrainGen_terrain_proc0_94" type="box"/>
        </body>
        <body pos="0.000000 0.000000 197.375000" quat="0.000000 0.000000 0.000000 1.000000" name="terrainGen_terrain_proc0_95">
            <geom conaffinity="1" contype="0" mass="1.000000" pos="0.000000 0.000000 0.000000" quat="0.000000 0.000000 0.000000 1.000000" size="0.250000 1.000000 0.012500" name="terrainGen_terrain_proc0_95" type="box"/>
        </body>
        <body pos="0.000000 0.000000 198.399994" quat="0.000000 0.000000 0.000000 1.000000" name="terrainGen_terrain_proc0_96">
            <geom conaffinity="1" contype="0" mass="1.000000" pos="0.000000 0.000000 0.000000" quat="0.000000 0.000000 0.000000 1.000000" size="0.250000 1.000000 0.012500" name="terrainGen_terrain_proc0_96" type="box"/>
        </body>
        <body pos="0.000000 0.000000 199.424988" quat="0.000000 0.000000 0.000000 1.000000" name="terrainGen_terrain_proc0_97">
            <geom conaffinity="1" contype="0" mass="1.000000" pos="0.000000 0.000000 0.000000" quat="0.000000 0.000000 0.000000 1.000000" size="0.250000 1.000000 0.012500" name="terrainGen_terrain_proc0_97" type="box"/>
        </body>
        <body pos="0.000000 0.000000 200.449997" quat="0.000000 0.000000 0.000000 1.000000" name="terrainGen_terrain_proc0_98">
            <geom conaffinity="1" contype="0" mass="1.000000" pos="0.000000 0.000000 0.000000" quat="0.000000 0.000000 0.000000 1.000000" size="0.250000 1.000000 0.012500" name="terrainGen_terrain_proc0_98" type="box"/>
        </body>
    </worldbody>
    <worldbody>
        <light diffuse="0.200000 0.200000 0.200000" dir="0.000000 0.000000 -1.000000" pos="0.000000 0.000000 5.000000" specular="0.000000 0.000000 0.000000" castshadow="false" directional="false"/>
        <light diffuse="0.800000 0.800000 0.800000" dir="0.000000 0.000000 -1.000000" pos="0.000000 0.000000 4.000000" specular="0.300000 0.300000 0.300000" directional="false" mode="targetbodycom" target="mjcbody_humanoid0_tmjcroot"/>
        <body pos="2.000000 0.000000 2.500000" name="mjcbody_humanoid0_tmjcroot">
            <freejoint name="mjcjoint_humanoid0_root"/>
            <geom condim="1" fromto="0.000000 -0.070000 0.000000 0.000000 0.070000 0.000000" size="0.070000" material="matgeom" name="mjcgeom_humanoid0_tmjcroot" type="capsule"/>
            <geom condim="1" pos="0.000000 0.000000 0.190000" size="0.090000" material="matgeom" name="mjcgeom_humanoid0_head" type="sphere"/>
            <geom condim="1" fromto="-0.010000 -0.060000 -0.120000 -0.010000 0.060000 -0.120000" size="0.060000" material="matgeom" name="mjcgeom_humanoid0_uwaist" type="capsule"/>
            <body pos="-0.010000 0.000000 -0.260000" quat="1.000000 0.000000 -0.002000 0.000000" name="mjcbody_humanoid0_lwaist">
                <geom condim="1" fromto="0.000000 -0.060000 0.000000 0.000000 0.060000 0.000000" size="0.060000" material="matgeom" name="mjcgeom_humanoid0_lwaist" type="capsule"/>
                <joint armature="0.020000" damping="5.000000" stiffness="20.000000" axis="0.000000 0.000000 1.000000" pos="0.000000 0.000000 0.065000" range="-45.000000 45.000000" limited="true" name="mjcjoint_humanoid0_abdomen_z" type="hinge"/>
                <joint armature="0.020000" damping="5.000000" stiffness="10.000000" axis="0.000000 1.000000 0.000000" pos="0.000000 0.000000 0.065000" range="-75.000000 30.000000" limited="true" name="mjcjoint_humanoid0_abdomen_y" type="hinge"/>
                <body pos="0.000000 0.000000 -0.165000" quat="1.000000 0.000000 -0.002000 0.000000" name="mjcbody_humanoid0_pelvis">
                    <joint armature="0.020000" damping="5.000000" stiffness="10.000000" axis="1.000000 0.000000 0.000000" pos="0.000000 0.000000 0.100000" range="-35.000000 35.000000" limited="true" name="mjcjoint_humanoid0_abdomen_x" type="hinge"/>
                    <geom condim="1" fromto="-0.020000 -0.070000 0.000000 -0.020000 0.070000 0.000000" size="0.090000" material="matgeom" name="mjcgeom_humanoid0_butt" type="capsule"/>
                    <body pos="0.000000 -0.100000 -0.040000" name="mjcbody_humanoid0_right_thigh">
                        <joint armature="0.010000" damping="5.000000" stiffness="10.000000" axis="1.000000 0.000000 0.000000" pos="0.000000 0.000000 0.000000" range="-25.000000 5.000000" limited="true" name="mjcjoint_humanoid0_right_hip_x" type="hinge"/>
                        <joint armature="0.010000" damping="5.000000" stiffness="10.000000" axis="0.000000 0.000000 1.000000" pos="0.000000 0.000000 0.000000" range="-60.000000 35.000000" limited="true" name="mjcjoint_humanoid0_right_hip_z" type="hinge"/>
                        <joint armature="0.010000" damping="5.000000" stiffness="20.000000" axis="0.000000 1.000000 0.000000" pos="0.000000 0.000000 0.000000" range="-120.000000 20.000000" limited="true" name="mjcjoint_humanoid0_right_hip_y" type="hinge"/>
                        <geom condim="1" fromto="0.000000 0.000000 0.000000 0.000000 0.010000 -0.340000" size="0.060000" material="matgeom" name="mjcgeom_humanoid0_right_thigh1" type="capsule"/>
                        <body pos="0.000000 0.010000 -0.403000" name="mjcbody_humanoid0_right_shin">
                            <joint armature="0.006000" damping="1.000000" stiffness="1.000000" axis="0.000000 -1.000000 0.000000" pos="0.000000 0.000000 0.020000" range="-160.000000 -2.000000" limited="true" name="mjcjoint_humanoid0_right_knee" type="hinge"/>
                            <geom condim="1" fromto="0.000000 0.000000 0.000000 0.000000 0.000000 -0.300000" size="0.049000" material="matgeom" name="mjcgeom_humanoid0_right_shin1" type="capsule"/>
                            <body pos="0.000000 0.000000 -0.390000" name="mjcbody_humanoid0_right_foot">
                                <joint armature="0.000800" damping="1.000000" stiffness="4.000000" axis="0.000000 1.000000 0.000000" pos="0.000000 0.000000 0.080000" range="-50.000000 50.000000" limited="true" name="mjcjoint_humanoid0_right_ankle_y" type="hinge"/>
                                <joint armature="0.000600" damping="1.000000" stiffness="1.000000" axis="1.000000 0.000000 0.500000" pos="0.000000 0.000000 0.040000" range="-50.000000 50.000000" limited="true" name="mjcjoint_humanoid0_right_ankle_x" type="hinge"/>
                                <geom condim="1" fromto="-0.070000 -0.020000 0.000000 0.140000 -0.040000 0.000000" size="0.027000" material="matgeom" name="mjcgeom_humanoid0_right_foot_cap1" type="capsule"/>
                                <geom condim="1" fromto="-0.070000 0.000000 0.000000 0.140000 0.020000 0.000000" size="0.027000" material="matgeom" name="mjcgeom_humanoid0_right_foot_cap2" type="capsule"/>
                            </body>
                        </body>
                    </body>
                    <body pos="0.000000 0.100000 -0.040000" name="mjcbody_humanoid0_left_thigh">
                        <joint armature="0.010000" damping="5.000000" stiffness="10.000000" axis="-1.000000 0.000000 0.000000" pos="0.000000 0.000000 0.000000" range="-25.000000 5.000000" limited="true" name="mjcjoint_humanoid0_left_hip_x" type="hinge"/>
                        <joint armature="0.010000" damping="5.000000" stiffness="10.000000" axis="0.000000 0.000000 -1.000000" pos="0.000000 0.000000 0.000000" range="-60.000000 35.000000" limited="true" name="mjcjoint_humanoid0_left_hip_z" type="hinge"/>
                        <joint armature="0.010000" damping="5.000000" stiffness="20.000000" axis="0.000000 1.000000 0.000000" pos="0.000000 0.000000 0.000000" range="-120.000000 20.000000" limited="true" name="mjcjoint_humanoid0_left_hip_y" type="hinge"/>
                        <geom condim="1" fromto="0.000000 0.000000 0.000000 0.000000 -0.010000 -0.340000" size="0.060000" material="matgeom" name="mjcgeom_humanoid0_left_thigh1" type="capsule"/>
                        <body pos="0.000000 -0.010000 -0.403000" name="mjcbody_humanoid0_left_shin">
                            <joint armature="0.006000" damping="1.000000" stiffness="1.000000" axis="0.000000 -1.000000 0.000000" pos="0.000000 0.000000 0.020000" range="-160.000000 -2.000000" limited="true" name="mjcjoint_humanoid0_left_knee" type="hinge"/>
                            <geom condim="1" fromto="0.000000 0.000000 0.000000 0.000000 0.000000 -0.300000" size="0.049000" material="matgeom" name="mjcgeom_humanoid0_left_shin1" type="capsule"/>
                            <body pos="0.000000 0.000000 -0.390000" name="mjcbody_humanoid0_left_foot">
                                <joint armature="0.000800" damping="1.000000" stiffness="4.000000" axis="0.000000 1.000000 0.000000" pos="0.000000 0.000000 0.080000" range="-50.000000 50.000000" limited="true" name="mjcjoint_humanoid0_left_ankle_y" type="hinge"/>
                                <joint armature="0.000600" damping="1.000000" stiffness="1.000000" axis="1.000000 0.000000 0.500000" pos="0.000000 0.000000 0.040000" range="-50.000000 50.000000" limited="true" name="mjcjoint_humanoid0_left_ankle_x" type="hinge"/>
                                <geom condim="1" fromto="-0.070000 0.020000 0.000000 0.140000 0.040000 0.000000" size="0.027000" material="matgeom" name="mjcgeom_humanoid0_left_foot_cap1" type="capsule"/>
                                <geom condim="1" fromto="-0.070000 0.000000 0.000000 0.140000 -0.020000 0.000000" size="0.027000" material="matgeom" name="mjcgeom_humanoid0_left_foot_cap2" type="capsule"/>
                            </body>
                        </body>
                    </body>
                </body>
            </body>
            <body pos="0.000000 -0.170000 0.060000" name="mjcbody_humanoid0_right_upper_arm">
                <joint armature="0.006800" damping="1.000000" stiffness="1.000000" axis="2.000000 1.000000 1.000000" pos="0.000000 0.000000 0.000000" range="-85.000000 60.000000" limited="true" name="mjcjoint_humanoid0_right_shoulder1" type="hinge"/>
                <joint armature="0.005100" damping="1.000000" stiffness="1.000000" axis="0.000000 -1.000000 1.000000" pos="0.000000 0.000000 0.000000" range="-85.000000 60.000000" limited="true" name="mjcjoint_humanoid0_right_shoulder2" type="hinge"/>
                <geom condim="1" fromto="0.000000 0.000000 0.000000 0.160000 -0.160000 -0.160000" size="0.040000 0.160000" material="matgeom" name="mjcgeom_humanoid0_right_uarm1" type="capsule"/>
                <body pos="0.180000 -0.180000 -0.180000" name="mjcbody_humanoid0_right_lower_arm">
                    <joint armature="0.002800" damping="1.000000" stiffness="0.000000" axis="0.000000 -1.000000 1.000000" pos="0.000000 0.000000 0.000000" range="-90.000000 50.000000" limited="true" name="mjcjoint_humanoid0_right_elbow" type="hinge"/>
                    <geom condim="1" fromto="0.010000 0.010000 0.010000 0.170000 0.170000 0.170000" size="0.031000" material="matgeom" name="mjcgeom_humanoid0_right_larm" type="capsule"/>
                    <geom condim="1" pos="0.180000 0.180000 0.180000" size="0.040000" material="matgeom" name="mjcgeom_humanoid0_right_hand" type="sphere"/>
                </body>
            </body>
            <body pos="0.000000 0.170000 0.060000" name="mjcbody_humanoid0_left_upper_arm">
                <joint armature="0.006800" damping="1.000000" stiffness="1.000000" axis="2.000000 -1.000000 1.000000" pos="0.000000 0.000000 0.000000" range="-60.000000 85.000000" limited="true" name="mjcjoint_humanoid0_left_shoulder1" type="hinge"/>
                <joint armature="0.005100" damping="1.000000" stiffness="1.000000" axis="0.000000 1.000000 1.000000" pos="0.000000 0.000000 0.000000" range="-60.000000 85.000000" limited="true" name="mjcjoint_humanoid0_left_shoulder2" type="hinge"/>
                <geom condim="1" fromto="0.000000 0.000000 0.000000 0.160000 0.160000 -0.160000" size="0.040000 0.160000" material="matgeom" name="mjcgeom_humanoid0_left_uarm1" type="capsule"/>
                <body pos="0.180000 0.180000 -0.180000" name="mjcbody_humanoid0_left_lower_arm">
                    <joint armature="0.002800" damping="1.000000" stiffness="0.000000" axis="0.000000 -1.000000 -1.000000" pos="0.000000 0.000000 0.000000" range="-90.000000 50.000000" limited="true" name="mjcjoint_humanoid0_left_elbow" type="hinge"/>
                    <geom condim="1" fromto="0.010000 -0.010000 0.010000 0.170000 -0.170000 0.170000" size="0.031000" material="matgeom" name="mjcgeom_humanoid0_left_larm" type="capsule"/>
                    <geom condim="1" pos="0.180000 -0.180000 0.180000" size="0.040000" material="matgeom" name="mjcgeom_humanoid0_left_hand" type="sphere"/>
                </body>
            </body>
        </body>
    </worldbody>
    <actuator>
        <motor ctrlrange="-0.400000 0.400000" gear="200.000000" ctrllimited="true" joint="mjcjoint_humanoid0_abdomen_y" name="mjcact_humanoid0_abdomen_y"/>
        <motor ctrlrange="-0.400000 0.400000" gear="200.000000" ctrllimited="true" joint="mjcjoint_humanoid0_abdomen_z" name="mjcact_humanoid0_abdomen_z"/>
        <motor ctrlrange="-0.400000 0.400000" gear="200.000000" ctrllimited="true" joint="mjcjoint_humanoid0_abdomen_x" name="mjcact_humanoid0_abdomen_x"/>
        <motor ctrlrange="-0.400000 0.400000" gear="200.000000" ctrllimited="true" joint="mjcjoint_humanoid0_right_hip_x" name="mjcact_humanoid0_right_hip_x"/>
        <motor ctrlrange="-0.400000 0.400000" gear="200.000000" ctrllimited="true" joint="mjcjoint_humanoid0_right_hip_z" name="mjcact_humanoid0_right_hip_z"/>
        <motor ctrlrange="-0.400000 0.400000" gear="600.000000" ctrllimited="true" joint="mjcjoint_humanoid0_right_hip_y" name="mjcact_humanoid0_right_hip_y"/>
        <motor ctrlrange="-0.400000 0.400000" gear="400.000000" ctrllimited="true" joint="mjcjoint_humanoid0_right_knee" name="mjcact_humanoid0_right_knee"/>
        <motor ctrlrange="-0.400000 0.400000" gear="100.000000" ctrllimited="true" joint="mjcjoint_humanoid0_right_ankle_x" name="mjcact_humanoid0_right_ankle_x"/>
        <motor ctrlrange="-0.400000 0.400000" gear="100.000000" ctrllimited="true" joint="mjcjoint_humanoid0_right_ankle_y" name="mjcact_humanoid0_right_ankle_y"/>
        <motor ctrlrange="-0.400000 0.400000" gear="200.000000" ctrllimited="true" joint="mjcjoint_humanoid0_left_hip_x" name="mjcact_humanoid0_left_hip_x"/>
        <motor ctrlrange="-0.400000 0.400000" gear="200.000000" ctrllimited="true" joint="mjcjoint_humanoid0_left_hip_z" name="mjcact_humanoid0_left_hip_z"/>
        <motor ctrlrange="-0.400000 0.400000" gear="600.000000" ctrllimited="true" joint="mjcjoint_humanoid0_left_hip_y" name="mjcact_humanoid0_left_hip_y"/>
        <motor ctrlrange="-0.400000 0.400000" gear="400.000000" ctrllimited="true" joint="mjcjoint_humanoid0_left_knee" name="mjcact_humanoid0_left_knee"/>
        <motor ctrlrange="-0.400000 0.400000" gear="100.000000" ctrllimited="true" joint="mjcjoint_humanoid0_left_ankle_x" name="mjcact_humanoid0_left_ankle_x"/>
        <motor ctrlrange="-0.400000 0.400000" gear="100.000000" ctrllimited="true" joint="mjcjoint_humanoid0_left_ankle_y" name="mjcact_humanoid0_left_ankle_y"/>
        <motor ctrlrange="-0.400000 0.400000" gear="100.000000" ctrllimited="true" joint="mjcjoint_humanoid0_right_shoulder1" name="mjcact_humanoid0_right_shoulder1"/>
        <motor ctrlrange="-0.400000 0.400000" gear="100.000000" ctrllimited="true" joint="mjcjoint_humanoid0_right_shoulder2" name="mjcact_humanoid0_right_shoulder2"/>
        <motor ctrlrange="-0.400000 0.400000" gear="200.000000" ctrllimited="true" joint="mjcjoint_humanoid0_right_elbow" name="mjcact_humanoid0_right_elbow"/>
        <motor ctrlrange="-0.400000 0.400000" gear="100.000000" ctrllimited="true" joint="mjcjoint_humanoid0_left_shoulder1" name="mjcact_humanoid0_left_shoulder1"/>
        <motor ctrlrange="-0.400000 0.400000" gear="100.000000" ctrllimited="true" joint="mjcjoint_humanoid0_left_shoulder2" name="mjcact_humanoid0_left_shoulder2"/>
        <motor ctrlrange="-0.400000 0.400000" gear="200.000000" ctrllimited="true" joint="mjcjoint_humanoid0_left_elbow" name="mjcact_humanoid0_left_elbow"/>
    </actuator>
    <sensor>
        <jointpos joint="mjcjoint_humanoid0_abdomen_z" name="mjcsensor_jointposhumanoid0_sensJoint_mjcjoint_humanoid0_abdomen_z"/>
        <jointvel joint="mjcjoint_humanoid0_abdomen_z" name="mjcsensor_jointvelhumanoid0_sensJoint_mjcjoint_humanoid0_abdomen_z"/>
        <jointpos joint="mjcjoint_humanoid0_abdomen_y" name="mjcsensor_jointposhumanoid0_sensJoint_mjcjoint_humanoid0_abdomen_y"/>
        <jointvel joint="mjcjoint_humanoid0_abdomen_y" name="mjcsensor_jointvelhumanoid0_sensJoint_mjcjoint_humanoid0_abdomen_y"/>
        <jointpos joint="mjcjoint_humanoid0_abdomen_x" name="mjcsensor_jointposhumanoid0_sensJoint_mjcjoint_humanoid0_abdomen_x"/>
        <jointvel joint="mjcjoint_humanoid0_abdomen_x" name="mjcsensor_jointvelhumanoid0_sensJoint_mjcjoint_humanoid0_abdomen_x"/>
        <jointpos joint="mjcjoint_humanoid0_right_hip_x" name="mjcsensor_jointposhumanoid0_sensJoint_mjcjoint_humanoid0_right_hip_x"/>
        <jointvel joint="mjcjoint_humanoid0_right_hip_x" name="mjcsensor_jointvelhumanoid0_sensJoint_mjcjoint_humanoid0_right_hip_x"/>
        <jointpos joint="mjcjoint_humanoid0_right_hip_z" name="mjcsensor_jointposhumanoid0_sensJoint_mjcjoint_humanoid0_right_hip_z"/>
        <jointvel joint="mjcjoint_humanoid0_right_hip_z" name="mjcsensor_jointvelhumanoid0_sensJoint_mjcjoint_humanoid0_right_hip_z"/>
        <jointpos joint="mjcjoint_humanoid0_right_hip_y" name="mjcsensor_jointposhumanoid0_sensJoint_mjcjoint_humanoid0_right_hip_y"/>
        <jointvel joint="mjcjoint_humanoid0_right_hip_y" name="mjcsensor_jointvelhumanoid0_sensJoint_mjcjoint_humanoid0_right_hip_y"/>
        <jointpos joint="mjcjoint_humanoid0_right_knee" name="mjcsensor_jointposhumanoid0_sensJoint_mjcjoint_humanoid0_right_knee"/>
        <jointvel joint="mjcjoint_humanoid0_right_knee" name="mjcsensor_jointvelhumanoid0_sensJoint_mjcjoint_humanoid0_right_knee"/>
        <jointpos joint="mjcjoint_humanoid0_right_ankle_y" name="mjcsensor_jointposhumanoid0_sensJoint_mjcjoint_humanoid0_right_ankle_y"/>
        <jointvel joint="mjcjoint_humanoid0_right_ankle_y" name="mjcsensor_jointvelhumanoid0_sensJoint_mjcjoint_humanoid0_right_ankle_y"/>
        <jointpos joint="mjcjoint_humanoid0_right_ankle_x" name="mjcsensor_jointposhumanoid0_sensJoint_mjcjoint_humanoid0_right_ankle_x"/>
        <jointvel joint="mjcjoint_humanoid0_right_ankle_x" name="mjcsensor_jointvelhumanoid0_sensJoint_mjcjoint_humanoid0_right_ankle_x"/>
        <jointpos joint="mjcjoint_humanoid0_left_hip_x" name="mjcsensor_jointposhumanoid0_sensJoint_mjcjoint_humanoid0_left_hip_x"/>
        <jointvel joint="mjcjoint_humanoid0_left_hip_x" name="mjcsensor_jointvelhumanoid0_sensJoint_mjcjoint_humanoid0_left_hip_x"/>
        <jointpos joint="mjcjoint_humanoid0_left_hip_z" name="mjcsensor_jointposhumanoid0_sensJoint_mjcjoint_humanoid0_left_hip_z"/>
        <jointvel joint="mjcjoint_humanoid0_left_hip_z" name="mjcsensor_jointvelhumanoid0_sensJoint_mjcjoint_humanoid0_left_hip_z"/>
        <jointpos joint="mjcjoint_humanoid0_left_hip_y" name="mjcsensor_jointposhumanoid0_sensJoint_mjcjoint_humanoid0_left_hip_y"/>
        <jointvel joint="mjcjoint_humanoid0_left_hip_y" name="mjcsensor_jointvelhumanoid0_sensJoint_mjcjoint_humanoid0_left_hip_y"/>
        <jointpos joint="mjcjoint_humanoid0_left_knee" name="mjcsensor_jointposhumanoid0_sensJoint_mjcjoint_humanoid0_left_knee"/>
        <jointvel joint="mjcjoint_humanoid0_left_knee" name="mjcsensor_jointvelhumanoid0_sensJoint_mjcjoint_humanoid0_left_knee"/>
        <jointpos joint="mjcjoint_humanoid0_left_ankle_y" name="mjcsensor_jointposhumanoid0_sensJoint_mjcjoint_humanoid0_left_ankle_y"/>
        <jointvel joint="mjcjoint_humanoid0_left_ankle_y" name="mjcsensor_jointvelhumanoid0_sensJoint_mjcjoint_humanoid0_left_ankle_y"/>
        <jointpos joint="mjcjoint_humanoid0_left_ankle_x" name="mjcsensor_jointposhumanoid0_sensJoint_mjcjoint_humanoid0_left_ankle_x"/>
        <jointvel joint="mjcjoint_humanoid0_left_ankle_x" name="mjcsensor_jointvelhumanoid0_sensJoint_mjcjoint_humanoid0_left_ankle_x"/>
        <jointpos joint="mjcjoint_humanoid0_right_shoulder1" name="mjcsensor_jointposhumanoid0_sensJoint_mjcjoint_humanoid0_right_shoulder1"/>
        <jointvel joint="mjcjoint_humanoid0_right_shoulder1" name="mjcsensor_jointvelhumanoid0_sensJoint_mjcjoint_humanoid0_right_shoulder1"/>
        <jointpos joint="mjcjoint_humanoid0_right_shoulder2" name="mjcsensor_jointposhumanoid0_sensJoint_mjcjoint_humanoid0_right_shoulder2"/>
        <jointvel joint="mjcjoint_humanoid0_right_shoulder2" name="mjcsensor_jointvelhumanoid0_sensJoint_mjcjoint_humanoid0_right_shoulder2"/>
        <jointpos joint="mjcjoint_humanoid0_right_elbow" name="mjcsensor_jointposhumanoid0_sensJoint_mjcjoint_humanoid0_right_elbow"/>
        <jointvel joint="mjcjoint_humanoid0_right_elbow" name="mjcsensor_jointvelhumanoid0_sensJoint_mjcjoint_humanoid0_right_elbow"/>
        <jointpos joint="mjcjoint_humanoid0_left_shoulder1" name="mjcsensor_jointposhumanoid0_sensJoint_mjcjoint_humanoid0_left_shoulder1"/>
        <jointvel joint="mjcjoint_humanoid0_left_shoulder1" name="mjcsensor_jointvelhumanoid0_sensJoint_mjcjoint_humanoid0_left_shoulder1"/>
        <jointpos joint="mjcjoint_humanoid0_left_shoulder2" name="mjcsensor_jointposhumanoid0_sensJoint_mjcjoint_humanoid0_left_shoulder2"/>
        <jointvel joint="mjcjoint_humanoid0_left_shoulder2" name="mjcsensor_jointvelhumanoid0_sensJoint_mjcjoint_humanoid0_left_shoulder2"/>
        <jointpos joint="mjcjoint_humanoid0_left_elbow" name="mjcsensor_jointposhumanoid0_sensJoint_mjcjoint_humanoid0_left_elbow"/>
        <jointvel joint="mjcjoint_humanoid0_left_elbow" name="mjcsensor_jointvelhumanoid0_sensJoint_mjcjoint_humanoid0_left_elbow"/>
        <framelinvel name="mjcsensor_framelinvelhumanoid0_sensBody_mjcbody_humanoid0_tmjcroot" objname="mjcbody_humanoid0_tmjcroot" objtype="body"/>
        <framelinacc name="mjcsensor_framelinacchumanoid0_sensBody_mjcbody_humanoid0_tmjcroot" objname="mjcbody_humanoid0_tmjcroot" objtype="body"/>
        <framelinvel name="mjcsensor_framelinvelhumanoid0_sensBody_mjcbody_humanoid0_lwaist" objname="mjcbody_humanoid0_lwaist" objtype="body"/>
        <framelinacc name="mjcsensor_framelinacchumanoid0_sensBody_mjcbody_humanoid0_lwaist" objname="mjcbody_humanoid0_lwaist" objtype="body"/>
        <framelinvel name="mjcsensor_framelinvelhumanoid0_sensBody_mjcbody_humanoid0_pelvis" objname="mjcbody_humanoid0_pelvis" objtype="body"/>
        <framelinacc name="mjcsensor_framelinacchumanoid0_sensBody_mjcbody_humanoid0_pelvis" objname="mjcbody_humanoid0_pelvis" objtype="body"/>
        <framelinvel name="mjcsensor_framelinvelhumanoid0_sensBody_mjcbody_humanoid0_right_thigh" objname="mjcbody_humanoid0_right_thigh" objtype="body"/>
        <framelinacc name="mjcsensor_framelinacchumanoid0_sensBody_mjcbody_humanoid0_right_thigh" objname="mjcbody_humanoid0_right_thigh" objtype="body"/>
        <framelinvel name="mjcsensor_framelinvelhumanoid0_sensBody_mjcbody_humanoid0_right_shin" objname="mjcbody_humanoid0_right_shin" objtype="body"/>
        <framelinacc name="mjcsensor_framelinacchumanoid0_sensBody_mjcbody_humanoid0_right_shin" objname="mjcbody_humanoid0_right_shin" objtype="body"/>
        <framelinvel name="mjcsensor_framelinvelhumanoid0_sensBody_mjcbody_humanoid0_right_foot" objname="mjcbody_humanoid0_right_foot" objtype="body"/>
        <framelinacc name="mjcsensor_framelinacchumanoid0_sensBody_mjcbody_humanoid0_right_foot" objname="mjcbody_humanoid0_right_foot" objtype="body"/>
        <framelinvel name="mjcsensor_framelinvelhumanoid0_sensBody_mjcbody_humanoid0_left_thigh" objname="mjcbody_humanoid0_left_thigh" objtype="body"/>
        <framelinacc name="mjcsensor_framelinacchumanoid0_sensBody_mjcbody_humanoid0_left_thigh" objname="mjcbody_humanoid0_left_thigh" objtype="body"/>
        <framelinvel name="mjcsensor_framelinvelhumanoid0_sensBody_mjcbody_humanoid0_left_shin" objname="mjcbody_humanoid0_left_shin" objtype="body"/>
        <framelinacc name="mjcsensor_framelinacchumanoid0_sensBody_mjcbody_humanoid0_left_shin" objname="mjcbody_humanoid0_left_shin" objtype="body"/>
        <framelinvel name="mjcsensor_framelinvelhumanoid0_sensBody_mjcbody_humanoid0_left_foot" objname="mjcbody_humanoid0_left_foot" objtype="body"/>
        <framelinacc name="mjcsensor_framelinacchumanoid0_sensBody_mjcbody_humanoid0_left_foot" objname="mjcbody_humanoid0_left_foot" objtype="body"/>
        <framelinvel name="mjcsensor_framelinvelhumanoid0_sensBody_mjcbody_humanoid0_right_upper_arm" objname="mjcbody_humanoid0_right_upper_arm" objtype="body"/>
        <framelinacc name="mjcsensor_framelinacchumanoid0_sensBody_mjcbody_humanoid0_right_upper_arm" objname="mjcbody_humanoid0_right_upper_arm" objtype="body"/>
        <framelinvel name="mjcsensor_framelinvelhumanoid0_sensBody_mjcbody_humanoid0_right_lower_arm" objname="mjcbody_humanoid0_right_lower_arm" objtype="body"/>
        <framelinacc name="mjcsensor_framelinacchumanoid0_sensBody_mjcbody_humanoid0_right_lower_arm" objname="mjcbody_humanoid0_right_lower_arm" objtype="body"/>
        <framelinvel name="mjcsensor_framelinvelhumanoid0_sensBody_mjcbody_humanoid0_left_upper_arm" objname="mjcbody_humanoid0_left_upper_arm" objtype="body"/>
        <framelinacc name="mjcsensor_framelinacchumanoid0_sensBody_mjcbody_humanoid0_left_upper_arm" objname="mjcbody_humanoid0_left_upper_arm" objtype="body"/>
        <framelinvel name="mjcsensor_framelinvelhumanoid0_sensBody_mjcbody_humanoid0_left_lower_arm" objname="mjcbody_humanoid0_left_lower_arm" objtype="body"/>
        <framelinacc name="mjcsensor_framelinacchumanoid0_sensBody_mjcbody_humanoid0_left_lower_arm" objname="mjcbody_humanoid0_left_lower_arm" objtype="body"/>
    </sensor>
</mujoco>
