<mujoco>
    <include file="visual.xml"/>
    <include file="skybox.xml"/>
    <include file="materials.xml"/>
    <compiler angle="degree" inertiafromgeom="true"/>
    <option iterations="50" timestep="0.005000" tolerance="0.000000" cone="pyramidal" jacobian="dense" solver="Newton"/>
    <size nconmax="4000" njmax="8000"/>
    <statistic extent="2.000000" center="0.000000 0.000000 1.000000"/>
    <visual>
        <map force="0.100000" zfar="30.000000"/>
        <rgba haze="0.150000 0.250000 0.350000 1.000000"/>
        <quality shadowsize="2048"/>
        <global offheight="800" offwidth="800"/>
    </visual>
    <asset>
        <texture height="512" width="512" rgb1="0.300000 0.500000 0.700000" rgb2="0.000000 0.000000 0.000000" builtin="gradient" type="skybox"/>
        <texture height="512" width="512" markrgb="0.800000 0.800000 0.800000" rgb1="0.200000 0.300000 0.400000" rgb2="0.100000 0.150000 0.200000" builtin="checker" mark="cross" name="texplane" type="2d"/>
        <texture height="1278" width="127" random="0.010000" markrgb="1.000000 1.000000 1.000000" rgb1="0.800000 0.600000 0.400000" rgb2="0.800000 0.600000 0.400000" builtin="flat" mark="cross" name="texgeom" type="cube"/>
        <material reflectance="0.300000" texrepeat="1.000000 1.000000" name="matplane" texture="texplane" texuniform="true"/>
        <material rgba="0.800000 0.600000 0.400000 1.000000" name="matgeom" texture="texgeom" texuniform="true"/>
    </asset>
    <worldbody>
        <body pos="0.000000 0.000000 100.000000" quat="0.000000 0.000000 0.000000 1.000000" name="terrainGen_terrain_proc0_0">
            <geom conaffinity="1" contype="0" mass="1.000000" pos="0.000000 0.000000 0.000000" quat="0.000000 0.000000 0.000000 1.000000" size="0.250000 1.000000 0.012500" name="terrainGen_terrain_proc0_0" type="box"/>
        </body>
        <body pos="0.000000 0.000000 101.025002" quat="0.000000 0.000000 0.000000 1.000000" name="terrainGen_terrain_proc0_1">
            <geom conaffinity="1" contype="0" mass="1.000000" pos="0.000000 0.000000 0.000000" quat="0.000000 0.000000 0.000000 1.000000" size="0.250000 1.000000 0.012500" name="terrainGen_terrain_proc0_1" type="box"/>
        </body>
        <body pos="0.000000 0.000000 102.050003" quat="0.000000 0.000000 0.000000 1.000000" name="terrainGen_terrain_proc0_2">
            <geom conaffinity="1" contype="0" mass="1.000000" pos="0.000000 0.000000 0.000000" quat="0.000000 0.000000 0.000000 1.000000" size="0.250000 1.000000 0.012500" name="terrainGen_terrain_proc0_2" type="box"/>
        </body>
        <body pos="0.000000 0.000000 103.074997" quat="0.000000 0.000000 0.000000 1.000000" name="terrainGen_terrain_proc0_3">
            <geom conaffinity="1" contype="0" mass="1.000000" pos="0.000000 0.000000 0.000000" quat="0.000000 0.000000 0.000000 1.000000" size="0.250000 1.000000 0.012500" name="terrainGen_terrain_proc0_3" type="box"/>
        </body>
        <body pos="0.000000 0.000000 104.099998" quat="0.000000 0.000000 0.000000 1.000000" name="terrainGen_terrain_proc0_4">
            <geom conaffinity="1" contype="0" mass="1.000000" pos="0.000000 0.000000 0.000000" quat="0.000000 0.000000 0.000000 1.000000" size="0.250000 1.000000 0.012500" name="terrainGen_terrain_proc0_4" type="box"/>
        </body>
        <body pos="0.000000 0.000000 105.125000" quat="0.000000 0.000000 0.000000 1.000000" name="terrainGen_terrain_proc0_5">
            <geom conaffinity="1" contype="0" mass="1.000000" pos="0.000000 0.000000 0.000000" quat="0.000000 0.000000 0.000000 1.000000" size="0.250000 1.000000 0.012500" name="terrainGen_terrain_proc0_5" type="box"/>
        </body>
        <body pos="0.000000 0.000000 106.150002" quat="0.000000 0.000000 0.000000 1.000000" name="terrainGen_terrain_proc0_6">
            <geom conaffinity="1" contype="0" mass="1.000000" pos="0.000000 0.000000 0.000000" quat="0.000000 0.000000 0.000000 1.000000" size="0.250000 1.000000 0.012500" name="terrainGen_terrain_proc0_6" type="box"/>
        </body>
        <body pos="0.000000 0.000000 107.175003" quat="0.000000 0.000000 0.000000 1.000000" name="terrainGen_terrain_proc0_7">
            <geom conaffinity="1" contype="0" mass="1.000000" pos="0.000000 0.000000 0.000000" quat="0.000000 0.000000 0.000000 1.000000" size="0.250000 1.000000 0.012500" name="terrainGen_terrain_proc0_7" type="box"/>
        </body>
        <body pos="0.000000 0.000000 108.199997" quat="0.000000 0.000000 0.000000 1.000000" name="terrainGen_terrain_proc0_8">
            <geom conaffinity="1" contype="0" mass="1.000000" pos="0.000000 0.000000 0.000000" quat="0.000000 0.000000 0.000000 1.000000" size="0.250000 1.000000 0.012500" name="terrainGen_terrain_proc0_8" type="box"/>
        </body>
        <body pos="0.000000 0.000000 109.224998" quat="0.000000 0.000000 0.000000 1.000000" name="terrainGen_terrain_proc0_9">
            <geom conaffinity="1" contype="0" mass="1.000000" pos="0.000000 0.000000 0.000000" quat="0.000000 0.000000 0.000000 1.000000" size="0.250000 1.000000 0.012500" name="terrainGen_terrain_proc0_9" type="box"/>
        </body>
        <body pos="0.000000 0.000000 110.250000" quat="0.000000 0.000000 0.000000 1.000000" name="terrainGen_terrain_proc0_10">
            <geom conaffinity="1" contype="0" mass="1.000000" pos="0.000000 0.000000 0.000000" quat="0.000000 0.000000 0.000000 1.000000" size="0.250000 1.000000 0.012500" name="terrainGen_terrain_proc0_10" type="box"/>
        </body>
        <body pos="0.000000 0.000000 111.275002" quat="0.000000 0.000000 0.000000 1.000000" name="terrainGen_terrain_proc0_11">
            <geom conaffinity="1" contype="0" mass="1.000000" pos="0.000000 0.000000 0.000000" quat="0.000000 0.000000 0.000000 1.000000" size="0.250000 1.000000 0.012500" name="terrainGen_terrain_proc0_11" type="box"/>
        </body>
        <body pos="0.000000 0.000000 112.300003" quat="0.000000 0.000000 0.000000 1.000000" name="terrainGen_terrain_proc0_12">
            <geom conaffinity="1" contype="0" mass="1.000000" pos="0.000000 0.000000 0.000000" quat="0.000000 0.000000 0.000000 1.000000" size="0.250000 1.000000 0.012500" name="terrainGen_terrain_proc0_12" type="box"/>
        </body>
        <body pos="0.000000 0.000000 113.324997" quat="0.000000 0.000000 0.000000 1.000000" name="terrainGen_terrain_proc0_13">
            <geom conaffinity="1" contype="0" mass="1.000000" pos="0.000000 0.000000 0.000000" quat="0.000000 0.000000 0.000000 1.000000" size="0.250000 1.000000 0.012500" name="terrainGen_terrain_proc0_13" type="box"/>
        </body>
        <body pos="0.000000 0.000000 114.349998" quat="0.000000 0.000000 0.000000 1.000000" name="terrainGen_terrain_proc0_14">
            <geom conaffinity="1" contype="0" mass="1.000000" pos="0.000000 0.000000 0.000000" quat="0.000000 0.000000 0.000000 1.000000" size="0.250000 1.000000 0.012500" name="terrainGen_terrain_proc0_14" type="box"/>
        </body>
        <body pos="0.000000 0.000000 115.375000" quat="0.000000 0.000000 0.000000 1.000000" name="terrainGen_terrain_proc0_15">
            <geom conaffinity="1" contype="0" mass="1.000000" pos="0.000000 0.000000 0.000000" quat="0.000000 0.000000 0.000000 1.000000" size="0.250000 1.000000 0.012500" name="terrainGen_terrain_proc0_15" type="box"/>
        </body>
        <body pos="0.000000 0.000000 116.400002" quat="0.000000 0.000000 0.000000 1.000000" name="terrainGen_terrain_proc0_16">
            <geom conaffinity="1" contype="0" mass="1.000000" pos="0.000000 0.000000 0.000000" quat="0.000000 0.000000 0.000000 1.000000" size="0.250000 1.000000 0.012500" name="terrainGen_terrain_proc0_16" type="box"/>
        </body>
        <body pos="0.000000 0.000000 117.425003" quat="0.000000 0.000000 0.000000 1.000000" name="terrainGen_terrain_proc0_17">
            <geom conaffinity="1" contype="0" mass="1.000000" pos="0.000000 0.000000 0.000000" quat="0.000000 0.000000 0.000000 1.000000" size="0.250000 1.000000 0.012500" name="terrainGen_terrain_proc0_17" type="box"/>
        </body>
        <body pos="0.000000 0.000000 118.449997" quat="0.000000 0.000000 0.000000 1.000000" name="terrainGen_terrain_proc0_18">
            <geom conaffinity="1" contype="0" mass="1.000000" pos="0.000000 0.000000 0.000000" quat="0.000000 0.000000 0.000000 1.000000" size="0.250000 1.000000 0.012500" name="terrainGen_terrain_proc0_18" type="box"/>
        </body>
        <body pos="0.000000 0.000000 119.474998" quat="0.000000 0.000000 0.000000 1.000000" name="terrainGen_terrain_proc0_19">
            <geom conaffinity="1" contype="0" mass="1.000000" pos="0.000000 0.000000 0.000000" quat="0.000000 0.000000 0.000000 1.000000" size="0.250000 1.000000 0.012500" name="terrainGen_terrain_proc0_19" type="box"/>
        </body>
        <body pos="0.000000 0.000000 120.500000" quat="0.000000 0.000000 0.000000 1.000000" name="terrainGen_terrain_proc0_20">
            <geom conaffinity="1" contype="0" mass="1.000000" pos="0.000000 0.000000 0.000000" quat="0.000000 0.000000 0.000000 1.000000" size="0.250000 1.000000 0.012500" name="terrainGen_terrain_proc0_20" type="box"/>
        </body>
        <body pos="0.000000 0.000000 121.525002" quat="0.000000 0.000000 0.000000 1.000000" name="terrainGen_terrain_proc0_21">
            <geom conaffinity="1" contype="0" mass="1.000000" pos="0.000000 0.000000 0.000000" quat="0.000000 0.000000 0.000000 1.000000" size="0.250000 1.000000 0.012500" name="terrainGen_terrain_proc0_21" type="box"/>
        </body>
        <body pos="0.000000 0.000000 122.550003" quat="0.000000 0.000000 0.000000 1.000000" name="terrainGen_terrain_proc0_22">
            <geom conaffinity="1" contype="0" mass="1.000000" pos="0.000000 0.000000 0.000000" quat="0.000000 0.000000 0.000000 1.000000" size="0.250000 1.000000 0.012500" name="terrainGen_terrain_proc0_22" type="box"/>
        </body>
        <body pos="0.000000 0.000000 123.574997" quat="0.000000 0.000000 0.000000 1.000000" name="terrainGen_terrain_proc0_23">
            <geom conaffinity="1" contype="0" mass="1.000000" pos="0.000000 0.000000 0.000000" quat="0.000000 0.000000 0.000000 1.000000" size="0.250000 1.000000 0.012500" name="terrainGen_terrain_proc0_23" type="box"/>
        </body>
        <body pos="0.000000 0.000000 124.599998" quat="0.000000 0.000000 0.000000 1.000000" name="terrainGen_terrain_proc0_24">
            <geom conaffinity="1" contype="0" mass="1.000000" pos="0.000000 0.000000 0.000000" quat="0.000000 0.000000 0.000000 1.000000" size="0.250000 1.000000 0.012500" name="terrainGen_terrain_proc0_24" type="box"/>
        </body>
        <body pos="0.000000 0.000000 125.625000" quat="0.000000 0.000000 0.000000 1.000000" name="terrainGen_terrain_proc0_25">
            <geom conaffinity="1" contype="0" mass="1.000000" pos="0.000000 0.000000 0.000000" quat="0.000000 0.000000 0.000000 1.000000" size="0.250000 1.000000 0.012500" name="terrainGen_terrain_proc0_25" type="box"/>
        </body>
        <body pos="0.000000 0.000000 126.650002" quat="0.000000 0.000000 0.000000 1.000000" name="terrainGen_terrain_proc0_26">
            <geom conaffinity="1" contype="0" mass="1.000000" pos="0.000000 0.000000 0.000000" quat="0.000000 0.000000 0.000000 1.000000" size="0.250000 1.000000 0.012500" name="terrainGen_terrain_proc0_26" type="box"/>
        </body>
        <body pos="0.000000 0.000000 127.675003" quat="0.000000 0.000000 0.000000 1.000000" name="terrainGen_terrain_proc0_27">
            <geom conaffinity="1" contype="0" mass="1.000000" pos="0.000000 0.000000 0.000000" quat="0.000000 0.000000 0.000000 1.000000" size="0.250000 1.000000 0.012500" name="terrainGen_terrain_proc0_27" type="box"/>
        </body>
        <body pos="0.000000 0.000000 128.699997" quat="0.000000 0.000000 0.000000 1.000000" name="terrainGen_terrain_proc0_28">
            <geom conaffinity="1" contype="0" mass="1.000000" pos="0.000000 0.000000 0.000000" quat="0.000000 0.000000 0.000000 1.000000" size="0.250000 1.000000 0.012500" name="terrainGen_terrain_proc0_28" type="box"/>
        </body>
        <body pos="0.000000 0.000000 129.725006" quat="0.000000 0.000000 0.000000 1.000000" name="terrainGen_terrain_proc0_29">
            <geom conaffinity="1" contype="0" mass="1.000000" pos="0.000000 0.000000 0.000000" quat="0.000000 0.000000 0.000000 1.000000" size="0.250000 1.000000 0.012500" name="terrainGen_terrain_proc0_29" type="box"/>
        </body>
    </worldbody>
    <worldbody>
        <body pos="0.000000 0.000000 100.000000" quat="0.000000 0.000000 0.000000 1.000000" name="terrainGen_terrain_proc1_0">
            <geom conaffinity="1" contype="0" mass="1.000000" pos="0.000000 0.000000 0.000000" quat="0.000000 0.000000 0.000000 1.000000" size="0.250000 1.000000 0.012500" name="terrainGen_terrain_proc1_0" type="box"/>
        </body>
        <body pos="0.000000 0.000000 101.025002" quat="0.000000 0.000000 0.000000 1.000000" name="terrainGen_terrain_proc1_1">
            <geom conaffinity="1" contype="0" mass="1.000000" pos="0.000000 0.000000 0.000000" quat="0.000000 0.000000 0.000000 1.000000" size="0.250000 1.000000 0.012500" name="terrainGen_terrain_proc1_1" type="box"/>
        </body>
        <body pos="0.000000 0.000000 102.050003" quat="0.000000 0.000000 0.000000 1.000000" name="terrainGen_terrain_proc1_2">
            <geom conaffinity="1" contype="0" mass="1.000000" pos="0.000000 0.000000 0.000000" quat="0.000000 0.000000 0.000000 1.000000" size="0.250000 1.000000 0.012500" name="terrainGen_terrain_proc1_2" type="box"/>
        </body>
        <body pos="0.000000 0.000000 103.074997" quat="0.000000 0.000000 0.000000 1.000000" name="terrainGen_terrain_proc1_3">
            <geom conaffinity="1" contype="0" mass="1.000000" pos="0.000000 0.000000 0.000000" quat="0.000000 0.000000 0.000000 1.000000" size="0.250000 1.000000 0.012500" name="terrainGen_terrain_proc1_3" type="box"/>
        </body>
        <body pos="0.000000 0.000000 104.099998" quat="0.000000 0.000000 0.000000 1.000000" name="terrainGen_terrain_proc1_4">
            <geom conaffinity="1" contype="0" mass="1.000000" pos="0.000000 0.000000 0.000000" quat="0.000000 0.000000 0.000000 1.000000" size="0.250000 1.000000 0.012500" name="terrainGen_terrain_proc1_4" type="box"/>
        </body>
        <body pos="0.000000 0.000000 105.125000" quat="0.000000 0.000000 0.000000 1.000000" name="terrainGen_terrain_proc1_5">
            <geom conaffinity="1" contype="0" mass="1.000000" pos="0.000000 0.000000 0.000000" quat="0.000000 0.000000 0.000000 1.000000" size="0.250000 1.000000 0.012500" name="terrainGen_terrain_proc1_5" type="box"/>
        </body>
        <body pos="0.000000 0.000000 106.150002" quat="0.000000 0.000000 0.000000 1.000000" name="terrainGen_terrain_proc1_6">
            <geom conaffinity="1" contype="0" mass="1.000000" pos="0.000000 0.000000 0.000000" quat="0.000000 0.000000 0.000000 1.000000" size="0.250000 1.000000 0.012500" name="terrainGen_terrain_proc1_6" type="box"/>
        </body>
        <body pos="0.000000 0.000000 107.175003" quat="0.000000 0.000000 0.000000 1.000000" name="terrainGen_terrain_proc1_7">
            <geom conaffinity="1" contype="0" mass="1.000000" pos="0.000000 0.000000 0.000000" quat="0.000000 0.000000 0.000000 1.000000" size="0.250000 1.000000 0.012500" name="terrainGen_terrain_proc1_7" type="box"/>
        </body>
        <body pos="0.000000 0.000000 108.199997" quat="0.000000 0.000000 0.000000 1.000000" name="terrainGen_terrain_proc1_8">
            <geom conaffinity="1" contype="0" mass="1.000000" pos="0.000000 0.000000 0.000000" quat="0.000000 0.000000 0.000000 1.000000" size="0.250000 1.000000 0.012500" name="terrainGen_terrain_proc1_8" type="box"/>
        </body>
        <body pos="0.000000 0.000000 109.224998" quat="0.000000 0.000000 0.000000 1.000000" name="terrainGen_terrain_proc1_9">
            <geom conaffinity="1" contype="0" mass="1.000000" pos="0.000000 0.000000 0.000000" quat="0.000000 0.000000 0.000000 1.000000" size="0.250000 1.000000 0.012500" name="terrainGen_terrain_proc1_9" type="box"/>
        </body>
        <body pos="0.000000 0.000000 110.250000" quat="0.000000 0.000000 0.000000 1.000000" name="terrainGen_terrain_proc1_10">
            <geom conaffinity="1" contype="0" mass="1.000000" pos="0.000000 0.000000 0.000000" quat="0.000000 0.000000 0.000000 1.000000" size="0.250000 1.000000 0.012500" name="terrainGen_terrain_proc1_10" type="box"/>
        </body>
        <body pos="0.000000 0.000000 111.275002" quat="0.000000 0.000000 0.000000 1.000000" name="terrainGen_terrain_proc1_11">
            <geom conaffinity="1" contype="0" mass="1.000000" pos="0.000000 0.000000 0.000000" quat="0.000000 0.000000 0.000000 1.000000" size="0.250000 1.000000 0.012500" name="terrainGen_terrain_proc1_11" type="box"/>
        </body>
        <body pos="0.000000 0.000000 112.300003" quat="0.000000 0.000000 0.000000 1.000000" name="terrainGen_terrain_proc1_12">
            <geom conaffinity="1" contype="0" mass="1.000000" pos="0.000000 0.000000 0.000000" quat="0.000000 0.000000 0.000000 1.000000" size="0.250000 1.000000 0.012500" name="terrainGen_terrain_proc1_12" type="box"/>
        </body>
        <body pos="0.000000 0.000000 113.324997" quat="0.000000 0.000000 0.000000 1.000000" name="terrainGen_terrain_proc1_13">
            <geom conaffinity="1" contype="0" mass="1.000000" pos="0.000000 0.000000 0.000000" quat="0.000000 0.000000 0.000000 1.000000" size="0.250000 1.000000 0.012500" name="terrainGen_terrain_proc1_13" type="box"/>
        </body>
        <body pos="0.000000 0.000000 114.349998" quat="0.000000 0.000000 0.000000 1.000000" name="terrainGen_terrain_proc1_14">
            <geom conaffinity="1" contype="0" mass="1.000000" pos="0.000000 0.000000 0.000000" quat="0.000000 0.000000 0.000000 1.000000" size="0.250000 1.000000 0.012500" name="terrainGen_terrain_proc1_14" type="box"/>
        </body>
        <body pos="0.000000 0.000000 115.375000" quat="0.000000 0.000000 0.000000 1.000000" name="terrainGen_terrain_proc1_15">
            <geom conaffinity="1" contype="0" mass="1.000000" pos="0.000000 0.000000 0.000000" quat="0.000000 0.000000 0.000000 1.000000" size="0.250000 1.000000 0.012500" name="terrainGen_terrain_proc1_15" type="box"/>
        </body>
        <body pos="0.000000 0.000000 116.400002" quat="0.000000 0.000000 0.000000 1.000000" name="terrainGen_terrain_proc1_16">
            <geom conaffinity="1" contype="0" mass="1.000000" pos="0.000000 0.000000 0.000000" quat="0.000000 0.000000 0.000000 1.000000" size="0.250000 1.000000 0.012500" name="terrainGen_terrain_proc1_16" type="box"/>
        </body>
        <body pos="0.000000 0.000000 117.425003" quat="0.000000 0.000000 0.000000 1.000000" name="terrainGen_terrain_proc1_17">
            <geom conaffinity="1" contype="0" mass="1.000000" pos="0.000000 0.000000 0.000000" quat="0.000000 0.000000 0.000000 1.000000" size="0.250000 1.000000 0.012500" name="terrainGen_terrain_proc1_17" type="box"/>
        </body>
        <body pos="0.000000 0.000000 118.449997" quat="0.000000 0.000000 0.000000 1.000000" name="terrainGen_terrain_proc1_18">
            <geom conaffinity="1" contype="0" mass="1.000000" pos="0.000000 0.000000 0.000000" quat="0.000000 0.000000 0.000000 1.000000" size="0.250000 1.000000 0.012500" name="terrainGen_terrain_proc1_18" type="box"/>
        </body>
        <body pos="0.000000 0.000000 119.474998" quat="0.000000 0.000000 0.000000 1.000000" name="terrainGen_terrain_proc1_19">
            <geom conaffinity="1" contype="0" mass="1.000000" pos="0.000000 0.000000 0.000000" quat="0.000000 0.000000 0.000000 1.000000" size="0.250000 1.000000 0.012500" name="terrainGen_terrain_proc1_19" type="box"/>
        </body>
        <body pos="0.000000 0.000000 120.500000" quat="0.000000 0.000000 0.000000 1.000000" name="terrainGen_terrain_proc1_20">
            <geom conaffinity="1" contype="0" mass="1.000000" pos="0.000000 0.000000 0.000000" quat="0.000000 0.000000 0.000000 1.000000" size="0.250000 1.000000 0.012500" name="terrainGen_terrain_proc1_20" type="box"/>
        </body>
        <body pos="0.000000 0.000000 121.525002" quat="0.000000 0.000000 0.000000 1.000000" name="terrainGen_terrain_proc1_21">
            <geom conaffinity="1" contype="0" mass="1.000000" pos="0.000000 0.000000 0.000000" quat="0.000000 0.000000 0.000000 1.000000" size="0.250000 1.000000 0.012500" name="terrainGen_terrain_proc1_21" type="box"/>
        </body>
        <body pos="0.000000 0.000000 122.550003" quat="0.000000 0.000000 0.000000 1.000000" name="terrainGen_terrain_proc1_22">
            <geom conaffinity="1" contype="0" mass="1.000000" pos="0.000000 0.000000 0.000000" quat="0.000000 0.000000 0.000000 1.000000" size="0.250000 1.000000 0.012500" name="terrainGen_terrain_proc1_22" type="box"/>
        </body>
        <body pos="0.000000 0.000000 123.574997" quat="0.000000 0.000000 0.000000 1.000000" name="terrainGen_terrain_proc1_23">
            <geom conaffinity="1" contype="0" mass="1.000000" pos="0.000000 0.000000 0.000000" quat="0.000000 0.000000 0.000000 1.000000" size="0.250000 1.000000 0.012500" name="terrainGen_terrain_proc1_23" type="box"/>
        </body>
        <body pos="0.000000 0.000000 124.599998" quat="0.000000 0.000000 0.000000 1.000000" name="terrainGen_terrain_proc1_24">
            <geom conaffinity="1" contype="0" mass="1.000000" pos="0.000000 0.000000 0.000000" quat="0.000000 0.000000 0.000000 1.000000" size="0.250000 1.000000 0.012500" name="terrainGen_terrain_proc1_24" type="box"/>
        </body>
        <body pos="0.000000 0.000000 125.625000" quat="0.000000 0.000000 0.000000 1.000000" name="terrainGen_terrain_proc1_25">
            <geom conaffinity="1" contype="0" mass="1.000000" pos="0.000000 0.000000 0.000000" quat="0.000000 0.000000 0.000000 1.000000" size="0.250000 1.000000 0.012500" name="terrainGen_terrain_proc1_25" type="box"/>
        </body>
        <body pos="0.000000 0.000000 126.650002" quat="0.000000 0.000000 0.000000 1.000000" name="terrainGen_terrain_proc1_26">
            <geom conaffinity="1" contype="0" mass="1.000000" pos="0.000000 0.000000 0.000000" quat="0.000000 0.000000 0.000000 1.000000" size="0.250000 1.000000 0.012500" name="terrainGen_terrain_proc1_26" type="box"/>
        </body>
        <body pos="0.000000 0.000000 127.675003" quat="0.000000 0.000000 0.000000 1.000000" name="terrainGen_terrain_proc1_27">
            <geom conaffinity="1" contype="0" mass="1.000000" pos="0.000000 0.000000 0.000000" quat="0.000000 0.000000 0.000000 1.000000" size="0.250000 1.000000 0.012500" name="terrainGen_terrain_proc1_27" type="box"/>
        </body>
        <body pos="0.000000 0.000000 128.699997" quat="0.000000 0.000000 0.000000 1.000000" name="terrainGen_terrain_proc1_28">
            <geom conaffinity="1" contype="0" mass="1.000000" pos="0.000000 0.000000 0.000000" quat="0.000000 0.000000 0.000000 1.000000" size="0.250000 1.000000 0.012500" name="terrainGen_terrain_proc1_28" type="box"/>
        </body>
        <body pos="0.000000 0.000000 129.725006" quat="0.000000 0.000000 0.000000 1.000000" name="terrainGen_terrain_proc1_29">
            <geom conaffinity="1" contype="0" mass="1.000000" pos="0.000000 0.000000 0.000000" quat="0.000000 0.000000 0.000000 1.000000" size="0.250000 1.000000 0.012500" name="terrainGen_terrain_proc1_29" type="box"/>
        </body>
    </worldbody>
    <worldbody>
        <body pos="0.000000 0.000000 100.000000" quat="0.000000 0.000000 0.000000 1.000000" name="terrainGen_terrain_proc2_0">
            <geom conaffinity="1" contype="0" mass="1.000000" pos="0.000000 0.000000 0.000000" quat="0.000000 0.000000 0.000000 1.000000" size="0.250000 1.000000 0.012500" name="terrainGen_terrain_proc2_0" type="box"/>
        </body>
        <body pos="0.000000 0.000000 101.025002" quat="0.000000 0.000000 0.000000 1.000000" name="terrainGen_terrain_proc2_1">
            <geom conaffinity="1" contype="0" mass="1.000000" pos="0.000000 0.000000 0.000000" quat="0.000000 0.000000 0.000000 1.000000" size="0.250000 1.000000 0.012500" name="terrainGen_terrain_proc2_1" type="box"/>
        </body>
        <body pos="0.000000 0.000000 102.050003" quat="0.000000 0.000000 0.000000 1.000000" name="terrainGen_terrain_proc2_2">
            <geom conaffinity="1" contype="0" mass="1.000000" pos="0.000000 0.000000 0.000000" quat="0.000000 0.000000 0.000000 1.000000" size="0.250000 1.000000 0.012500" name="terrainGen_terrain_proc2_2" type="box"/>
        </body>
        <body pos="0.000000 0.000000 103.074997" quat="0.000000 0.000000 0.000000 1.000000" name="terrainGen_terrain_proc2_3">
            <geom conaffinity="1" contype="0" mass="1.000000" pos="0.000000 0.000000 0.000000" quat="0.000000 0.000000 0.000000 1.000000" size="0.250000 1.000000 0.012500" name="terrainGen_terrain_proc2_3" type="box"/>
        </body>
        <body pos="0.000000 0.000000 104.099998" quat="0.000000 0.000000 0.000000 1.000000" name="terrainGen_terrain_proc2_4">
            <geom conaffinity="1" contype="0" mass="1.000000" pos="0.000000 0.000000 0.000000" quat="0.000000 0.000000 0.000000 1.000000" size="0.250000 1.000000 0.012500" name="terrainGen_terrain_proc2_4" type="box"/>
        </body>
        <body pos="0.000000 0.000000 105.125000" quat="0.000000 0.000000 0.000000 1.000000" name="terrainGen_terrain_proc2_5">
            <geom conaffinity="1" contype="0" mass="1.000000" pos="0.000000 0.000000 0.000000" quat="0.000000 0.000000 0.000000 1.000000" size="0.250000 1.000000 0.012500" name="terrainGen_terrain_proc2_5" type="box"/>
        </body>
        <body pos="0.000000 0.000000 106.150002" quat="0.000000 0.000000 0.000000 1.000000" name="terrainGen_terrain_proc2_6">
            <geom conaffinity="1" contype="0" mass="1.000000" pos="0.000000 0.000000 0.000000" quat="0.000000 0.000000 0.000000 1.000000" size="0.250000 1.000000 0.012500" name="terrainGen_terrain_proc2_6" type="box"/>
        </body>
        <body pos="0.000000 0.000000 107.175003" quat="0.000000 0.000000 0.000000 1.000000" name="terrainGen_terrain_proc2_7">
            <geom conaffinity="1" contype="0" mass="1.000000" pos="0.000000 0.000000 0.000000" quat="0.000000 0.000000 0.000000 1.000000" size="0.250000 1.000000 0.012500" name="terrainGen_terrain_proc2_7" type="box"/>
        </body>
        <body pos="0.000000 0.000000 108.199997" quat="0.000000 0.000000 0.000000 1.000000" name="terrainGen_terrain_proc2_8">
            <geom conaffinity="1" contype="0" mass="1.000000" pos="0.000000 0.000000 0.000000" quat="0.000000 0.000000 0.000000 1.000000" size="0.250000 1.000000 0.012500" name="terrainGen_terrain_proc2_8" type="box"/>
        </body>
        <body pos="0.000000 0.000000 109.224998" quat="0.000000 0.000000 0.000000 1.000000" name="terrainGen_terrain_proc2_9">
            <geom conaffinity="1" contype="0" mass="1.000000" pos="0.000000 0.000000 0.000000" quat="0.000000 0.000000 0.000000 1.000000" size="0.250000 1.000000 0.012500" name="terrainGen_terrain_proc2_9" type="box"/>
        </body>
        <body pos="0.000000 0.000000 110.250000" quat="0.000000 0.000000 0.000000 1.000000" name="terrainGen_terrain_proc2_10">
            <geom conaffinity="1" contype="0" mass="1.000000" pos="0.000000 0.000000 0.000000" quat="0.000000 0.000000 0.000000 1.000000" size="0.250000 1.000000 0.012500" name="terrainGen_terrain_proc2_10" type="box"/>
        </body>
        <body pos="0.000000 0.000000 111.275002" quat="0.000000 0.000000 0.000000 1.000000" name="terrainGen_terrain_proc2_11">
            <geom conaffinity="1" contype="0" mass="1.000000" pos="0.000000 0.000000 0.000000" quat="0.000000 0.000000 0.000000 1.000000" size="0.250000 1.000000 0.012500" name="terrainGen_terrain_proc2_11" type="box"/>
        </body>
        <body pos="0.000000 0.000000 112.300003" quat="0.000000 0.000000 0.000000 1.000000" name="terrainGen_terrain_proc2_12">
            <geom conaffinity="1" contype="0" mass="1.000000" pos="0.000000 0.000000 0.000000" quat="0.000000 0.000000 0.000000 1.000000" size="0.250000 1.000000 0.012500" name="terrainGen_terrain_proc2_12" type="box"/>
        </body>
        <body pos="0.000000 0.000000 113.324997" quat="0.000000 0.000000 0.000000 1.000000" name="terrainGen_terrain_proc2_13">
            <geom conaffinity="1" contype="0" mass="1.000000" pos="0.000000 0.000000 0.000000" quat="0.000000 0.000000 0.000000 1.000000" size="0.250000 1.000000 0.012500" name="terrainGen_terrain_proc2_13" type="box"/>
        </body>
        <body pos="0.000000 0.000000 114.349998" quat="0.000000 0.000000 0.000000 1.000000" name="terrainGen_terrain_proc2_14">
            <geom conaffinity="1" contype="0" mass="1.000000" pos="0.000000 0.000000 0.000000" quat="0.000000 0.000000 0.000000 1.000000" size="0.250000 1.000000 0.012500" name="terrainGen_terrain_proc2_14" type="box"/>
        </body>
        <body pos="0.000000 0.000000 115.375000" quat="0.000000 0.000000 0.000000 1.000000" name="terrainGen_terrain_proc2_15">
            <geom conaffinity="1" contype="0" mass="1.000000" pos="0.000000 0.000000 0.000000" quat="0.000000 0.000000 0.000000 1.000000" size="0.250000 1.000000 0.012500" name="terrainGen_terrain_proc2_15" type="box"/>
        </body>
        <body pos="0.000000 0.000000 116.400002" quat="0.000000 0.000000 0.000000 1.000000" name="terrainGen_terrain_proc2_16">
            <geom conaffinity="1" contype="0" mass="1.000000" pos="0.000000 0.000000 0.000000" quat="0.000000 0.000000 0.000000 1.000000" size="0.250000 1.000000 0.012500" name="terrainGen_terrain_proc2_16" type="box"/>
        </body>
        <body pos="0.000000 0.000000 117.425003" quat="0.000000 0.000000 0.000000 1.000000" name="terrainGen_terrain_proc2_17">
            <geom conaffinity="1" contype="0" mass="1.000000" pos="0.000000 0.000000 0.000000" quat="0.000000 0.000000 0.000000 1.000000" size="0.250000 1.000000 0.012500" name="terrainGen_terrain_proc2_17" type="box"/>
        </body>
        <body pos="0.000000 0.000000 118.449997" quat="0.000000 0.000000 0.000000 1.000000" name="terrainGen_terrain_proc2_18">
            <geom conaffinity="1" contype="0" mass="1.000000" pos="0.000000 0.000000 0.000000" quat="0.000000 0.000000 0.000000 1.000000" size="0.250000 1.000000 0.012500" name="terrainGen_terrain_proc2_18" type="box"/>
        </body>
        <body pos="0.000000 0.000000 119.474998" quat="0.000000 0.000000 0.000000 1.000000" name="terrainGen_terrain_proc2_19">
            <geom conaffinity="1" contype="0" mass="1.000000" pos="0.000000 0.000000 0.000000" quat="0.000000 0.000000 0.000000 1.000000" size="0.250000 1.000000 0.012500" name="terrainGen_terrain_proc2_19" type="box"/>
        </body>
        <body pos="0.000000 0.000000 120.500000" quat="0.000000 0.000000 0.000000 1.000000" name="terrainGen_terrain_proc2_20">
            <geom conaffinity="1" contype="0" mass="1.000000" pos="0.000000 0.000000 0.000000" quat="0.000000 0.000000 0.000000 1.000000" size="0.250000 1.000000 0.012500" name="terrainGen_terrain_proc2_20" type="box"/>
        </body>
        <body pos="0.000000 0.000000 121.525002" quat="0.000000 0.000000 0.000000 1.000000" name="terrainGen_terrain_proc2_21">
            <geom conaffinity="1" contype="0" mass="1.000000" pos="0.000000 0.000000 0.000000" quat="0.000000 0.000000 0.000000 1.000000" size="0.250000 1.000000 0.012500" name="terrainGen_terrain_proc2_21" type="box"/>
        </body>
        <body pos="0.000000 0.000000 122.550003" quat="0.000000 0.000000 0.000000 1.000000" name="terrainGen_terrain_proc2_22">
            <geom conaffinity="1" contype="0" mass="1.000000" pos="0.000000 0.000000 0.000000" quat="0.000000 0.000000 0.000000 1.000000" size="0.250000 1.000000 0.012500" name="terrainGen_terrain_proc2_22" type="box"/>
        </body>
        <body pos="0.000000 0.000000 123.574997" quat="0.000000 0.000000 0.000000 1.000000" name="terrainGen_terrain_proc2_23">
            <geom conaffinity="1" contype="0" mass="1.000000" pos="0.000000 0.000000 0.000000" quat="0.000000 0.000000 0.000000 1.000000" size="0.250000 1.000000 0.012500" name="terrainGen_terrain_proc2_23" type="box"/>
        </body>
        <body pos="0.000000 0.000000 124.599998" quat="0.000000 0.000000 0.000000 1.000000" name="terrainGen_terrain_proc2_24">
            <geom conaffinity="1" contype="0" mass="1.000000" pos="0.000000 0.000000 0.000000" quat="0.000000 0.000000 0.000000 1.000000" size="0.250000 1.000000 0.012500" name="terrainGen_terrain_proc2_24" type="box"/>
        </body>
        <body pos="0.000000 0.000000 125.625000" quat="0.000000 0.000000 0.000000 1.000000" name="terrainGen_terrain_proc2_25">
            <geom conaffinity="1" contype="0" mass="1.000000" pos="0.000000 0.000000 0.000000" quat="0.000000 0.000000 0.000000 1.000000" size="0.250000 1.000000 0.012500" name="terrainGen_terrain_proc2_25" type="box"/>
        </body>
        <body pos="0.000000 0.000000 126.650002" quat="0.000000 0.000000 0.000000 1.000000" name="terrainGen_terrain_proc2_26">
            <geom conaffinity="1" contype="0" mass="1.000000" pos="0.000000 0.000000 0.000000" quat="0.000000 0.000000 0.000000 1.000000" size="0.250000 1.000000 0.012500" name="terrainGen_terrain_proc2_26" type="box"/>
        </body>
        <body pos="0.000000 0.000000 127.675003" quat="0.000000 0.000000 0.000000 1.000000" name="terrainGen_terrain_proc2_27">
            <geom conaffinity="1" contype="0" mass="1.000000" pos="0.000000 0.000000 0.000000" quat="0.000000 0.000000 0.000000 1.000000" size="0.250000 1.000000 0.012500" name="terrainGen_terrain_proc2_27" type="box"/>
        </body>
        <body pos="0.000000 0.000000 128.699997" quat="0.000000 0.000000 0.000000 1.000000" name="terrainGen_terrain_proc2_28">
            <geom conaffinity="1" contype="0" mass="1.000000" pos="0.000000 0.000000 0.000000" quat="0.000000 0.000000 0.000000 1.000000" size="0.250000 1.000000 0.012500" name="terrainGen_terrain_proc2_28" type="box"/>
        </body>
        <body pos="0.000000 0.000000 129.725006" quat="0.000000 0.000000 0.000000 1.000000" name="terrainGen_terrain_proc2_29">
            <geom conaffinity="1" contype="0" mass="1.000000" pos="0.000000 0.000000 0.000000" quat="0.000000 0.000000 0.000000 1.000000" size="0.250000 1.000000 0.012500" name="terrainGen_terrain_proc2_29" type="box"/>
        </body>
    </worldbody>
    <worldbody>
        <body pos="0.000000 0.000000 100.000000" quat="0.000000 0.000000 0.000000 1.000000" name="terrainGen_terrain_proc3_0">
            <geom conaffinity="1" contype="0" mass="1.000000" pos="0.000000 0.000000 0.000000" quat="0.000000 0.000000 0.000000 1.000000" size="0.250000 1.000000 0.012500" name="terrainGen_terrain_proc3_0" type="box"/>
        </body>
        <body pos="0.000000 0.000000 101.025002" quat="0.000000 0.000000 0.000000 1.000000" name="terrainGen_terrain_proc3_1">
            <geom conaffinity="1" contype="0" mass="1.000000" pos="0.000000 0.000000 0.000000" quat="0.000000 0.000000 0.000000 1.000000" size="0.250000 1.000000 0.012500" name="terrainGen_terrain_proc3_1" type="box"/>
        </body>
        <body pos="0.000000 0.000000 102.050003" quat="0.000000 0.000000 0.000000 1.000000" name="terrainGen_terrain_proc3_2">
            <geom conaffinity="1" contype="0" mass="1.000000" pos="0.000000 0.000000 0.000000" quat="0.000000 0.000000 0.000000 1.000000" size="0.250000 1.000000 0.012500" name="terrainGen_terrain_proc3_2" type="box"/>
        </body>
        <body pos="0.000000 0.000000 103.074997" quat="0.000000 0.000000 0.000000 1.000000" name="terrainGen_terrain_proc3_3">
            <geom conaffinity="1" contype="0" mass="1.000000" pos="0.000000 0.000000 0.000000" quat="0.000000 0.000000 0.000000 1.000000" size="0.250000 1.000000 0.012500" name="terrainGen_terrain_proc3_3" type="box"/>
        </body>
        <body pos="0.000000 0.000000 104.099998" quat="0.000000 0.000000 0.000000 1.000000" name="terrainGen_terrain_proc3_4">
            <geom conaffinity="1" contype="0" mass="1.000000" pos="0.000000 0.000000 0.000000" quat="0.000000 0.000000 0.000000 1.000000" size="0.250000 1.000000 0.012500" name="terrainGen_terrain_proc3_4" type="box"/>
        </body>
        <body pos="0.000000 0.000000 105.125000" quat="0.000000 0.000000 0.000000 1.000000" name="terrainGen_terrain_proc3_5">
            <geom conaffinity="1" contype="0" mass="1.000000" pos="0.000000 0.000000 0.000000" quat="0.000000 0.000000 0.000000 1.000000" size="0.250000 1.000000 0.012500" name="terrainGen_terrain_proc3_5" type="box"/>
        </body>
        <body pos="0.000000 0.000000 106.150002" quat="0.000000 0.000000 0.000000 1.000000" name="terrainGen_terrain_proc3_6">
            <geom conaffinity="1" contype="0" mass="1.000000" pos="0.000000 0.000000 0.000000" quat="0.000000 0.000000 0.000000 1.000000" size="0.250000 1.000000 0.012500" name="terrainGen_terrain_proc3_6" type="box"/>
        </body>
        <body pos="0.000000 0.000000 107.175003" quat="0.000000 0.000000 0.000000 1.000000" name="terrainGen_terrain_proc3_7">
            <geom conaffinity="1" contype="0" mass="1.000000" pos="0.000000 0.000000 0.000000" quat="0.000000 0.000000 0.000000 1.000000" size="0.250000 1.000000 0.012500" name="terrainGen_terrain_proc3_7" type="box"/>
        </body>
        <body pos="0.000000 0.000000 108.199997" quat="0.000000 0.000000 0.000000 1.000000" name="terrainGen_terrain_proc3_8">
            <geom conaffinity="1" contype="0" mass="1.000000" pos="0.000000 0.000000 0.000000" quat="0.000000 0.000000 0.000000 1.000000" size="0.250000 1.000000 0.012500" name="terrainGen_terrain_proc3_8" type="box"/>
        </body>
        <body pos="0.000000 0.000000 109.224998" quat="0.000000 0.000000 0.000000 1.000000" name="terrainGen_terrain_proc3_9">
            <geom conaffinity="1" contype="0" mass="1.000000" pos="0.000000 0.000000 0.000000" quat="0.000000 0.000000 0.000000 1.000000" size="0.250000 1.000000 0.012500" name="terrainGen_terrain_proc3_9" type="box"/>
        </body>
        <body pos="0.000000 0.000000 110.250000" quat="0.000000 0.000000 0.000000 1.000000" name="terrainGen_terrain_proc3_10">
            <geom conaffinity="1" contype="0" mass="1.000000" pos="0.000000 0.000000 0.000000" quat="0.000000 0.000000 0.000000 1.000000" size="0.250000 1.000000 0.012500" name="terrainGen_terrain_proc3_10" type="box"/>
        </body>
        <body pos="0.000000 0.000000 111.275002" quat="0.000000 0.000000 0.000000 1.000000" name="terrainGen_terrain_proc3_11">
            <geom conaffinity="1" contype="0" mass="1.000000" pos="0.000000 0.000000 0.000000" quat="0.000000 0.000000 0.000000 1.000000" size="0.250000 1.000000 0.012500" name="terrainGen_terrain_proc3_11" type="box"/>
        </body>
        <body pos="0.000000 0.000000 112.300003" quat="0.000000 0.000000 0.000000 1.000000" name="terrainGen_terrain_proc3_12">
            <geom conaffinity="1" contype="0" mass="1.000000" pos="0.000000 0.000000 0.000000" quat="0.000000 0.000000 0.000000 1.000000" size="0.250000 1.000000 0.012500" name="terrainGen_terrain_proc3_12" type="box"/>
        </body>
        <body pos="0.000000 0.000000 113.324997" quat="0.000000 0.000000 0.000000 1.000000" name="terrainGen_terrain_proc3_13">
            <geom conaffinity="1" contype="0" mass="1.000000" pos="0.000000 0.000000 0.000000" quat="0.000000 0.000000 0.000000 1.000000" size="0.250000 1.000000 0.012500" name="terrainGen_terrain_proc3_13" type="box"/>
        </body>
        <body pos="0.000000 0.000000 114.349998" quat="0.000000 0.000000 0.000000 1.000000" name="terrainGen_terrain_proc3_14">
            <geom conaffinity="1" contype="0" mass="1.000000" pos="0.000000 0.000000 0.000000" quat="0.000000 0.000000 0.000000 1.000000" size="0.250000 1.000000 0.012500" name="terrainGen_terrain_proc3_14" type="box"/>
        </body>
        <body pos="0.000000 0.000000 115.375000" quat="0.000000 0.000000 0.000000 1.000000" name="terrainGen_terrain_proc3_15">
            <geom conaffinity="1" contype="0" mass="1.000000" pos="0.000000 0.000000 0.000000" quat="0.000000 0.000000 0.000000 1.000000" size="0.250000 1.000000 0.012500" name="terrainGen_terrain_proc3_15" type="box"/>
        </body>
        <body pos="0.000000 0.000000 116.400002" quat="0.000000 0.000000 0.000000 1.000000" name="terrainGen_terrain_proc3_16">
            <geom conaffinity="1" contype="0" mass="1.000000" pos="0.000000 0.000000 0.000000" quat="0.000000 0.000000 0.000000 1.000000" size="0.250000 1.000000 0.012500" name="terrainGen_terrain_proc3_16" type="box"/>
        </body>
        <body pos="0.000000 0.000000 117.425003" quat="0.000000 0.000000 0.000000 1.000000" name="terrainGen_terrain_proc3_17">
            <geom conaffinity="1" contype="0" mass="1.000000" pos="0.000000 0.000000 0.000000" quat="0.000000 0.000000 0.000000 1.000000" size="0.250000 1.000000 0.012500" name="terrainGen_terrain_proc3_17" type="box"/>
        </body>
        <body pos="0.000000 0.000000 118.449997" quat="0.000000 0.000000 0.000000 1.000000" name="terrainGen_terrain_proc3_18">
            <geom conaffinity="1" contype="0" mass="1.000000" pos="0.000000 0.000000 0.000000" quat="0.000000 0.000000 0.000000 1.000000" size="0.250000 1.000000 0.012500" name="terrainGen_terrain_proc3_18" type="box"/>
        </body>
        <body pos="0.000000 0.000000 119.474998" quat="0.000000 0.000000 0.000000 1.000000" name="terrainGen_terrain_proc3_19">
            <geom conaffinity="1" contype="0" mass="1.000000" pos="0.000000 0.000000 0.000000" quat="0.000000 0.000000 0.000000 1.000000" size="0.250000 1.000000 0.012500" name="terrainGen_terrain_proc3_19" type="box"/>
        </body>
        <body pos="0.000000 0.000000 120.500000" quat="0.000000 0.000000 0.000000 1.000000" name="terrainGen_terrain_proc3_20">
            <geom conaffinity="1" contype="0" mass="1.000000" pos="0.000000 0.000000 0.000000" quat="0.000000 0.000000 0.000000 1.000000" size="0.250000 1.000000 0.012500" name="terrainGen_terrain_proc3_20" type="box"/>
        </body>
        <body pos="0.000000 0.000000 121.525002" quat="0.000000 0.000000 0.000000 1.000000" name="terrainGen_terrain_proc3_21">
            <geom conaffinity="1" contype="0" mass="1.000000" pos="0.000000 0.000000 0.000000" quat="0.000000 0.000000 0.000000 1.000000" size="0.250000 1.000000 0.012500" name="terrainGen_terrain_proc3_21" type="box"/>
        </body>
        <body pos="0.000000 0.000000 122.550003" quat="0.000000 0.000000 0.000000 1.000000" name="terrainGen_terrain_proc3_22">
            <geom conaffinity="1" contype="0" mass="1.000000" pos="0.000000 0.000000 0.000000" quat="0.000000 0.000000 0.000000 1.000000" size="0.250000 1.000000 0.012500" name="terrainGen_terrain_proc3_22" type="box"/>
        </body>
        <body pos="0.000000 0.000000 123.574997" quat="0.000000 0.000000 0.000000 1.000000" name="terrainGen_terrain_proc3_23">
            <geom conaffinity="1" contype="0" mass="1.000000" pos="0.000000 0.000000 0.000000" quat="0.000000 0.000000 0.000000 1.000000" size="0.250000 1.000000 0.012500" name="terrainGen_terrain_proc3_23" type="box"/>
        </body>
        <body pos="0.000000 0.000000 124.599998" quat="0.000000 0.000000 0.000000 1.000000" name="terrainGen_terrain_proc3_24">
            <geom conaffinity="1" contype="0" mass="1.000000" pos="0.000000 0.000000 0.000000" quat="0.000000 0.000000 0.000000 1.000000" size="0.250000 1.000000 0.012500" name="terrainGen_terrain_proc3_24" type="box"/>
        </body>
        <body pos="0.000000 0.000000 125.625000" quat="0.000000 0.000000 0.000000 1.000000" name="terrainGen_terrain_proc3_25">
            <geom conaffinity="1" contype="0" mass="1.000000" pos="0.000000 0.000000 0.000000" quat="0.000000 0.000000 0.000000 1.000000" size="0.250000 1.000000 0.012500" name="terrainGen_terrain_proc3_25" type="box"/>
        </body>
        <body pos="0.000000 0.000000 126.650002" quat="0.000000 0.000000 0.000000 1.000000" name="terrainGen_terrain_proc3_26">
            <geom conaffinity="1" contype="0" mass="1.000000" pos="0.000000 0.000000 0.000000" quat="0.000000 0.000000 0.000000 1.000000" size="0.250000 1.000000 0.012500" name="terrainGen_terrain_proc3_26" type="box"/>
        </body>
        <body pos="0.000000 0.000000 127.675003" quat="0.000000 0.000000 0.000000 1.000000" name="terrainGen_terrain_proc3_27">
            <geom conaffinity="1" contype="0" mass="1.000000" pos="0.000000 0.000000 0.000000" quat="0.000000 0.000000 0.000000 1.000000" size="0.250000 1.000000 0.012500" name="terrainGen_terrain_proc3_27" type="box"/>
        </body>
        <body pos="0.000000 0.000000 128.699997" quat="0.000000 0.000000 0.000000 1.000000" name="terrainGen_terrain_proc3_28">
            <geom conaffinity="1" contype="0" mass="1.000000" pos="0.000000 0.000000 0.000000" quat="0.000000 0.000000 0.000000 1.000000" size="0.250000 1.000000 0.012500" name="terrainGen_terrain_proc3_28" type="box"/>
        </body>
        <body pos="0.000000 0.000000 129.725006" quat="0.000000 0.000000 0.000000 1.000000" name="terrainGen_terrain_proc3_29">
            <geom conaffinity="1" contype="0" mass="1.000000" pos="0.000000 0.000000 0.000000" quat="0.000000 0.000000 0.000000 1.000000" size="0.250000 1.000000 0.012500" name="terrainGen_terrain_proc3_29" type="box"/>
        </body>
    </worldbody>
    <worldbody>
        <body pos="0.000000 0.000000 100.000000" quat="0.000000 0.000000 0.000000 1.000000" name="terrainGen_terrain_proc4_0">
            <geom conaffinity="1" contype="0" mass="1.000000" pos="0.000000 0.000000 0.000000" quat="0.000000 0.000000 0.000000 1.000000" size="0.250000 1.000000 0.012500" name="terrainGen_terrain_proc4_0" type="box"/>
        </body>
        <body pos="0.000000 0.000000 101.025002" quat="0.000000 0.000000 0.000000 1.000000" name="terrainGen_terrain_proc4_1">
            <geom conaffinity="1" contype="0" mass="1.000000" pos="0.000000 0.000000 0.000000" quat="0.000000 0.000000 0.000000 1.000000" size="0.250000 1.000000 0.012500" name="terrainGen_terrain_proc4_1" type="box"/>
        </body>
        <body pos="0.000000 0.000000 102.050003" quat="0.000000 0.000000 0.000000 1.000000" name="terrainGen_terrain_proc4_2">
            <geom conaffinity="1" contype="0" mass="1.000000" pos="0.000000 0.000000 0.000000" quat="0.000000 0.000000 0.000000 1.000000" size="0.250000 1.000000 0.012500" name="terrainGen_terrain_proc4_2" type="box"/>
        </body>
        <body pos="0.000000 0.000000 103.074997" quat="0.000000 0.000000 0.000000 1.000000" name="terrainGen_terrain_proc4_3">
            <geom conaffinity="1" contype="0" mass="1.000000" pos="0.000000 0.000000 0.000000" quat="0.000000 0.000000 0.000000 1.000000" size="0.250000 1.000000 0.012500" name="terrainGen_terrain_proc4_3" type="box"/>
        </body>
        <body pos="0.000000 0.000000 104.099998" quat="0.000000 0.000000 0.000000 1.000000" name="terrainGen_terrain_proc4_4">
            <geom conaffinity="1" contype="0" mass="1.000000" pos="0.000000 0.000000 0.000000" quat="0.000000 0.000000 0.000000 1.000000" size="0.250000 1.000000 0.012500" name="terrainGen_terrain_proc4_4" type="box"/>
        </body>
        <body pos="0.000000 0.000000 105.125000" quat="0.000000 0.000000 0.000000 1.000000" name="terrainGen_terrain_proc4_5">
            <geom conaffinity="1" contype="0" mass="1.000000" pos="0.000000 0.000000 0.000000" quat="0.000000 0.000000 0.000000 1.000000" size="0.250000 1.000000 0.012500" name="terrainGen_terrain_proc4_5" type="box"/>
        </body>
        <body pos="0.000000 0.000000 106.150002" quat="0.000000 0.000000 0.000000 1.000000" name="terrainGen_terrain_proc4_6">
            <geom conaffinity="1" contype="0" mass="1.000000" pos="0.000000 0.000000 0.000000" quat="0.000000 0.000000 0.000000 1.000000" size="0.250000 1.000000 0.012500" name="terrainGen_terrain_proc4_6" type="box"/>
        </body>
        <body pos="0.000000 0.000000 107.175003" quat="0.000000 0.000000 0.000000 1.000000" name="terrainGen_terrain_proc4_7">
            <geom conaffinity="1" contype="0" mass="1.000000" pos="0.000000 0.000000 0.000000" quat="0.000000 0.000000 0.000000 1.000000" size="0.250000 1.000000 0.012500" name="terrainGen_terrain_proc4_7" type="box"/>
        </body>
        <body pos="0.000000 0.000000 108.199997" quat="0.000000 0.000000 0.000000 1.000000" name="terrainGen_terrain_proc4_8">
            <geom conaffinity="1" contype="0" mass="1.000000" pos="0.000000 0.000000 0.000000" quat="0.000000 0.000000 0.000000 1.000000" size="0.250000 1.000000 0.012500" name="terrainGen_terrain_proc4_8" type="box"/>
        </body>
        <body pos="0.000000 0.000000 109.224998" quat="0.000000 0.000000 0.000000 1.000000" name="terrainGen_terrain_proc4_9">
            <geom conaffinity="1" contype="0" mass="1.000000" pos="0.000000 0.000000 0.000000" quat="0.000000 0.000000 0.000000 1.000000" size="0.250000 1.000000 0.012500" name="terrainGen_terrain_proc4_9" type="box"/>
        </body>
        <body pos="0.000000 0.000000 110.250000" quat="0.000000 0.000000 0.000000 1.000000" name="terrainGen_terrain_proc4_10">
            <geom conaffinity="1" contype="0" mass="1.000000" pos="0.000000 0.000000 0.000000" quat="0.000000 0.000000 0.000000 1.000000" size="0.250000 1.000000 0.012500" name="terrainGen_terrain_proc4_10" type="box"/>
        </body>
        <body pos="0.000000 0.000000 111.275002" quat="0.000000 0.000000 0.000000 1.000000" name="terrainGen_terrain_proc4_11">
            <geom conaffinity="1" contype="0" mass="1.000000" pos="0.000000 0.000000 0.000000" quat="0.000000 0.000000 0.000000 1.000000" size="0.250000 1.000000 0.012500" name="terrainGen_terrain_proc4_11" type="box"/>
        </body>
        <body pos="0.000000 0.000000 112.300003" quat="0.000000 0.000000 0.000000 1.000000" name="terrainGen_terrain_proc4_12">
            <geom conaffinity="1" contype="0" mass="1.000000" pos="0.000000 0.000000 0.000000" quat="0.000000 0.000000 0.000000 1.000000" size="0.250000 1.000000 0.012500" name="terrainGen_terrain_proc4_12" type="box"/>
        </body>
        <body pos="0.000000 0.000000 113.324997" quat="0.000000 0.000000 0.000000 1.000000" name="terrainGen_terrain_proc4_13">
            <geom conaffinity="1" contype="0" mass="1.000000" pos="0.000000 0.000000 0.000000" quat="0.000000 0.000000 0.000000 1.000000" size="0.250000 1.000000 0.012500" name="terrainGen_terrain_proc4_13" type="box"/>
        </body>
        <body pos="0.000000 0.000000 114.349998" quat="0.000000 0.000000 0.000000 1.000000" name="terrainGen_terrain_proc4_14">
            <geom conaffinity="1" contype="0" mass="1.000000" pos="0.000000 0.000000 0.000000" quat="0.000000 0.000000 0.000000 1.000000" size="0.250000 1.000000 0.012500" name="terrainGen_terrain_proc4_14" type="box"/>
        </body>
        <body pos="0.000000 0.000000 115.375000" quat="0.000000 0.000000 0.000000 1.000000" name="terrainGen_terrain_proc4_15">
            <geom conaffinity="1" contype="0" mass="1.000000" pos="0.000000 0.000000 0.000000" quat="0.000000 0.000000 0.000000 1.000000" size="0.250000 1.000000 0.012500" name="terrainGen_terrain_proc4_15" type="box"/>
        </body>
        <body pos="0.000000 0.000000 116.400002" quat="0.000000 0.000000 0.000000 1.000000" name="terrainGen_terrain_proc4_16">
            <geom conaffinity="1" contype="0" mass="1.000000" pos="0.000000 0.000000 0.000000" quat="0.000000 0.000000 0.000000 1.000000" size="0.250000 1.000000 0.012500" name="terrainGen_terrain_proc4_16" type="box"/>
        </body>
        <body pos="0.000000 0.000000 117.425003" quat="0.000000 0.000000 0.000000 1.000000" name="terrainGen_terrain_proc4_17">
            <geom conaffinity="1" contype="0" mass="1.000000" pos="0.000000 0.000000 0.000000" quat="0.000000 0.000000 0.000000 1.000000" size="0.250000 1.000000 0.012500" name="terrainGen_terrain_proc4_17" type="box"/>
        </body>
        <body pos="0.000000 0.000000 118.449997" quat="0.000000 0.000000 0.000000 1.000000" name="terrainGen_terrain_proc4_18">
            <geom conaffinity="1" contype="0" mass="1.000000" pos="0.000000 0.000000 0.000000" quat="0.000000 0.000000 0.000000 1.000000" size="0.250000 1.000000 0.012500" name="terrainGen_terrain_proc4_18" type="box"/>
        </body>
        <body pos="0.000000 0.000000 119.474998" quat="0.000000 0.000000 0.000000 1.000000" name="terrainGen_terrain_proc4_19">
            <geom conaffinity="1" contype="0" mass="1.000000" pos="0.000000 0.000000 0.000000" quat="0.000000 0.000000 0.000000 1.000000" size="0.250000 1.000000 0.012500" name="terrainGen_terrain_proc4_19" type="box"/>
        </body>
        <body pos="0.000000 0.000000 120.500000" quat="0.000000 0.000000 0.000000 1.000000" name="terrainGen_terrain_proc4_20">
            <geom conaffinity="1" contype="0" mass="1.000000" pos="0.000000 0.000000 0.000000" quat="0.000000 0.000000 0.000000 1.000000" size="0.250000 1.000000 0.012500" name="terrainGen_terrain_proc4_20" type="box"/>
        </body>
        <body pos="0.000000 0.000000 121.525002" quat="0.000000 0.000000 0.000000 1.000000" name="terrainGen_terrain_proc4_21">
            <geom conaffinity="1" contype="0" mass="1.000000" pos="0.000000 0.000000 0.000000" quat="0.000000 0.000000 0.000000 1.000000" size="0.250000 1.000000 0.012500" name="terrainGen_terrain_proc4_21" type="box"/>
        </body>
        <body pos="0.000000 0.000000 122.550003" quat="0.000000 0.000000 0.000000 1.000000" name="terrainGen_terrain_proc4_22">
            <geom conaffinity="1" contype="0" mass="1.000000" pos="0.000000 0.000000 0.000000" quat="0.000000 0.000000 0.000000 1.000000" size="0.250000 1.000000 0.012500" name="terrainGen_terrain_proc4_22" type="box"/>
        </body>
        <body pos="0.000000 0.000000 123.574997" quat="0.000000 0.000000 0.000000 1.000000" name="terrainGen_terrain_proc4_23">
            <geom conaffinity="1" contype="0" mass="1.000000" pos="0.000000 0.000000 0.000000" quat="0.000000 0.000000 0.000000 1.000000" size="0.250000 1.000000 0.012500" name="terrainGen_terrain_proc4_23" type="box"/>
        </body>
        <body pos="0.000000 0.000000 124.599998" quat="0.000000 0.000000 0.000000 1.000000" name="terrainGen_terrain_proc4_24">
            <geom conaffinity="1" contype="0" mass="1.000000" pos="0.000000 0.000000 0.000000" quat="0.000000 0.000000 0.000000 1.000000" size="0.250000 1.000000 0.012500" name="terrainGen_terrain_proc4_24" type="box"/>
        </body>
        <body pos="0.000000 0.000000 125.625000" quat="0.000000 0.000000 0.000000 1.000000" name="terrainGen_terrain_proc4_25">
            <geom conaffinity="1" contype="0" mass="1.000000" pos="0.000000 0.000000 0.000000" quat="0.000000 0.000000 0.000000 1.000000" size="0.250000 1.000000 0.012500" name="terrainGen_terrain_proc4_25" type="box"/>
        </body>
        <body pos="0.000000 0.000000 126.650002" quat="0.000000 0.000000 0.000000 1.000000" name="terrainGen_terrain_proc4_26">
            <geom conaffinity="1" contype="0" mass="1.000000" pos="0.000000 0.000000 0.000000" quat="0.000000 0.000000 0.000000 1.000000" size="0.250000 1.000000 0.012500" name="terrainGen_terrain_proc4_26" type="box"/>
        </body>
        <body pos="0.000000 0.000000 127.675003" quat="0.000000 0.000000 0.000000 1.000000" name="terrainGen_terrain_proc4_27">
            <geom conaffinity="1" contype="0" mass="1.000000" pos="0.000000 0.000000 0.000000" quat="0.000000 0.000000 0.000000 1.000000" size="0.250000 1.000000 0.012500" name="terrainGen_terrain_proc4_27" type="box"/>
        </body>
        <body pos="0.000000 0.000000 128.699997" quat="0.000000 0.000000 0.000000 1.000000" name="terrainGen_terrain_proc4_28">
            <geom conaffinity="1" contype="0" mass="1.000000" pos="0.000000 0.000000 0.000000" quat="0.000000 0.000000 0.000000 1.000000" size="0.250000 1.000000 0.012500" name="terrainGen_terrain_proc4_28" type="box"/>
        </body>
        <body pos="0.000000 0.000000 129.725006" quat="0.000000 0.000000 0.000000 1.000000" name="terrainGen_terrain_proc4_29">
            <geom conaffinity="1" contype="0" mass="1.000000" pos="0.000000 0.000000 0.000000" quat="0.000000 0.000000 0.000000 1.000000" size="0.250000 1.000000 0.012500" name="terrainGen_terrain_proc4_29" type="box"/>
        </body>
    </worldbody>
    <worldbody>
        <body pos="1.000000 0.000000 4.500000" name="mjcbody_walker_0_tmjcroot">
            <light pos="0.000000 0.000000 2.000000" mode="trackcom" name="mjclight_walker_0_light"/>
            <camera euler="60.000000 0.000000 0.000000" pos="0.000000 -2.000000 0.700000" mode="trackcom" name="mjccam_walker_0_side"/>
            <camera pos="-2.000000 0.000000 0.500000" xyaxes="0.000000 -1.000000 0.000000 1.000000 0.000000 3.000000" mode="trackcom" name="mjccam_walker_0_back"/>
            <joint armature="0.000000" damping="0.000000" axis="0.000000 0.000000 1.000000" solimplimit="0.000000 0.990000 0.010000" limited="false" name="mjcjoint_walker_0_tmjcrootz" type="slide"/>
            <joint armature="0.000000" damping="0.000000" axis="1.000000 0.000000 0.000000" solimplimit="0.000000 0.990000 0.010000" limited="false" name="mjcjoint_walker_0_tmjcrootx" type="slide"/>
            <joint armature="0.000000" damping="0.000000" axis="0.000000 1.000000 0.000000" solimplimit="0.000000 0.990000 0.010000" limited="false" name="mjcjoint_walker_0_tmjcrooty" type="hinge"/>
            <geom conaffinity="0" contype="1" friction="0.700000 0.100000 0.100000" size="0.070000 0.300000" material="self" name="mjcgeom_walker_0_tmjcroot" type="capsule"/>
            <body pos="0.000000 -0.050000 -0.300000" name="mjcbody_walker_0_right_thigh">
                <joint armature="0.010000" damping="0.100000" axis="0.000000 -1.000000 0.000000" range="-20.000000 100.000000" solimplimit="0.000000 0.990000 0.010000" limited="true" name="mjcjoint_walker_0_right_hip"/>
                <geom conaffinity="0" contype="1" friction="0.700000 0.100000 0.100000" pos="0.000000 0.000000 -0.225000" size="0.050000 0.225000" material="self" name="mjcgeom_walker_0_right_thigh" type="capsule"/>
                <body pos="0.000000 0.000000 -0.700000" name="mjcbody_walker_0_right_leg">
                    <joint armature="0.010000" damping="0.100000" axis="0.000000 -1.000000 0.000000" pos="0.000000 0.000000 0.250000" range="-150.000000 0.000000" solimplimit="0.000000 0.990000 0.010000" limited="true" name="mjcjoint_walker_0_right_knee"/>
                    <geom conaffinity="0" contype="1" friction="0.700000 0.100000 0.100000" size="0.040000 0.250000" material="self" name="mjcgeom_walker_0_right_leg" type="capsule"/>
                    <body pos="0.060000 0.000000 -0.250000" name="mjcbody_walker_0_right_foot">
                        <joint armature="0.010000" damping="0.100000" axis="0.000000 -1.000000 0.000000" pos="-0.060000 0.000000 0.000000" range="-45.000000 45.000000" solimplimit="0.000000 0.990000 0.010000" limited="true" name="mjcjoint_walker_0_right_ankle"/>
                        <geom conaffinity="0" contype="1" friction="0.700000 0.100000 0.100000" size="0.050000 0.100000" zaxis="1.000000 0.000000 0.000000" material="self" name="mjcgeom_walker_0_right_foot" type="capsule"/>
                    </body>
                </body>
            </body>
            <body pos="0.000000 0.050000 -0.300000" name="mjcbody_walker_0_left_thigh">
                <joint armature="0.010000" damping="0.100000" axis="0.000000 -1.000000 0.000000" range="-20.000000 100.000000" solimplimit="0.000000 0.990000 0.010000" limited="true" name="mjcjoint_walker_0_left_hip"/>
                <geom conaffinity="0" contype="1" friction="0.700000 0.100000 0.100000" pos="0.000000 0.000000 -0.225000" size="0.050000 0.225000" material="self" name="mjcgeom_walker_0_left_thigh" type="capsule"/>
                <body pos="0.000000 0.000000 -0.700000" name="mjcbody_walker_0_left_leg">
                    <joint armature="0.010000" damping="0.100000" axis="0.000000 -1.000000 0.000000" pos="0.000000 0.000000 0.250000" range="-150.000000 0.000000" solimplimit="0.000000 0.990000 0.010000" limited="true" name="mjcjoint_walker_0_left_knee"/>
                    <geom conaffinity="0" contype="1" friction="0.700000 0.100000 0.100000" size="0.040000 0.250000" material="self" name="mjcgeom_walker_0_left_leg" type="capsule"/>
                    <body pos="0.060000 0.000000 -0.250000" name="mjcbody_walker_0_left_foot">
                        <joint armature="0.010000" damping="0.100000" axis="0.000000 -1.000000 0.000000" pos="-0.060000 0.000000 0.000000" range="-45.000000 45.000000" solimplimit="0.000000 0.990000 0.010000" limited="true" name="mjcjoint_walker_0_left_ankle"/>
                        <geom conaffinity="0" contype="1" friction="0.700000 0.100000 0.100000" size="0.050000 0.100000" zaxis="1.000000 0.000000 0.000000" material="self" name="mjcgeom_walker_0_left_foot" type="capsule"/>
                    </body>
                </body>
            </body>
        </body>
    </worldbody>
    <actuator>
        <motor ctrlrange="-1.000000 1.000000" gear="100.000000" ctrllimited="true" joint="mjcjoint_walker_0_right_hip" name="mjcact_walker_0_right_hip"/>
        <motor ctrlrange="-1.000000 1.000000" gear="50.000000" ctrllimited="true" joint="mjcjoint_walker_0_right_knee" name="mjcact_walker_0_right_knee"/>
        <motor ctrlrange="-1.000000 1.000000" gear="20.000000" ctrllimited="true" joint="mjcjoint_walker_0_right_ankle" name="mjcact_walker_0_right_ankle"/>
        <motor ctrlrange="-1.000000 1.000000" gear="100.000000" ctrllimited="true" joint="mjcjoint_walker_0_left_hip" name="mjcact_walker_0_left_hip"/>
        <motor ctrlrange="-1.000000 1.000000" gear="50.000000" ctrllimited="true" joint="mjcjoint_walker_0_left_knee" name="mjcact_walker_0_left_knee"/>
        <motor ctrlrange="-1.000000 1.000000" gear="20.000000" ctrllimited="true" joint="mjcjoint_walker_0_left_ankle" name="mjcact_walker_0_left_ankle"/>
    </actuator>
    <worldbody>
        <body pos="1.000000 2.500000 4.500000" name="mjcbody_walker_1_tmjcroot">
            <light pos="0.000000 0.000000 2.000000" mode="trackcom" name="mjclight_walker_1_light"/>
            <camera euler="60.000000 0.000000 0.000000" pos="0.000000 -2.000000 0.700000" mode="trackcom" name="mjccam_walker_1_side"/>
            <camera pos="-2.000000 0.000000 0.500000" xyaxes="0.000000 -1.000000 0.000000 1.000000 0.000000 3.000000" mode="trackcom" name="mjccam_walker_1_back"/>
            <joint armature="0.000000" damping="0.000000" axis="0.000000 0.000000 1.000000" solimplimit="0.000000 0.990000 0.010000" limited="false" name="mjcjoint_walker_1_tmjcrootz" type="slide"/>
            <joint armature="0.000000" damping="0.000000" axis="1.000000 0.000000 0.000000" solimplimit="0.000000 0.990000 0.010000" limited="false" name="mjcjoint_walker_1_tmjcrootx" type="slide"/>
            <joint armature="0.000000" damping="0.000000" axis="0.000000 1.000000 0.000000" solimplimit="0.000000 0.990000 0.010000" limited="false" name="mjcjoint_walker_1_tmjcrooty" type="hinge"/>
            <geom conaffinity="0" contype="1" friction="0.700000 0.100000 0.100000" size="0.070000 0.300000" material="self" name="mjcgeom_walker_1_tmjcroot" type="capsule"/>
            <body pos="0.000000 -0.050000 -0.300000" name="mjcbody_walker_1_right_thigh">
                <joint armature="0.010000" damping="0.100000" axis="0.000000 -1.000000 0.000000" range="-20.000000 100.000000" solimplimit="0.000000 0.990000 0.010000" limited="true" name="mjcjoint_walker_1_right_hip"/>
                <geom conaffinity="0" contype="1" friction="0.700000 0.100000 0.100000" pos="0.000000 0.000000 -0.225000" size="0.050000 0.225000" material="self" name="mjcgeom_walker_1_right_thigh" type="capsule"/>
                <body pos="0.000000 0.000000 -0.700000" name="mjcbody_walker_1_right_leg">
                    <joint armature="0.010000" damping="0.100000" axis="0.000000 -1.000000 0.000000" pos="0.000000 0.000000 0.250000" range="-150.000000 0.000000" solimplimit="0.000000 0.990000 0.010000" limited="true" name="mjcjoint_walker_1_right_knee"/>
                    <geom conaffinity="0" contype="1" friction="0.700000 0.100000 0.100000" size="0.040000 0.250000" material="self" name="mjcgeom_walker_1_right_leg" type="capsule"/>
                    <body pos="0.060000 0.000000 -0.250000" name="mjcbody_walker_1_right_foot">
                        <joint armature="0.010000" damping="0.100000" axis="0.000000 -1.000000 0.000000" pos="-0.060000 0.000000 0.000000" range="-45.000000 45.000000" solimplimit="0.000000 0.990000 0.010000" limited="true" name="mjcjoint_walker_1_right_ankle"/>
                        <geom conaffinity="0" contype="1" friction="0.700000 0.100000 0.100000" size="0.050000 0.100000" zaxis="1.000000 0.000000 0.000000" material="self" name="mjcgeom_walker_1_right_foot" type="capsule"/>
                    </body>
                </body>
            </body>
            <body pos="0.000000 0.050000 -0.300000" name="mjcbody_walker_1_left_thigh">
                <joint armature="0.010000" damping="0.100000" axis="0.000000 -1.000000 0.000000" range="-20.000000 100.000000" solimplimit="0.000000 0.990000 0.010000" limited="true" name="mjcjoint_walker_1_left_hip"/>
                <geom conaffinity="0" contype="1" friction="0.700000 0.100000 0.100000" pos="0.000000 0.000000 -0.225000" size="0.050000 0.225000" material="self" name="mjcgeom_walker_1_left_thigh" type="capsule"/>
                <body pos="0.000000 0.000000 -0.700000" name="mjcbody_walker_1_left_leg">
                    <joint armature="0.010000" damping="0.100000" axis="0.000000 -1.000000 0.000000" pos="0.000000 0.000000 0.250000" range="-150.000000 0.000000" solimplimit="0.000000 0.990000 0.010000" limited="true" name="mjcjoint_walker_1_left_knee"/>
                    <geom conaffinity="0" contype="1" friction="0.700000 0.100000 0.100000" size="0.040000 0.250000" material="self" name="mjcgeom_walker_1_left_leg" type="capsule"/>
                    <body pos="0.060000 0.000000 -0.250000" name="mjcbody_walker_1_left_foot">
                        <joint armature="0.010000" damping="0.100000" axis="0.000000 -1.000000 0.000000" pos="-0.060000 0.000000 0.000000" range="-45.000000 45.000000" solimplimit="0.000000 0.990000 0.010000" limited="true" name="mjcjoint_walker_1_left_ankle"/>
                        <geom conaffinity="0" contype="1" friction="0.700000 0.100000 0.100000" size="0.050000 0.100000" zaxis="1.000000 0.000000 0.000000" material="self" name="mjcgeom_walker_1_left_foot" type="capsule"/>
                    </body>
                </body>
            </body>
        </body>
    </worldbody>
    <actuator>
        <motor ctrlrange="-1.000000 1.000000" gear="100.000000" ctrllimited="true" joint="mjcjoint_walker_1_right_hip" name="mjcact_walker_1_right_hip"/>
        <motor ctrlrange="-1.000000 1.000000" gear="50.000000" ctrllimited="true" joint="mjcjoint_walker_1_right_knee" name="mjcact_walker_1_right_knee"/>
        <motor ctrlrange="-1.000000 1.000000" gear="20.000000" ctrllimited="true" joint="mjcjoint_walker_1_right_ankle" name="mjcact_walker_1_right_ankle"/>
        <motor ctrlrange="-1.000000 1.000000" gear="100.000000" ctrllimited="true" joint="mjcjoint_walker_1_left_hip" name="mjcact_walker_1_left_hip"/>
        <motor ctrlrange="-1.000000 1.000000" gear="50.000000" ctrllimited="true" joint="mjcjoint_walker_1_left_knee" name="mjcact_walker_1_left_knee"/>
        <motor ctrlrange="-1.000000 1.000000" gear="20.000000" ctrllimited="true" joint="mjcjoint_walker_1_left_ankle" name="mjcact_walker_1_left_ankle"/>
    </actuator>
    <worldbody>
        <body pos="1.000000 5.000000 4.500000" name="mjcbody_walker_2_tmjcroot">
            <light pos="0.000000 0.000000 2.000000" mode="trackcom" name="mjclight_walker_2_light"/>
            <camera euler="60.000000 0.000000 0.000000" pos="0.000000 -2.000000 0.700000" mode="trackcom" name="mjccam_walker_2_side"/>
            <camera pos="-2.000000 0.000000 0.500000" xyaxes="0.000000 -1.000000 0.000000 1.000000 0.000000 3.000000" mode="trackcom" name="mjccam_walker_2_back"/>
            <joint armature="0.000000" damping="0.000000" axis="0.000000 0.000000 1.000000" solimplimit="0.000000 0.990000 0.010000" limited="false" name="mjcjoint_walker_2_tmjcrootz" type="slide"/>
            <joint armature="0.000000" damping="0.000000" axis="1.000000 0.000000 0.000000" solimplimit="0.000000 0.990000 0.010000" limited="false" name="mjcjoint_walker_2_tmjcrootx" type="slide"/>
            <joint armature="0.000000" damping="0.000000" axis="0.000000 1.000000 0.000000" solimplimit="0.000000 0.990000 0.010000" limited="false" name="mjcjoint_walker_2_tmjcrooty" type="hinge"/>
            <geom conaffinity="0" contype="1" friction="0.700000 0.100000 0.100000" size="0.070000 0.300000" material="self" name="mjcgeom_walker_2_tmjcroot" type="capsule"/>
            <body pos="0.000000 -0.050000 -0.300000" name="mjcbody_walker_2_right_thigh">
                <joint armature="0.010000" damping="0.100000" axis="0.000000 -1.000000 0.000000" range="-20.000000 100.000000" solimplimit="0.000000 0.990000 0.010000" limited="true" name="mjcjoint_walker_2_right_hip"/>
                <geom conaffinity="0" contype="1" friction="0.700000 0.100000 0.100000" pos="0.000000 0.000000 -0.225000" size="0.050000 0.225000" material="self" name="mjcgeom_walker_2_right_thigh" type="capsule"/>
                <body pos="0.000000 0.000000 -0.700000" name="mjcbody_walker_2_right_leg">
                    <joint armature="0.010000" damping="0.100000" axis="0.000000 -1.000000 0.000000" pos="0.000000 0.000000 0.250000" range="-150.000000 0.000000" solimplimit="0.000000 0.990000 0.010000" limited="true" name="mjcjoint_walker_2_right_knee"/>
                    <geom conaffinity="0" contype="1" friction="0.700000 0.100000 0.100000" size="0.040000 0.250000" material="self" name="mjcgeom_walker_2_right_leg" type="capsule"/>
                    <body pos="0.060000 0.000000 -0.250000" name="mjcbody_walker_2_right_foot">
                        <joint armature="0.010000" damping="0.100000" axis="0.000000 -1.000000 0.000000" pos="-0.060000 0.000000 0.000000" range="-45.000000 45.000000" solimplimit="0.000000 0.990000 0.010000" limited="true" name="mjcjoint_walker_2_right_ankle"/>
                        <geom conaffinity="0" contype="1" friction="0.700000 0.100000 0.100000" size="0.050000 0.100000" zaxis="1.000000 0.000000 0.000000" material="self" name="mjcgeom_walker_2_right_foot" type="capsule"/>
                    </body>
                </body>
            </body>
            <body pos="0.000000 0.050000 -0.300000" name="mjcbody_walker_2_left_thigh">
                <joint armature="0.010000" damping="0.100000" axis="0.000000 -1.000000 0.000000" range="-20.000000 100.000000" solimplimit="0.000000 0.990000 0.010000" limited="true" name="mjcjoint_walker_2_left_hip"/>
                <geom conaffinity="0" contype="1" friction="0.700000 0.100000 0.100000" pos="0.000000 0.000000 -0.225000" size="0.050000 0.225000" material="self" name="mjcgeom_walker_2_left_thigh" type="capsule"/>
                <body pos="0.000000 0.000000 -0.700000" name="mjcbody_walker_2_left_leg">
                    <joint armature="0.010000" damping="0.100000" axis="0.000000 -1.000000 0.000000" pos="0.000000 0.000000 0.250000" range="-150.000000 0.000000" solimplimit="0.000000 0.990000 0.010000" limited="true" name="mjcjoint_walker_2_left_knee"/>
                    <geom conaffinity="0" contype="1" friction="0.700000 0.100000 0.100000" size="0.040000 0.250000" material="self" name="mjcgeom_walker_2_left_leg" type="capsule"/>
                    <body pos="0.060000 0.000000 -0.250000" name="mjcbody_walker_2_left_foot">
                        <joint armature="0.010000" damping="0.100000" axis="0.000000 -1.000000 0.000000" pos="-0.060000 0.000000 0.000000" range="-45.000000 45.000000" solimplimit="0.000000 0.990000 0.010000" limited="true" name="mjcjoint_walker_2_left_ankle"/>
                        <geom conaffinity="0" contype="1" friction="0.700000 0.100000 0.100000" size="0.050000 0.100000" zaxis="1.000000 0.000000 0.000000" material="self" name="mjcgeom_walker_2_left_foot" type="capsule"/>
                    </body>
                </body>
            </body>
        </body>
    </worldbody>
    <actuator>
        <motor ctrlrange="-1.000000 1.000000" gear="100.000000" ctrllimited="true" joint="mjcjoint_walker_2_right_hip" name="mjcact_walker_2_right_hip"/>
        <motor ctrlrange="-1.000000 1.000000" gear="50.000000" ctrllimited="true" joint="mjcjoint_walker_2_right_knee" name="mjcact_walker_2_right_knee"/>
        <motor ctrlrange="-1.000000 1.000000" gear="20.000000" ctrllimited="true" joint="mjcjoint_walker_2_right_ankle" name="mjcact_walker_2_right_ankle"/>
        <motor ctrlrange="-1.000000 1.000000" gear="100.000000" ctrllimited="true" joint="mjcjoint_walker_2_left_hip" name="mjcact_walker_2_left_hip"/>
        <motor ctrlrange="-1.000000 1.000000" gear="50.000000" ctrllimited="true" joint="mjcjoint_walker_2_left_knee" name="mjcact_walker_2_left_knee"/>
        <motor ctrlrange="-1.000000 1.000000" gear="20.000000" ctrllimited="true" joint="mjcjoint_walker_2_left_ankle" name="mjcact_walker_2_left_ankle"/>
    </actuator>
    <worldbody>
        <body pos="1.000000 7.500000 4.500000" name="mjcbody_walker_3_tmjcroot">
            <light pos="0.000000 0.000000 2.000000" mode="trackcom" name="mjclight_walker_3_light"/>
            <camera euler="60.000000 0.000000 0.000000" pos="0.000000 -2.000000 0.700000" mode="trackcom" name="mjccam_walker_3_side"/>
            <camera pos="-2.000000 0.000000 0.500000" xyaxes="0.000000 -1.000000 0.000000 1.000000 0.000000 3.000000" mode="trackcom" name="mjccam_walker_3_back"/>
            <joint armature="0.000000" damping="0.000000" axis="0.000000 0.000000 1.000000" solimplimit="0.000000 0.990000 0.010000" limited="false" name="mjcjoint_walker_3_tmjcrootz" type="slide"/>
            <joint armature="0.000000" damping="0.000000" axis="1.000000 0.000000 0.000000" solimplimit="0.000000 0.990000 0.010000" limited="false" name="mjcjoint_walker_3_tmjcrootx" type="slide"/>
            <joint armature="0.000000" damping="0.000000" axis="0.000000 1.000000 0.000000" solimplimit="0.000000 0.990000 0.010000" limited="false" name="mjcjoint_walker_3_tmjcrooty" type="hinge"/>
            <geom conaffinity="0" contype="1" friction="0.700000 0.100000 0.100000" size="0.070000 0.300000" material="self" name="mjcgeom_walker_3_tmjcroot" type="capsule"/>
            <body pos="0.000000 -0.050000 -0.300000" name="mjcbody_walker_3_right_thigh">
                <joint armature="0.010000" damping="0.100000" axis="0.000000 -1.000000 0.000000" range="-20.000000 100.000000" solimplimit="0.000000 0.990000 0.010000" limited="true" name="mjcjoint_walker_3_right_hip"/>
                <geom conaffinity="0" contype="1" friction="0.700000 0.100000 0.100000" pos="0.000000 0.000000 -0.225000" size="0.050000 0.225000" material="self" name="mjcgeom_walker_3_right_thigh" type="capsule"/>
                <body pos="0.000000 0.000000 -0.700000" name="mjcbody_walker_3_right_leg">
                    <joint armature="0.010000" damping="0.100000" axis="0.000000 -1.000000 0.000000" pos="0.000000 0.000000 0.250000" range="-150.000000 0.000000" solimplimit="0.000000 0.990000 0.010000" limited="true" name="mjcjoint_walker_3_right_knee"/>
                    <geom conaffinity="0" contype="1" friction="0.700000 0.100000 0.100000" size="0.040000 0.250000" material="self" name="mjcgeom_walker_3_right_leg" type="capsule"/>
                    <body pos="0.060000 0.000000 -0.250000" name="mjcbody_walker_3_right_foot">
                        <joint armature="0.010000" damping="0.100000" axis="0.000000 -1.000000 0.000000" pos="-0.060000 0.000000 0.000000" range="-45.000000 45.000000" solimplimit="0.000000 0.990000 0.010000" limited="true" name="mjcjoint_walker_3_right_ankle"/>
                        <geom conaffinity="0" contype="1" friction="0.700000 0.100000 0.100000" size="0.050000 0.100000" zaxis="1.000000 0.000000 0.000000" material="self" name="mjcgeom_walker_3_right_foot" type="capsule"/>
                    </body>
                </body>
            </body>
            <body pos="0.000000 0.050000 -0.300000" name="mjcbody_walker_3_left_thigh">
                <joint armature="0.010000" damping="0.100000" axis="0.000000 -1.000000 0.000000" range="-20.000000 100.000000" solimplimit="0.000000 0.990000 0.010000" limited="true" name="mjcjoint_walker_3_left_hip"/>
                <geom conaffinity="0" contype="1" friction="0.700000 0.100000 0.100000" pos="0.000000 0.000000 -0.225000" size="0.050000 0.225000" material="self" name="mjcgeom_walker_3_left_thigh" type="capsule"/>
                <body pos="0.000000 0.000000 -0.700000" name="mjcbody_walker_3_left_leg">
                    <joint armature="0.010000" damping="0.100000" axis="0.000000 -1.000000 0.000000" pos="0.000000 0.000000 0.250000" range="-150.000000 0.000000" solimplimit="0.000000 0.990000 0.010000" limited="true" name="mjcjoint_walker_3_left_knee"/>
                    <geom conaffinity="0" contype="1" friction="0.700000 0.100000 0.100000" size="0.040000 0.250000" material="self" name="mjcgeom_walker_3_left_leg" type="capsule"/>
                    <body pos="0.060000 0.000000 -0.250000" name="mjcbody_walker_3_left_foot">
                        <joint armature="0.010000" damping="0.100000" axis="0.000000 -1.000000 0.000000" pos="-0.060000 0.000000 0.000000" range="-45.000000 45.000000" solimplimit="0.000000 0.990000 0.010000" limited="true" name="mjcjoint_walker_3_left_ankle"/>
                        <geom conaffinity="0" contype="1" friction="0.700000 0.100000 0.100000" size="0.050000 0.100000" zaxis="1.000000 0.000000 0.000000" material="self" name="mjcgeom_walker_3_left_foot" type="capsule"/>
                    </body>
                </body>
            </body>
        </body>
    </worldbody>
    <actuator>
        <motor ctrlrange="-1.000000 1.000000" gear="100.000000" ctrllimited="true" joint="mjcjoint_walker_3_right_hip" name="mjcact_walker_3_right_hip"/>
        <motor ctrlrange="-1.000000 1.000000" gear="50.000000" ctrllimited="true" joint="mjcjoint_walker_3_right_knee" name="mjcact_walker_3_right_knee"/>
        <motor ctrlrange="-1.000000 1.000000" gear="20.000000" ctrllimited="true" joint="mjcjoint_walker_3_right_ankle" name="mjcact_walker_3_right_ankle"/>
        <motor ctrlrange="-1.000000 1.000000" gear="100.000000" ctrllimited="true" joint="mjcjoint_walker_3_left_hip" name="mjcact_walker_3_left_hip"/>
        <motor ctrlrange="-1.000000 1.000000" gear="50.000000" ctrllimited="true" joint="mjcjoint_walker_3_left_knee" name="mjcact_walker_3_left_knee"/>
        <motor ctrlrange="-1.000000 1.000000" gear="20.000000" ctrllimited="true" joint="mjcjoint_walker_3_left_ankle" name="mjcact_walker_3_left_ankle"/>
    </actuator>
    <worldbody>
        <body pos="1.000000 10.000000 4.500000" name="mjcbody_walker_4_tmjcroot">
            <light pos="0.000000 0.000000 2.000000" mode="trackcom" name="mjclight_walker_4_light"/>
            <camera euler="60.000000 0.000000 0.000000" pos="0.000000 -2.000000 0.700000" mode="trackcom" name="mjccam_walker_4_side"/>
            <camera pos="-2.000000 0.000000 0.500000" xyaxes="0.000000 -1.000000 0.000000 1.000000 0.000000 3.000000" mode="trackcom" name="mjccam_walker_4_back"/>
            <joint armature="0.000000" damping="0.000000" axis="0.000000 0.000000 1.000000" solimplimit="0.000000 0.990000 0.010000" limited="false" name="mjcjoint_walker_4_tmjcrootz" type="slide"/>
            <joint armature="0.000000" damping="0.000000" axis="1.000000 0.000000 0.000000" solimplimit="0.000000 0.990000 0.010000" limited="false" name="mjcjoint_walker_4_tmjcrootx" type="slide"/>
            <joint armature="0.000000" damping="0.000000" axis="0.000000 1.000000 0.000000" solimplimit="0.000000 0.990000 0.010000" limited="false" name="mjcjoint_walker_4_tmjcrooty" type="hinge"/>
            <geom conaffinity="0" contype="1" friction="0.700000 0.100000 0.100000" size="0.070000 0.300000" material="self" name="mjcgeom_walker_4_tmjcroot" type="capsule"/>
            <body pos="0.000000 -0.050000 -0.300000" name="mjcbody_walker_4_right_thigh">
                <joint armature="0.010000" damping="0.100000" axis="0.000000 -1.000000 0.000000" range="-20.000000 100.000000" solimplimit="0.000000 0.990000 0.010000" limited="true" name="mjcjoint_walker_4_right_hip"/>
                <geom conaffinity="0" contype="1" friction="0.700000 0.100000 0.100000" pos="0.000000 0.000000 -0.225000" size="0.050000 0.225000" material="self" name="mjcgeom_walker_4_right_thigh" type="capsule"/>
                <body pos="0.000000 0.000000 -0.700000" name="mjcbody_walker_4_right_leg">
                    <joint armature="0.010000" damping="0.100000" axis="0.000000 -1.000000 0.000000" pos="0.000000 0.000000 0.250000" range="-150.000000 0.000000" solimplimit="0.000000 0.990000 0.010000" limited="true" name="mjcjoint_walker_4_right_knee"/>
                    <geom conaffinity="0" contype="1" friction="0.700000 0.100000 0.100000" size="0.040000 0.250000" material="self" name="mjcgeom_walker_4_right_leg" type="capsule"/>
                    <body pos="0.060000 0.000000 -0.250000" name="mjcbody_walker_4_right_foot">
                        <joint armature="0.010000" damping="0.100000" axis="0.000000 -1.000000 0.000000" pos="-0.060000 0.000000 0.000000" range="-45.000000 45.000000" solimplimit="0.000000 0.990000 0.010000" limited="true" name="mjcjoint_walker_4_right_ankle"/>
                        <geom conaffinity="0" contype="1" friction="0.700000 0.100000 0.100000" size="0.050000 0.100000" zaxis="1.000000 0.000000 0.000000" material="self" name="mjcgeom_walker_4_right_foot" type="capsule"/>
                    </body>
                </body>
            </body>
            <body pos="0.000000 0.050000 -0.300000" name="mjcbody_walker_4_left_thigh">
                <joint armature="0.010000" damping="0.100000" axis="0.000000 -1.000000 0.000000" range="-20.000000 100.000000" solimplimit="0.000000 0.990000 0.010000" limited="true" name="mjcjoint_walker_4_left_hip"/>
                <geom conaffinity="0" contype="1" friction="0.700000 0.100000 0.100000" pos="0.000000 0.000000 -0.225000" size="0.050000 0.225000" material="self" name="mjcgeom_walker_4_left_thigh" type="capsule"/>
                <body pos="0.000000 0.000000 -0.700000" name="mjcbody_walker_4_left_leg">
                    <joint armature="0.010000" damping="0.100000" axis="0.000000 -1.000000 0.000000" pos="0.000000 0.000000 0.250000" range="-150.000000 0.000000" solimplimit="0.000000 0.990000 0.010000" limited="true" name="mjcjoint_walker_4_left_knee"/>
                    <geom conaffinity="0" contype="1" friction="0.700000 0.100000 0.100000" size="0.040000 0.250000" material="self" name="mjcgeom_walker_4_left_leg" type="capsule"/>
                    <body pos="0.060000 0.000000 -0.250000" name="mjcbody_walker_4_left_foot">
                        <joint armature="0.010000" damping="0.100000" axis="0.000000 -1.000000 0.000000" pos="-0.060000 0.000000 0.000000" range="-45.000000 45.000000" solimplimit="0.000000 0.990000 0.010000" limited="true" name="mjcjoint_walker_4_left_ankle"/>
                        <geom conaffinity="0" contype="1" friction="0.700000 0.100000 0.100000" size="0.050000 0.100000" zaxis="1.000000 0.000000 0.000000" material="self" name="mjcgeom_walker_4_left_foot" type="capsule"/>
                    </body>
                </body>
            </body>
        </body>
    </worldbody>
    <actuator>
        <motor ctrlrange="-1.000000 1.000000" gear="100.000000" ctrllimited="true" joint="mjcjoint_walker_4_right_hip" name="mjcact_walker_4_right_hip"/>
        <motor ctrlrange="-1.000000 1.000000" gear="50.000000" ctrllimited="true" joint="mjcjoint_walker_4_right_knee" name="mjcact_walker_4_right_knee"/>
        <motor ctrlrange="-1.000000 1.000000" gear="20.000000" ctrllimited="true" joint="mjcjoint_walker_4_right_ankle" name="mjcact_walker_4_right_ankle"/>
        <motor ctrlrange="-1.000000 1.000000" gear="100.000000" ctrllimited="true" joint="mjcjoint_walker_4_left_hip" name="mjcact_walker_4_left_hip"/>
        <motor ctrlrange="-1.000000 1.000000" gear="50.000000" ctrllimited="true" joint="mjcjoint_walker_4_left_knee" name="mjcact_walker_4_left_knee"/>
        <motor ctrlrange="-1.000000 1.000000" gear="20.000000" ctrllimited="true" joint="mjcjoint_walker_4_left_ankle" name="mjcact_walker_4_left_ankle"/>
    </actuator>
</mujoco>
