<mujoco>
    <include file="materials.xml"/>
    <compiler angle="degree" coordinate="local" inertiafromgeom="true"/>
    <option iterations="50" timestep="0.005000" tolerance="0.000000" cone="pyramidal" jacobian="dense" solver="Newton"/>
    <size nconmax="4000" njmax="8000"/>
    <statistic extent="2.000000" center="0.000000 0.000000 1.000000"/>
    <asset>
        <texture height="512" width="512" rgb1="0.300000 0.500000 0.700000" rgb2="0.000000 0.000000 0.000000" builtin="gradient" type="skybox"/>
        <texture height="512" width="512" markrgb="0.800000 0.800000 0.800000" rgb1="0.200000 0.300000 0.400000" rgb2="0.100000 0.150000 0.200000" builtin="checker" mark="cross" name="texplane" type="2d"/>
        <texture height="1278" width="127" random="0.010000" markrgb="1.000000 1.000000 1.000000" rgb1="0.800000 0.600000 0.400000" rgb2="0.800000 0.600000 0.400000" builtin="flat" mark="cross" name="texgeom" type="cube"/>
        <material reflectance="0.300000" texrepeat="1.000000 1.000000" name="matplane" texture="texplane" texuniform="true"/>
        <material rgba="0.800000 0.600000 0.400000 1.000000" name="matgeom" texture="texgeom" texuniform="true"/>
    </asset>
    <visual>
        <map force="0.100000" zfar="30.000000"/>
        <rgba haze="0.150000 0.250000 0.350000 1.000000"/>
        <quality shadowsize="2048"/>
        <global offheight="800" offwidth="800"/>
    </visual>
    <worldbody>
        <geom conaffinity="1" contype="1" friction="0.700000 0.100000 0.100000" pos="0.000000 0.000000 -10.000000" size="1.000000 1.000000 0.200000" zaxis="0.000000 0.000000 1.000000" name="floor" type="plane"/>
    </worldbody>
    <worldbody>
        <body pos="0.000000 0.000000 0.000000" quat="1.000000 0.000000 0.000000 0.000000" name="tmjcroot">
            <joint name="root" type="free"/>
            <geom condim="1" pos="0.000000 0.000000 0.000000" quat="0.707107 -0.707107 0.000000 0.000000" rgba="0.700000 0.500000 0.300000 1.000000" size="0.070000 0.070000 0.000000" material="matgeom" name="tmjcroot" type="capsule"/>
            <geom condim="1" pos="0.000000 0.000000 0.190000" quat="1.000000 0.000000 0.000000 0.000000" rgba="0.700000 0.500000 0.300000 1.000000" size="0.090000 0.000000 0.000000" material="matgeom" name="head" type="sphere"/>
            <geom condim="1" pos="-0.010000 0.000000 -0.120000" quat="0.707107 -0.707107 0.000000 0.000000" rgba="0.700000 0.500000 0.300000 1.000000" size="0.060000 0.060000 0.000000" material="matgeom" name="uwaist" type="capsule"/>
            <body pos="-0.010000 0.000000 -0.260000" quat="0.999998 0.000000 -0.002000 0.000000" name="lwaist">
                <joint armature="0.020000" damping="5.000000" stiffness="20.000000" axis="0.000000 0.000000 1.000000" pos="0.000000 0.000000 0.065000" range="-45.000000 45.000000" limited="true" name="abdomen_z" type="hinge"/>
                <joint armature="0.020000" damping="5.000000" stiffness="10.000000" axis="0.000000 1.000000 0.000000" pos="0.000000 0.000000 0.065000" range="-75.000000 30.000000" limited="true" name="abdomen_y" type="hinge"/>
                <geom condim="1" pos="0.000000 0.000000 0.000000" quat="0.707107 -0.707107 0.000000 0.000000" rgba="0.700000 0.500000 0.300000 1.000000" size="0.060000 0.060000 0.000000" material="matgeom" name="lwaist" type="capsule"/>
                <body pos="0.000000 0.000000 -0.165000" quat="0.999998 0.000000 -0.002000 0.000000" name="pelvis">
                    <joint armature="0.020000" damping="5.000000" stiffness="10.000000" axis="1.000000 0.000000 0.000000" pos="0.000000 0.000000 0.100000" range="-35.000000 35.000000" limited="true" name="abdomen_x" type="hinge"/>
                    <geom condim="1" pos="-0.020000 0.000000 0.000000" quat="0.707107 -0.707107 0.000000 0.000000" rgba="0.700000 0.500000 0.300000 1.000000" size="0.090000 0.070000 0.000000" material="matgeom" name="butt" type="capsule"/>
                    <body pos="0.000000 -0.100000 -0.040000" quat="1.000000 0.000000 0.000000 0.000000" name="right_thigh">
                        <joint armature="0.010000" damping="5.000000" stiffness="10.000000" axis="1.000000 0.000000 0.000000" pos="0.000000 0.000000 0.000000" range="-25.000000 5.000000" limited="true" name="right_hip_x" type="hinge"/>
                        <joint armature="0.010000" damping="5.000000" stiffness="10.000000" axis="0.000000 0.000000 1.000000" pos="0.000000 0.000000 0.000000" range="-60.000000 35.000000" limited="true" name="right_hip_z" type="hinge"/>
                        <joint armature="0.010000" damping="5.000000" stiffness="20.000000" axis="0.000000 1.000000 0.000000" pos="0.000000 0.000000 0.000000" range="-120.000000 20.000000" limited="true" name="right_hip_y" type="hinge"/>
                        <geom condim="1" pos="0.000000 0.005000 -0.170000" quat="-0.014703 0.999892 0.000000 0.000000" rgba="0.700000 0.500000 0.300000 1.000000" size="0.060000 0.170074 0.000000" material="matgeom" name="right_thigh1" type="capsule"/>
                        <body pos="0.000000 0.010000 -0.403000" quat="1.000000 0.000000 0.000000 0.000000" name="right_shin">
                            <joint armature="0.006000" damping="1.000000" stiffness="1.000000" axis="0.000000 -1.000000 0.000000" pos="0.000000 0.000000 0.020000" range="-160.000000 -2.000000" limited="true" name="right_knee" type="hinge"/>
                            <geom condim="1" pos="0.000000 0.000000 -0.150000" quat="0.000000 0.000000 1.000000 0.000000" rgba="0.700000 0.500000 0.300000 1.000000" size="0.049000 0.150000 0.000000" material="matgeom" name="right_shin1" type="capsule"/>
                            <body pos="0.000000 0.000000 -0.390000" quat="1.000000 0.000000 0.000000 0.000000" name="right_foot">
                                <joint armature="0.000800" damping="1.000000" stiffness="4.000000" axis="0.000000 1.000000 0.000000" pos="0.000000 0.000000 0.080000" range="-50.000000 50.000000" limited="true" name="right_ankle_y" type="hinge"/>
                                <joint armature="0.000600" damping="1.000000" stiffness="1.000000" axis="1.000000 0.000000 0.500000" pos="0.000000 0.000000 0.040000" range="-50.000000 50.000000" limited="true" name="right_ankle_x" type="hinge"/>
                                <geom condim="1" pos="0.035000 -0.030000 0.000000" quat="0.707107 0.067040 0.703922 0.000000" rgba="0.700000 0.500000 0.300000 1.000000" size="0.027000 0.105475 0.000000" material="matgeom" name="right_foot_cap1" type="capsule"/>
                                <geom condim="1" pos="0.035000 0.010000 0.000000" quat="0.707107 -0.067040 0.703922 0.000000" rgba="0.700000 0.500000 0.300000 1.000000" size="0.027000 0.105475 0.000000" material="matgeom" name="right_foot_cap2" type="capsule"/>
                            </body>
                        </body>
                    </body>
                    <body pos="0.000000 0.100000 -0.040000" quat="1.000000 0.000000 0.000000 0.000000" name="left_thigh">
                        <joint armature="0.010000" damping="5.000000" stiffness="10.000000" axis="-1.000000 0.000000 0.000000" pos="0.000000 0.000000 0.000000" range="-25.000000 5.000000" limited="true" name="left_hip_x" type="hinge"/>
                        <joint armature="0.010000" damping="5.000000" stiffness="10.000000" axis="0.000000 0.000000 -1.000000" pos="0.000000 0.000000 0.000000" range="-60.000000 35.000000" limited="true" name="left_hip_z" type="hinge"/>
                        <joint armature="0.010000" damping="5.000000" stiffness="20.000000" axis="0.000000 1.000000 0.000000" pos="0.000000 0.000000 0.000000" range="-120.000000 20.000000" limited="true" name="left_hip_y" type="hinge"/>
                        <geom condim="1" pos="0.000000 -0.005000 -0.170000" quat="0.014703 0.999892 0.000000 0.000000" rgba="0.700000 0.500000 0.300000 1.000000" size="0.060000 0.170074 0.000000" material="matgeom" name="left_thigh1" type="capsule"/>
                        <body pos="0.000000 -0.010000 -0.403000" quat="1.000000 0.000000 0.000000 0.000000" name="left_shin">
                            <joint armature="0.006000" damping="1.000000" stiffness="1.000000" axis="0.000000 -1.000000 0.000000" pos="0.000000 0.000000 0.020000" range="-160.000000 -2.000000" limited="true" name="left_knee" type="hinge"/>
                            <geom condim="1" pos="0.000000 0.000000 -0.150000" quat="0.000000 0.000000 1.000000 0.000000" rgba="0.700000 0.500000 0.300000 1.000000" size="0.049000 0.150000 0.000000" material="matgeom" name="left_shin1" type="capsule"/>
                            <body pos="0.000000 0.000000 -0.390000" quat="1.000000 0.000000 0.000000 0.000000" name="left_foot">
                                <joint armature="0.000800" damping="1.000000" stiffness="4.000000" axis="0.000000 1.000000 0.000000" pos="0.000000 0.000000 0.080000" range="-50.000000 50.000000" limited="true" name="left_ankle_y" type="hinge"/>
                                <joint armature="0.000600" damping="1.000000" stiffness="1.000000" axis="1.000000 0.000000 0.500000" pos="0.000000 0.000000 0.040000" range="-50.000000 50.000000" limited="true" name="left_ankle_x" type="hinge"/>
                                <geom condim="1" pos="0.035000 0.030000 0.000000" quat="0.707107 -0.067040 0.703922 0.000000" rgba="0.700000 0.500000 0.300000 1.000000" size="0.027000 0.105475 0.000000" material="matgeom" name="left_foot_cap1" type="capsule"/>
                                <geom condim="1" pos="0.035000 -0.010000 0.000000" quat="0.707107 0.067040 0.703922 0.000000" rgba="0.700000 0.500000 0.300000 1.000000" size="0.027000 0.105475 0.000000" material="matgeom" name="left_foot_cap2" type="capsule"/>
                            </body>
                        </body>
                    </body>
                </body>
            </body>
            <body pos="0.000000 -0.170000 0.060000" quat="1.000000 0.000000 0.000000 0.000000" name="right_upper_arm">
                <joint armature="0.006800" damping="1.000000" stiffness="1.000000" axis="2.000000 1.000000 1.000000" pos="0.000000 0.000000 0.000000" range="-85.000000 60.000000" limited="true" name="right_shoulder1" type="hinge"/>
                <joint armature="0.005100" damping="1.000000" stiffness="1.000000" axis="0.000000 -1.000000 1.000000" pos="0.000000 0.000000 0.000000" range="-85.000000 60.000000" limited="true" name="right_shoulder2" type="hinge"/>
                <geom condim="1" pos="0.080000 -0.080000 -0.080000" quat="0.459701 0.627963 0.627963 0.000000" rgba="0.700000 0.500000 0.300000 1.000000" size="0.040000 0.138564 0.000000" material="matgeom" name="right_uarm1" type="capsule"/>
                <body pos="0.180000 -0.180000 -0.180000" quat="1.000000 0.000000 0.000000 0.000000" name="right_lower_arm">
                    <joint armature="0.002800" damping="1.000000" axis="0.000000 -1.000000 1.000000" pos="0.000000 0.000000 0.000000" range="-90.000000 50.000000" limited="true" name="right_elbow" type="hinge"/>
                    <geom condim="1" pos="0.090000 0.090000 0.090000" quat="0.888074 -0.325058 0.325058 0.000000" rgba="0.700000 0.500000 0.300000 1.000000" size="0.031000 0.138564 0.000000" material="matgeom" name="right_larm" type="capsule"/>
                    <geom condim="1" pos="0.180000 0.180000 0.180000" quat="1.000000 0.000000 0.000000 0.000000" rgba="0.700000 0.500000 0.300000 1.000000" size="0.040000 0.000000 0.000000" material="matgeom" name="right_hand" type="sphere"/>
                </body>
            </body>
            <body pos="0.000000 0.170000 0.060000" quat="1.000000 0.000000 0.000000 0.000000" name="left_upper_arm">
                <joint armature="0.006800" damping="1.000000" stiffness="1.000000" axis="2.000000 -1.000000 1.000000" pos="0.000000 0.000000 0.000000" range="-60.000000 85.000000" limited="true" name="left_shoulder1" type="hinge"/>
                <joint armature="0.005100" damping="1.000000" stiffness="1.000000" axis="0.000000 1.000000 1.000000" pos="0.000000 0.000000 0.000000" range="-60.000000 85.000000" limited="true" name="left_shoulder2" type="hinge"/>
                <geom condim="1" pos="0.080000 0.080000 -0.080000" quat="0.459701 -0.627963 0.627963 0.000000" rgba="0.700000 0.500000 0.300000 1.000000" size="0.040000 0.138564 0.000000" material="matgeom" name="left_uarm1" type="capsule"/>
                <body pos="0.180000 0.180000 -0.180000" quat="1.000000 0.000000 0.000000 0.000000" name="left_lower_arm">
                    <joint armature="0.002800" damping="1.000000" axis="0.000000 -1.000000 -1.000000" pos="0.000000 0.000000 0.000000" range="-90.000000 50.000000" limited="true" name="left_elbow" type="hinge"/>
                    <geom condim="1" pos="0.090000 -0.090000 0.090000" quat="0.888074 0.325058 0.325058 0.000000" rgba="0.700000 0.500000 0.300000 1.000000" size="0.031000 0.138564 0.000000" material="matgeom" name="left_larm" type="capsule"/>
                    <geom condim="1" pos="0.180000 -0.180000 0.180000" quat="1.000000 0.000000 0.000000 0.000000" rgba="0.700000 0.500000 0.300000 1.000000" size="0.040000 0.000000 0.000000" material="matgeom" name="left_hand" type="sphere"/>
                </body>
            </body>
        </body>
    </worldbody>
    <actuator>
        <motor ctrlrange="-0.400000 0.400000" gear="200.000000" ctrllimited="true" joint="abdomen_y" name="abdomen_y"/>
        <motor ctrlrange="-0.400000 0.400000" gear="200.000000" ctrllimited="true" joint="abdomen_z" name="abdomen_z"/>
        <motor ctrlrange="-0.400000 0.400000" gear="200.000000" ctrllimited="true" joint="abdomen_x" name="abdomen_x"/>
        <motor ctrlrange="-0.400000 0.400000" gear="200.000000" ctrllimited="true" joint="right_hip_x" name="right_hip_x"/>
        <motor ctrlrange="-0.400000 0.400000" gear="200.000000" ctrllimited="true" joint="right_hip_z" name="right_hip_z"/>
        <motor ctrlrange="-0.400000 0.400000" gear="600.000000" ctrllimited="true" joint="right_hip_y" name="right_hip_y"/>
        <motor ctrlrange="-0.400000 0.400000" gear="400.000000" ctrllimited="true" joint="right_knee" name="right_knee"/>
        <motor ctrlrange="-0.400000 0.400000" gear="100.000000" ctrllimited="true" joint="right_ankle_x" name="right_ankle_x"/>
        <motor ctrlrange="-0.400000 0.400000" gear="100.000000" ctrllimited="true" joint="right_ankle_y" name="right_ankle_y"/>
        <motor ctrlrange="-0.400000 0.400000" gear="200.000000" ctrllimited="true" joint="left_hip_x" name="left_hip_x"/>
        <motor ctrlrange="-0.400000 0.400000" gear="200.000000" ctrllimited="true" joint="left_hip_z" name="left_hip_z"/>
        <motor ctrlrange="-0.400000 0.400000" gear="600.000000" ctrllimited="true" joint="left_hip_y" name="left_hip_y"/>
        <motor ctrlrange="-0.400000 0.400000" gear="400.000000" ctrllimited="true" joint="left_knee" name="left_knee"/>
        <motor ctrlrange="-0.400000 0.400000" gear="100.000000" ctrllimited="true" joint="left_ankle_x" name="left_ankle_x"/>
        <motor ctrlrange="-0.400000 0.400000" gear="100.000000" ctrllimited="true" joint="left_ankle_y" name="left_ankle_y"/>
        <motor ctrlrange="-0.400000 0.400000" gear="100.000000" ctrllimited="true" joint="right_shoulder1" name="right_shoulder1"/>
        <motor ctrlrange="-0.400000 0.400000" gear="100.000000" ctrllimited="true" joint="right_shoulder2" name="right_shoulder2"/>
        <motor ctrlrange="-0.400000 0.400000" gear="200.000000" ctrllimited="true" joint="right_elbow" name="right_elbow"/>
        <motor ctrlrange="-0.400000 0.400000" gear="100.000000" ctrllimited="true" joint="left_shoulder1" name="left_shoulder1"/>
        <motor ctrlrange="-0.400000 0.400000" gear="100.000000" ctrllimited="true" joint="left_shoulder2" name="left_shoulder2"/>
        <motor ctrlrange="-0.400000 0.400000" gear="200.000000" ctrllimited="true" joint="left_elbow" name="left_elbow"/>
    </actuator>
    <sensor>
        <jointpos joint="abdomen_z" name="sensor_agent0_abdomen_z_jointpos"/>
        <jointvel joint="abdomen_z" name="sensor_agent0_abdomen_z_jointvel"/>
        <jointpos joint="abdomen_y" name="sensor_agent0_abdomen_y_jointpos"/>
        <jointvel joint="abdomen_y" name="sensor_agent0_abdomen_y_jointvel"/>
        <jointpos joint="abdomen_x" name="sensor_agent0_abdomen_x_jointpos"/>
        <jointvel joint="abdomen_x" name="sensor_agent0_abdomen_x_jointvel"/>
        <jointpos joint="right_hip_x" name="sensor_agent0_right_hip_x_jointpos"/>
        <jointvel joint="right_hip_x" name="sensor_agent0_right_hip_x_jointvel"/>
        <jointpos joint="right_hip_z" name="sensor_agent0_right_hip_z_jointpos"/>
        <jointvel joint="right_hip_z" name="sensor_agent0_right_hip_z_jointvel"/>
        <jointpos joint="right_hip_y" name="sensor_agent0_right_hip_y_jointpos"/>
        <jointvel joint="right_hip_y" name="sensor_agent0_right_hip_y_jointvel"/>
        <jointpos joint="right_knee" name="sensor_agent0_right_knee_jointpos"/>
        <jointvel joint="right_knee" name="sensor_agent0_right_knee_jointvel"/>
        <jointpos joint="right_ankle_y" name="sensor_agent0_right_ankle_y_jointpos"/>
        <jointvel joint="right_ankle_y" name="sensor_agent0_right_ankle_y_jointvel"/>
        <jointpos joint="right_ankle_x" name="sensor_agent0_right_ankle_x_jointpos"/>
        <jointvel joint="right_ankle_x" name="sensor_agent0_right_ankle_x_jointvel"/>
        <jointpos joint="left_hip_x" name="sensor_agent0_left_hip_x_jointpos"/>
        <jointvel joint="left_hip_x" name="sensor_agent0_left_hip_x_jointvel"/>
        <jointpos joint="left_hip_z" name="sensor_agent0_left_hip_z_jointpos"/>
        <jointvel joint="left_hip_z" name="sensor_agent0_left_hip_z_jointvel"/>
        <jointpos joint="left_hip_y" name="sensor_agent0_left_hip_y_jointpos"/>
        <jointvel joint="left_hip_y" name="sensor_agent0_left_hip_y_jointvel"/>
        <jointpos joint="left_knee" name="sensor_agent0_left_knee_jointpos"/>
        <jointvel joint="left_knee" name="sensor_agent0_left_knee_jointvel"/>
        <jointpos joint="left_ankle_y" name="sensor_agent0_left_ankle_y_jointpos"/>
        <jointvel joint="left_ankle_y" name="sensor_agent0_left_ankle_y_jointvel"/>
        <jointpos joint="left_ankle_x" name="sensor_agent0_left_ankle_x_jointpos"/>
        <jointvel joint="left_ankle_x" name="sensor_agent0_left_ankle_x_jointvel"/>
        <jointpos joint="right_shoulder1" name="sensor_agent0_right_shoulder1_jointpos"/>
        <jointvel joint="right_shoulder1" name="sensor_agent0_right_shoulder1_jointvel"/>
        <jointpos joint="right_shoulder2" name="sensor_agent0_right_shoulder2_jointpos"/>
        <jointvel joint="right_shoulder2" name="sensor_agent0_right_shoulder2_jointvel"/>
        <jointpos joint="right_elbow" name="sensor_agent0_right_elbow_jointpos"/>
        <jointvel joint="right_elbow" name="sensor_agent0_right_elbow_jointvel"/>
        <jointpos joint="left_shoulder1" name="sensor_agent0_left_shoulder1_jointpos"/>
        <jointvel joint="left_shoulder1" name="sensor_agent0_left_shoulder1_jointvel"/>
        <jointpos joint="left_shoulder2" name="sensor_agent0_left_shoulder2_jointpos"/>
        <jointvel joint="left_shoulder2" name="sensor_agent0_left_shoulder2_jointvel"/>
        <jointpos joint="left_elbow" name="sensor_agent0_left_elbow_jointpos"/>
        <jointvel joint="left_elbow" name="sensor_agent0_left_elbow_jointvel"/>
        <framelinvel name="sensoragent0_tmjcroot_framelinvel" objname="tmjcroot" objtype="body"/>
        <framelinacc name="sensoragent0_tmjcroot_framelinacc" objname="tmjcroot" objtype="body"/>
        <framelinvel name="sensoragent0_lwaist_framelinvel" objname="lwaist" objtype="body"/>
        <framelinacc name="sensoragent0_lwaist_framelinacc" objname="lwaist" objtype="body"/>
        <framelinvel name="sensoragent0_pelvis_framelinvel" objname="pelvis" objtype="body"/>
        <framelinacc name="sensoragent0_pelvis_framelinacc" objname="pelvis" objtype="body"/>
        <framelinvel name="sensoragent0_right_thigh_framelinvel" objname="right_thigh" objtype="body"/>
        <framelinacc name="sensoragent0_right_thigh_framelinacc" objname="right_thigh" objtype="body"/>
        <framelinvel name="sensoragent0_right_shin_framelinvel" objname="right_shin" objtype="body"/>
        <framelinacc name="sensoragent0_right_shin_framelinacc" objname="right_shin" objtype="body"/>
        <framelinvel name="sensoragent0_right_foot_framelinvel" objname="right_foot" objtype="body"/>
        <framelinacc name="sensoragent0_right_foot_framelinacc" objname="right_foot" objtype="body"/>
        <framelinvel name="sensoragent0_left_thigh_framelinvel" objname="left_thigh" objtype="body"/>
        <framelinacc name="sensoragent0_left_thigh_framelinacc" objname="left_thigh" objtype="body"/>
        <framelinvel name="sensoragent0_left_shin_framelinvel" objname="left_shin" objtype="body"/>
        <framelinacc name="sensoragent0_left_shin_framelinacc" objname="left_shin" objtype="body"/>
        <framelinvel name="sensoragent0_left_foot_framelinvel" objname="left_foot" objtype="body"/>
        <framelinacc name="sensoragent0_left_foot_framelinacc" objname="left_foot" objtype="body"/>
        <framelinvel name="sensoragent0_right_upper_arm_framelinvel" objname="right_upper_arm" objtype="body"/>
        <framelinacc name="sensoragent0_right_upper_arm_framelinacc" objname="right_upper_arm" objtype="body"/>
        <framelinvel name="sensoragent0_right_lower_arm_framelinvel" objname="right_lower_arm" objtype="body"/>
        <framelinacc name="sensoragent0_right_lower_arm_framelinacc" objname="right_lower_arm" objtype="body"/>
        <framelinvel name="sensoragent0_left_upper_arm_framelinvel" objname="left_upper_arm" objtype="body"/>
        <framelinacc name="sensoragent0_left_upper_arm_framelinacc" objname="left_upper_arm" objtype="body"/>
        <framelinvel name="sensoragent0_left_lower_arm_framelinvel" objname="left_lower_arm" objtype="body"/>
        <framelinacc name="sensoragent0_left_lower_arm_framelinacc" objname="left_lower_arm" objtype="body"/>
    </sensor>
</mujoco>
