<mujoco>
    <include file="materials.xml"/>
    <compiler angle="degree" coordinate="local" inertiafromgeom="true"/>
    <option iterations="50" timestep="0.005000" tolerance="0.000000" cone="pyramidal" jacobian="dense" solver="Newton"/>
    <size nconmax="4000" njmax="8000"/>
    <statistic extent="2.000000" center="0.000000 0.000000 1.000000"/>
    <asset>
        <texture height="512" width="512" rgb1="0.300000 0.500000 0.700000" rgb2="0.000000 0.000000 0.000000" builtin="gradient" type="skybox"/>
        <texture height="512" width="512" markrgb="0.800000 0.800000 0.800000" rgb1="0.200000 0.300000 0.400000" rgb2="0.100000 0.150000 0.200000" builtin="checker" mark="cross" name="texplane" type="2d"/>
        <texture height="1278" width="127" random="0.010000" markrgb="1.000000 1.000000 1.000000" rgb1="0.800000 0.600000 0.400000" rgb2="0.800000 0.600000 0.400000" builtin="flat" mark="cross" name="texgeom" type="cube"/>
        <material reflectance="0.300000" texrepeat="1.000000 1.000000" name="matplane" texture="texplane" texuniform="true"/>
        <material rgba="0.800000 0.600000 0.400000 1.000000" name="matgeom" texture="texgeom" texuniform="true"/>
    </asset>
    <visual>
        <map force="0.100000" zfar="30.000000"/>
        <rgba haze="0.150000 0.250000 0.350000 1.000000"/>
        <quality shadowsize="2048"/>
        <global offheight="800" offwidth="800"/>
    </visual>
    <worldbody>
        <geom conaffinity="1" contype="1" friction="0.700000 0.100000 0.100000" pos="0.000000 0.000000 -10.000000" size="1.000000 1.000000 0.200000" zaxis="0.000000 0.000000 1.000000" name="floor" type="plane"/>
    </worldbody>
    <worldbody>
        <body pos="0.000000 0.000000 100.000000" quat="1.000000 0.000000 0.000000 0.000000" name="terrainGen_terrain_proc0_0">
            <geom conaffinity="1" contype="0" mass="1.000000" pos="0.000000 0.000000 0.000000" quat="1.000000 0.000000 0.000000 0.000000" size="0.250000 1.000000 0.012500" name="terrainGen_terrain_proc0_0" type="box"/>
        </body>
        <body pos="0.000000 0.000000 101.025002" quat="1.000000 0.000000 0.000000 0.000000" name="terrainGen_terrain_proc0_1">
            <geom conaffinity="1" contype="0" mass="1.000000" pos="0.000000 0.000000 0.000000" quat="1.000000 0.000000 0.000000 0.000000" size="0.250000 1.000000 0.012500" name="terrainGen_terrain_proc0_1" type="box"/>
        </body>
        <body pos="0.000000 0.000000 102.050003" quat="1.000000 0.000000 0.000000 0.000000" name="terrainGen_terrain_proc0_2">
            <geom conaffinity="1" contype="0" mass="1.000000" pos="0.000000 0.000000 0.000000" quat="1.000000 0.000000 0.000000 0.000000" size="0.250000 1.000000 0.012500" name="terrainGen_terrain_proc0_2" type="box"/>
        </body>
        <body pos="0.000000 0.000000 103.074997" quat="1.000000 0.000000 0.000000 0.000000" name="terrainGen_terrain_proc0_3">
            <geom conaffinity="1" contype="0" mass="1.000000" pos="0.000000 0.000000 0.000000" quat="1.000000 0.000000 0.000000 0.000000" size="0.250000 1.000000 0.012500" name="terrainGen_terrain_proc0_3" type="box"/>
        </body>
        <body pos="0.000000 0.000000 104.099998" quat="1.000000 0.000000 0.000000 0.000000" name="terrainGen_terrain_proc0_4">
            <geom conaffinity="1" contype="0" mass="1.000000" pos="0.000000 0.000000 0.000000" quat="1.000000 0.000000 0.000000 0.000000" size="0.250000 1.000000 0.012500" name="terrainGen_terrain_proc0_4" type="box"/>
        </body>
        <body pos="0.000000 0.000000 105.125000" quat="1.000000 0.000000 0.000000 0.000000" name="terrainGen_terrain_proc0_5">
            <geom conaffinity="1" contype="0" mass="1.000000" pos="0.000000 0.000000 0.000000" quat="1.000000 0.000000 0.000000 0.000000" size="0.250000 1.000000 0.012500" name="terrainGen_terrain_proc0_5" type="box"/>
        </body>
        <body pos="0.000000 0.000000 106.150002" quat="1.000000 0.000000 0.000000 0.000000" name="terrainGen_terrain_proc0_6">
            <geom conaffinity="1" contype="0" mass="1.000000" pos="0.000000 0.000000 0.000000" quat="1.000000 0.000000 0.000000 0.000000" size="0.250000 1.000000 0.012500" name="terrainGen_terrain_proc0_6" type="box"/>
        </body>
        <body pos="0.000000 0.000000 107.175003" quat="1.000000 0.000000 0.000000 0.000000" name="terrainGen_terrain_proc0_7">
            <geom conaffinity="1" contype="0" mass="1.000000" pos="0.000000 0.000000 0.000000" quat="1.000000 0.000000 0.000000 0.000000" size="0.250000 1.000000 0.012500" name="terrainGen_terrain_proc0_7" type="box"/>
        </body>
        <body pos="0.000000 0.000000 108.199997" quat="1.000000 0.000000 0.000000 0.000000" name="terrainGen_terrain_proc0_8">
            <geom conaffinity="1" contype="0" mass="1.000000" pos="0.000000 0.000000 0.000000" quat="1.000000 0.000000 0.000000 0.000000" size="0.250000 1.000000 0.012500" name="terrainGen_terrain_proc0_8" type="box"/>
        </body>
        <body pos="0.000000 0.000000 109.224998" quat="1.000000 0.000000 0.000000 0.000000" name="terrainGen_terrain_proc0_9">
            <geom conaffinity="1" contype="0" mass="1.000000" pos="0.000000 0.000000 0.000000" quat="1.000000 0.000000 0.000000 0.000000" size="0.250000 1.000000 0.012500" name="terrainGen_terrain_proc0_9" type="box"/>
        </body>
        <body pos="0.000000 0.000000 110.250000" quat="1.000000 0.000000 0.000000 0.000000" name="terrainGen_terrain_proc0_10">
            <geom conaffinity="1" contype="0" mass="1.000000" pos="0.000000 0.000000 0.000000" quat="1.000000 0.000000 0.000000 0.000000" size="0.250000 1.000000 0.012500" name="terrainGen_terrain_proc0_10" type="box"/>
        </body>
        <body pos="0.000000 0.000000 111.275002" quat="1.000000 0.000000 0.000000 0.000000" name="terrainGen_terrain_proc0_11">
            <geom conaffinity="1" contype="0" mass="1.000000" pos="0.000000 0.000000 0.000000" quat="1.000000 0.000000 0.000000 0.000000" size="0.250000 1.000000 0.012500" name="terrainGen_terrain_proc0_11" type="box"/>
        </body>
        <body pos="0.000000 0.000000 112.300003" quat="1.000000 0.000000 0.000000 0.000000" name="terrainGen_terrain_proc0_12">
            <geom conaffinity="1" contype="0" mass="1.000000" pos="0.000000 0.000000 0.000000" quat="1.000000 0.000000 0.000000 0.000000" size="0.250000 1.000000 0.012500" name="terrainGen_terrain_proc0_12" type="box"/>
        </body>
        <body pos="0.000000 0.000000 113.324997" quat="1.000000 0.000000 0.000000 0.000000" name="terrainGen_terrain_proc0_13">
            <geom conaffinity="1" contype="0" mass="1.000000" pos="0.000000 0.000000 0.000000" quat="1.000000 0.000000 0.000000 0.000000" size="0.250000 1.000000 0.012500" name="terrainGen_terrain_proc0_13" type="box"/>
        </body>
        <body pos="0.000000 0.000000 114.349998" quat="1.000000 0.000000 0.000000 0.000000" name="terrainGen_terrain_proc0_14">
            <geom conaffinity="1" contype="0" mass="1.000000" pos="0.000000 0.000000 0.000000" quat="1.000000 0.000000 0.000000 0.000000" size="0.250000 1.000000 0.012500" name="terrainGen_terrain_proc0_14" type="box"/>
        </body>
        <body pos="0.000000 0.000000 115.375000" quat="1.000000 0.000000 0.000000 0.000000" name="terrainGen_terrain_proc0_15">
            <geom conaffinity="1" contype="0" mass="1.000000" pos="0.000000 0.000000 0.000000" quat="1.000000 0.000000 0.000000 0.000000" size="0.250000 1.000000 0.012500" name="terrainGen_terrain_proc0_15" type="box"/>
        </body>
        <body pos="0.000000 0.000000 116.400002" quat="1.000000 0.000000 0.000000 0.000000" name="terrainGen_terrain_proc0_16">
            <geom conaffinity="1" contype="0" mass="1.000000" pos="0.000000 0.000000 0.000000" quat="1.000000 0.000000 0.000000 0.000000" size="0.250000 1.000000 0.012500" name="terrainGen_terrain_proc0_16" type="box"/>
        </body>
        <body pos="0.000000 0.000000 117.425003" quat="1.000000 0.000000 0.000000 0.000000" name="terrainGen_terrain_proc0_17">
            <geom conaffinity="1" contype="0" mass="1.000000" pos="0.000000 0.000000 0.000000" quat="1.000000 0.000000 0.000000 0.000000" size="0.250000 1.000000 0.012500" name="terrainGen_terrain_proc0_17" type="box"/>
        </body>
        <body pos="0.000000 0.000000 118.449997" quat="1.000000 0.000000 0.000000 0.000000" name="terrainGen_terrain_proc0_18">
            <geom conaffinity="1" contype="0" mass="1.000000" pos="0.000000 0.000000 0.000000" quat="1.000000 0.000000 0.000000 0.000000" size="0.250000 1.000000 0.012500" name="terrainGen_terrain_proc0_18" type="box"/>
        </body>
        <body pos="0.000000 0.000000 119.474998" quat="1.000000 0.000000 0.000000 0.000000" name="terrainGen_terrain_proc0_19">
            <geom conaffinity="1" contype="0" mass="1.000000" pos="0.000000 0.000000 0.000000" quat="1.000000 0.000000 0.000000 0.000000" size="0.250000 1.000000 0.012500" name="terrainGen_terrain_proc0_19" type="box"/>
        </body>
        <body pos="0.000000 0.000000 120.500000" quat="1.000000 0.000000 0.000000 0.000000" name="terrainGen_terrain_proc0_20">
            <geom conaffinity="1" contype="0" mass="1.000000" pos="0.000000 0.000000 0.000000" quat="1.000000 0.000000 0.000000 0.000000" size="0.250000 1.000000 0.012500" name="terrainGen_terrain_proc0_20" type="box"/>
        </body>
        <body pos="0.000000 0.000000 121.525002" quat="1.000000 0.000000 0.000000 0.000000" name="terrainGen_terrain_proc0_21">
            <geom conaffinity="1" contype="0" mass="1.000000" pos="0.000000 0.000000 0.000000" quat="1.000000 0.000000 0.000000 0.000000" size="0.250000 1.000000 0.012500" name="terrainGen_terrain_proc0_21" type="box"/>
        </body>
        <body pos="0.000000 0.000000 122.550003" quat="1.000000 0.000000 0.000000 0.000000" name="terrainGen_terrain_proc0_22">
            <geom conaffinity="1" contype="0" mass="1.000000" pos="0.000000 0.000000 0.000000" quat="1.000000 0.000000 0.000000 0.000000" size="0.250000 1.000000 0.012500" name="terrainGen_terrain_proc0_22" type="box"/>
        </body>
        <body pos="0.000000 0.000000 123.574997" quat="1.000000 0.000000 0.000000 0.000000" name="terrainGen_terrain_proc0_23">
            <geom conaffinity="1" contype="0" mass="1.000000" pos="0.000000 0.000000 0.000000" quat="1.000000 0.000000 0.000000 0.000000" size="0.250000 1.000000 0.012500" name="terrainGen_terrain_proc0_23" type="box"/>
        </body>
        <body pos="0.000000 0.000000 124.599998" quat="1.000000 0.000000 0.000000 0.000000" name="terrainGen_terrain_proc0_24">
            <geom conaffinity="1" contype="0" mass="1.000000" pos="0.000000 0.000000 0.000000" quat="1.000000 0.000000 0.000000 0.000000" size="0.250000 1.000000 0.012500" name="terrainGen_terrain_proc0_24" type="box"/>
        </body>
        <body pos="0.000000 0.000000 125.625000" quat="1.000000 0.000000 0.000000 0.000000" name="terrainGen_terrain_proc0_25">
            <geom conaffinity="1" contype="0" mass="1.000000" pos="0.000000 0.000000 0.000000" quat="1.000000 0.000000 0.000000 0.000000" size="0.250000 1.000000 0.012500" name="terrainGen_terrain_proc0_25" type="box"/>
        </body>
        <body pos="0.000000 0.000000 126.650002" quat="1.000000 0.000000 0.000000 0.000000" name="terrainGen_terrain_proc0_26">
            <geom conaffinity="1" contype="0" mass="1.000000" pos="0.000000 0.000000 0.000000" quat="1.000000 0.000000 0.000000 0.000000" size="0.250000 1.000000 0.012500" name="terrainGen_terrain_proc0_26" type="box"/>
        </body>
        <body pos="0.000000 0.000000 127.675003" quat="1.000000 0.000000 0.000000 0.000000" name="terrainGen_terrain_proc0_27">
            <geom conaffinity="1" contype="0" mass="1.000000" pos="0.000000 0.000000 0.000000" quat="1.000000 0.000000 0.000000 0.000000" size="0.250000 1.000000 0.012500" name="terrainGen_terrain_proc0_27" type="box"/>
        </body>
        <body pos="0.000000 0.000000 128.699997" quat="1.000000 0.000000 0.000000 0.000000" name="terrainGen_terrain_proc0_28">
            <geom conaffinity="1" contype="0" mass="1.000000" pos="0.000000 0.000000 0.000000" quat="1.000000 0.000000 0.000000 0.000000" size="0.250000 1.000000 0.012500" name="terrainGen_terrain_proc0_28" type="box"/>
        </body>
        <body pos="0.000000 0.000000 129.725006" quat="1.000000 0.000000 0.000000 0.000000" name="terrainGen_terrain_proc0_29">
            <geom conaffinity="1" contype="0" mass="1.000000" pos="0.000000 0.000000 0.000000" quat="1.000000 0.000000 0.000000 0.000000" size="0.250000 1.000000 0.012500" name="terrainGen_terrain_proc0_29" type="box"/>
        </body>
        <body pos="0.000000 0.000000 130.750000" quat="1.000000 0.000000 0.000000 0.000000" name="terrainGen_terrain_proc0_30">
            <geom conaffinity="1" contype="0" mass="1.000000" pos="0.000000 0.000000 0.000000" quat="1.000000 0.000000 0.000000 0.000000" size="0.250000 1.000000 0.012500" name="terrainGen_terrain_proc0_30" type="box"/>
        </body>
        <body pos="0.000000 0.000000 131.774994" quat="1.000000 0.000000 0.000000 0.000000" name="terrainGen_terrain_proc0_31">
            <geom conaffinity="1" contype="0" mass="1.000000" pos="0.000000 0.000000 0.000000" quat="1.000000 0.000000 0.000000 0.000000" size="0.250000 1.000000 0.012500" name="terrainGen_terrain_proc0_31" type="box"/>
        </body>
        <body pos="0.000000 0.000000 132.800003" quat="1.000000 0.000000 0.000000 0.000000" name="terrainGen_terrain_proc0_32">
            <geom conaffinity="1" contype="0" mass="1.000000" pos="0.000000 0.000000 0.000000" quat="1.000000 0.000000 0.000000 0.000000" size="0.250000 1.000000 0.012500" name="terrainGen_terrain_proc0_32" type="box"/>
        </body>
        <body pos="0.000000 0.000000 133.824997" quat="1.000000 0.000000 0.000000 0.000000" name="terrainGen_terrain_proc0_33">
            <geom conaffinity="1" contype="0" mass="1.000000" pos="0.000000 0.000000 0.000000" quat="1.000000 0.000000 0.000000 0.000000" size="0.250000 1.000000 0.012500" name="terrainGen_terrain_proc0_33" type="box"/>
        </body>
        <body pos="0.000000 0.000000 134.850006" quat="1.000000 0.000000 0.000000 0.000000" name="terrainGen_terrain_proc0_34">
            <geom conaffinity="1" contype="0" mass="1.000000" pos="0.000000 0.000000 0.000000" quat="1.000000 0.000000 0.000000 0.000000" size="0.250000 1.000000 0.012500" name="terrainGen_terrain_proc0_34" type="box"/>
        </body>
        <body pos="0.000000 0.000000 135.875000" quat="1.000000 0.000000 0.000000 0.000000" name="terrainGen_terrain_proc0_35">
            <geom conaffinity="1" contype="0" mass="1.000000" pos="0.000000 0.000000 0.000000" quat="1.000000 0.000000 0.000000 0.000000" size="0.250000 1.000000 0.012500" name="terrainGen_terrain_proc0_35" type="box"/>
        </body>
        <body pos="0.000000 0.000000 136.899994" quat="1.000000 0.000000 0.000000 0.000000" name="terrainGen_terrain_proc0_36">
            <geom conaffinity="1" contype="0" mass="1.000000" pos="0.000000 0.000000 0.000000" quat="1.000000 0.000000 0.000000 0.000000" size="0.250000 1.000000 0.012500" name="terrainGen_terrain_proc0_36" type="box"/>
        </body>
        <body pos="0.000000 0.000000 137.925003" quat="1.000000 0.000000 0.000000 0.000000" name="terrainGen_terrain_proc0_37">
            <geom conaffinity="1" contype="0" mass="1.000000" pos="0.000000 0.000000 0.000000" quat="1.000000 0.000000 0.000000 0.000000" size="0.250000 1.000000 0.012500" name="terrainGen_terrain_proc0_37" type="box"/>
        </body>
        <body pos="0.000000 0.000000 138.949997" quat="1.000000 0.000000 0.000000 0.000000" name="terrainGen_terrain_proc0_38">
            <geom conaffinity="1" contype="0" mass="1.000000" pos="0.000000 0.000000 0.000000" quat="1.000000 0.000000 0.000000 0.000000" size="0.250000 1.000000 0.012500" name="terrainGen_terrain_proc0_38" type="box"/>
        </body>
        <body pos="0.000000 0.000000 139.975006" quat="1.000000 0.000000 0.000000 0.000000" name="terrainGen_terrain_proc0_39">
            <geom conaffinity="1" contype="0" mass="1.000000" pos="0.000000 0.000000 0.000000" quat="1.000000 0.000000 0.000000 0.000000" size="0.250000 1.000000 0.012500" name="terrainGen_terrain_proc0_39" type="box"/>
        </body>
        <body pos="0.000000 0.000000 141.000000" quat="1.000000 0.000000 0.000000 0.000000" name="terrainGen_terrain_proc0_40">
            <geom conaffinity="1" contype="0" mass="1.000000" pos="0.000000 0.000000 0.000000" quat="1.000000 0.000000 0.000000 0.000000" size="0.250000 1.000000 0.012500" name="terrainGen_terrain_proc0_40" type="box"/>
        </body>
        <body pos="0.000000 0.000000 142.024994" quat="1.000000 0.000000 0.000000 0.000000" name="terrainGen_terrain_proc0_41">
            <geom conaffinity="1" contype="0" mass="1.000000" pos="0.000000 0.000000 0.000000" quat="1.000000 0.000000 0.000000 0.000000" size="0.250000 1.000000 0.012500" name="terrainGen_terrain_proc0_41" type="box"/>
        </body>
        <body pos="0.000000 0.000000 143.050003" quat="1.000000 0.000000 0.000000 0.000000" name="terrainGen_terrain_proc0_42">
            <geom conaffinity="1" contype="0" mass="1.000000" pos="0.000000 0.000000 0.000000" quat="1.000000 0.000000 0.000000 0.000000" size="0.250000 1.000000 0.012500" name="terrainGen_terrain_proc0_42" type="box"/>
        </body>
        <body pos="0.000000 0.000000 144.074997" quat="1.000000 0.000000 0.000000 0.000000" name="terrainGen_terrain_proc0_43">
            <geom conaffinity="1" contype="0" mass="1.000000" pos="0.000000 0.000000 0.000000" quat="1.000000 0.000000 0.000000 0.000000" size="0.250000 1.000000 0.012500" name="terrainGen_terrain_proc0_43" type="box"/>
        </body>
        <body pos="0.000000 0.000000 145.100006" quat="1.000000 0.000000 0.000000 0.000000" name="terrainGen_terrain_proc0_44">
            <geom conaffinity="1" contype="0" mass="1.000000" pos="0.000000 0.000000 0.000000" quat="1.000000 0.000000 0.000000 0.000000" size="0.250000 1.000000 0.012500" name="terrainGen_terrain_proc0_44" type="box"/>
        </body>
        <body pos="0.000000 0.000000 146.125000" quat="1.000000 0.000000 0.000000 0.000000" name="terrainGen_terrain_proc0_45">
            <geom conaffinity="1" contype="0" mass="1.000000" pos="0.000000 0.000000 0.000000" quat="1.000000 0.000000 0.000000 0.000000" size="0.250000 1.000000 0.012500" name="terrainGen_terrain_proc0_45" type="box"/>
        </body>
        <body pos="0.000000 0.000000 147.149994" quat="1.000000 0.000000 0.000000 0.000000" name="terrainGen_terrain_proc0_46">
            <geom conaffinity="1" contype="0" mass="1.000000" pos="0.000000 0.000000 0.000000" quat="1.000000 0.000000 0.000000 0.000000" size="0.250000 1.000000 0.012500" name="terrainGen_terrain_proc0_46" type="box"/>
        </body>
        <body pos="0.000000 0.000000 148.175003" quat="1.000000 0.000000 0.000000 0.000000" name="terrainGen_terrain_proc0_47">
            <geom conaffinity="1" contype="0" mass="1.000000" pos="0.000000 0.000000 0.000000" quat="1.000000 0.000000 0.000000 0.000000" size="0.250000 1.000000 0.012500" name="terrainGen_terrain_proc0_47" type="box"/>
        </body>
        <body pos="0.000000 0.000000 149.199997" quat="1.000000 0.000000 0.000000 0.000000" name="terrainGen_terrain_proc0_48">
            <geom conaffinity="1" contype="0" mass="1.000000" pos="0.000000 0.000000 0.000000" quat="1.000000 0.000000 0.000000 0.000000" size="0.250000 1.000000 0.012500" name="terrainGen_terrain_proc0_48" type="box"/>
        </body>
        <body pos="0.000000 0.000000 150.225006" quat="1.000000 0.000000 0.000000 0.000000" name="terrainGen_terrain_proc0_49">
            <geom conaffinity="1" contype="0" mass="1.000000" pos="0.000000 0.000000 0.000000" quat="1.000000 0.000000 0.000000 0.000000" size="0.250000 1.000000 0.012500" name="terrainGen_terrain_proc0_49" type="box"/>
        </body>
        <body pos="0.000000 0.000000 151.250000" quat="1.000000 0.000000 0.000000 0.000000" name="terrainGen_terrain_proc0_50">
            <geom conaffinity="1" contype="0" mass="1.000000" pos="0.000000 0.000000 0.000000" quat="1.000000 0.000000 0.000000 0.000000" size="0.250000 1.000000 0.012500" name="terrainGen_terrain_proc0_50" type="box"/>
        </body>
        <body pos="0.000000 0.000000 152.274994" quat="1.000000 0.000000 0.000000 0.000000" name="terrainGen_terrain_proc0_51">
            <geom conaffinity="1" contype="0" mass="1.000000" pos="0.000000 0.000000 0.000000" quat="1.000000 0.000000 0.000000 0.000000" size="0.250000 1.000000 0.012500" name="terrainGen_terrain_proc0_51" type="box"/>
        </body>
        <body pos="0.000000 0.000000 153.300003" quat="1.000000 0.000000 0.000000 0.000000" name="terrainGen_terrain_proc0_52">
            <geom conaffinity="1" contype="0" mass="1.000000" pos="0.000000 0.000000 0.000000" quat="1.000000 0.000000 0.000000 0.000000" size="0.250000 1.000000 0.012500" name="terrainGen_terrain_proc0_52" type="box"/>
        </body>
        <body pos="0.000000 0.000000 154.324997" quat="1.000000 0.000000 0.000000 0.000000" name="terrainGen_terrain_proc0_53">
            <geom conaffinity="1" contype="0" mass="1.000000" pos="0.000000 0.000000 0.000000" quat="1.000000 0.000000 0.000000 0.000000" size="0.250000 1.000000 0.012500" name="terrainGen_terrain_proc0_53" type="box"/>
        </body>
        <body pos="0.000000 0.000000 155.350006" quat="1.000000 0.000000 0.000000 0.000000" name="terrainGen_terrain_proc0_54">
            <geom conaffinity="1" contype="0" mass="1.000000" pos="0.000000 0.000000 0.000000" quat="1.000000 0.000000 0.000000 0.000000" size="0.250000 1.000000 0.012500" name="terrainGen_terrain_proc0_54" type="box"/>
        </body>
        <body pos="0.000000 0.000000 156.375000" quat="1.000000 0.000000 0.000000 0.000000" name="terrainGen_terrain_proc0_55">
            <geom conaffinity="1" contype="0" mass="1.000000" pos="0.000000 0.000000 0.000000" quat="1.000000 0.000000 0.000000 0.000000" size="0.250000 1.000000 0.012500" name="terrainGen_terrain_proc0_55" type="box"/>
        </body>
        <body pos="0.000000 0.000000 157.399994" quat="1.000000 0.000000 0.000000 0.000000" name="terrainGen_terrain_proc0_56">
            <geom conaffinity="1" contype="0" mass="1.000000" pos="0.000000 0.000000 0.000000" quat="1.000000 0.000000 0.000000 0.000000" size="0.250000 1.000000 0.012500" name="terrainGen_terrain_proc0_56" type="box"/>
        </body>
        <body pos="0.000000 0.000000 158.425003" quat="1.000000 0.000000 0.000000 0.000000" name="terrainGen_terrain_proc0_57">
            <geom conaffinity="1" contype="0" mass="1.000000" pos="0.000000 0.000000 0.000000" quat="1.000000 0.000000 0.000000 0.000000" size="0.250000 1.000000 0.012500" name="terrainGen_terrain_proc0_57" type="box"/>
        </body>
        <body pos="0.000000 0.000000 159.449997" quat="1.000000 0.000000 0.000000 0.000000" name="terrainGen_terrain_proc0_58">
            <geom conaffinity="1" contype="0" mass="1.000000" pos="0.000000 0.000000 0.000000" quat="1.000000 0.000000 0.000000 0.000000" size="0.250000 1.000000 0.012500" name="terrainGen_terrain_proc0_58" type="box"/>
        </body>
        <body pos="0.000000 0.000000 160.475006" quat="1.000000 0.000000 0.000000 0.000000" name="terrainGen_terrain_proc0_59">
            <geom conaffinity="1" contype="0" mass="1.000000" pos="0.000000 0.000000 0.000000" quat="1.000000 0.000000 0.000000 0.000000" size="0.250000 1.000000 0.012500" name="terrainGen_terrain_proc0_59" type="box"/>
        </body>
        <body pos="0.000000 0.000000 161.500000" quat="1.000000 0.000000 0.000000 0.000000" name="terrainGen_terrain_proc0_60">
            <geom conaffinity="1" contype="0" mass="1.000000" pos="0.000000 0.000000 0.000000" quat="1.000000 0.000000 0.000000 0.000000" size="0.250000 1.000000 0.012500" name="terrainGen_terrain_proc0_60" type="box"/>
        </body>
        <body pos="0.000000 0.000000 162.524994" quat="1.000000 0.000000 0.000000 0.000000" name="terrainGen_terrain_proc0_61">
            <geom conaffinity="1" contype="0" mass="1.000000" pos="0.000000 0.000000 0.000000" quat="1.000000 0.000000 0.000000 0.000000" size="0.250000 1.000000 0.012500" name="terrainGen_terrain_proc0_61" type="box"/>
        </body>
        <body pos="0.000000 0.000000 163.550003" quat="1.000000 0.000000 0.000000 0.000000" name="terrainGen_terrain_proc0_62">
            <geom conaffinity="1" contype="0" mass="1.000000" pos="0.000000 0.000000 0.000000" quat="1.000000 0.000000 0.000000 0.000000" size="0.250000 1.000000 0.012500" name="terrainGen_terrain_proc0_62" type="box"/>
        </body>
        <body pos="0.000000 0.000000 164.574997" quat="1.000000 0.000000 0.000000 0.000000" name="terrainGen_terrain_proc0_63">
            <geom conaffinity="1" contype="0" mass="1.000000" pos="0.000000 0.000000 0.000000" quat="1.000000 0.000000 0.000000 0.000000" size="0.250000 1.000000 0.012500" name="terrainGen_terrain_proc0_63" type="box"/>
        </body>
        <body pos="0.000000 0.000000 165.600006" quat="1.000000 0.000000 0.000000 0.000000" name="terrainGen_terrain_proc0_64">
            <geom conaffinity="1" contype="0" mass="1.000000" pos="0.000000 0.000000 0.000000" quat="1.000000 0.000000 0.000000 0.000000" size="0.250000 1.000000 0.012500" name="terrainGen_terrain_proc0_64" type="box"/>
        </body>
        <body pos="0.000000 0.000000 166.625000" quat="1.000000 0.000000 0.000000 0.000000" name="terrainGen_terrain_proc0_65">
            <geom conaffinity="1" contype="0" mass="1.000000" pos="0.000000 0.000000 0.000000" quat="1.000000 0.000000 0.000000 0.000000" size="0.250000 1.000000 0.012500" name="terrainGen_terrain_proc0_65" type="box"/>
        </body>
        <body pos="0.000000 0.000000 167.649994" quat="1.000000 0.000000 0.000000 0.000000" name="terrainGen_terrain_proc0_66">
            <geom conaffinity="1" contype="0" mass="1.000000" pos="0.000000 0.000000 0.000000" quat="1.000000 0.000000 0.000000 0.000000" size="0.250000 1.000000 0.012500" name="terrainGen_terrain_proc0_66" type="box"/>
        </body>
        <body pos="0.000000 0.000000 168.674988" quat="1.000000 0.000000 0.000000 0.000000" name="terrainGen_terrain_proc0_67">
            <geom conaffinity="1" contype="0" mass="1.000000" pos="0.000000 0.000000 0.000000" quat="1.000000 0.000000 0.000000 0.000000" size="0.250000 1.000000 0.012500" name="terrainGen_terrain_proc0_67" type="box"/>
        </body>
        <body pos="0.000000 0.000000 169.699997" quat="1.000000 0.000000 0.000000 0.000000" name="terrainGen_terrain_proc0_68">
            <geom conaffinity="1" contype="0" mass="1.000000" pos="0.000000 0.000000 0.000000" quat="1.000000 0.000000 0.000000 0.000000" size="0.250000 1.000000 0.012500" name="terrainGen_terrain_proc0_68" type="box"/>
        </body>
        <body pos="0.000000 0.000000 170.725006" quat="1.000000 0.000000 0.000000 0.000000" name="terrainGen_terrain_proc0_69">
            <geom conaffinity="1" contype="0" mass="1.000000" pos="0.000000 0.000000 0.000000" quat="1.000000 0.000000 0.000000 0.000000" size="0.250000 1.000000 0.012500" name="terrainGen_terrain_proc0_69" type="box"/>
        </body>
        <body pos="0.000000 0.000000 171.750000" quat="1.000000 0.000000 0.000000 0.000000" name="terrainGen_terrain_proc0_70">
            <geom conaffinity="1" contype="0" mass="1.000000" pos="0.000000 0.000000 0.000000" quat="1.000000 0.000000 0.000000 0.000000" size="0.250000 1.000000 0.012500" name="terrainGen_terrain_proc0_70" type="box"/>
        </body>
        <body pos="0.000000 0.000000 172.774994" quat="1.000000 0.000000 0.000000 0.000000" name="terrainGen_terrain_proc0_71">
            <geom conaffinity="1" contype="0" mass="1.000000" pos="0.000000 0.000000 0.000000" quat="1.000000 0.000000 0.000000 0.000000" size="0.250000 1.000000 0.012500" name="terrainGen_terrain_proc0_71" type="box"/>
        </body>
        <body pos="0.000000 0.000000 173.799988" quat="1.000000 0.000000 0.000000 0.000000" name="terrainGen_terrain_proc0_72">
            <geom conaffinity="1" contype="0" mass="1.000000" pos="0.000000 0.000000 0.000000" quat="1.000000 0.000000 0.000000 0.000000" size="0.250000 1.000000 0.012500" name="terrainGen_terrain_proc0_72" type="box"/>
        </body>
        <body pos="0.000000 0.000000 174.824997" quat="1.000000 0.000000 0.000000 0.000000" name="terrainGen_terrain_proc0_73">
            <geom conaffinity="1" contype="0" mass="1.000000" pos="0.000000 0.000000 0.000000" quat="1.000000 0.000000 0.000000 0.000000" size="0.250000 1.000000 0.012500" name="terrainGen_terrain_proc0_73" type="box"/>
        </body>
        <body pos="0.000000 0.000000 175.850006" quat="1.000000 0.000000 0.000000 0.000000" name="terrainGen_terrain_proc0_74">
            <geom conaffinity="1" contype="0" mass="1.000000" pos="0.000000 0.000000 0.000000" quat="1.000000 0.000000 0.000000 0.000000" size="0.250000 1.000000 0.012500" name="terrainGen_terrain_proc0_74" type="box"/>
        </body>
        <body pos="0.000000 0.000000 176.875000" quat="1.000000 0.000000 0.000000 0.000000" name="terrainGen_terrain_proc0_75">
            <geom conaffinity="1" contype="0" mass="1.000000" pos="0.000000 0.000000 0.000000" quat="1.000000 0.000000 0.000000 0.000000" size="0.250000 1.000000 0.012500" name="terrainGen_terrain_proc0_75" type="box"/>
        </body>
        <body pos="0.000000 0.000000 177.899994" quat="1.000000 0.000000 0.000000 0.000000" name="terrainGen_terrain_proc0_76">
            <geom conaffinity="1" contype="0" mass="1.000000" pos="0.000000 0.000000 0.000000" quat="1.000000 0.000000 0.000000 0.000000" size="0.250000 1.000000 0.012500" name="terrainGen_terrain_proc0_76" type="box"/>
        </body>
        <body pos="0.000000 0.000000 178.924988" quat="1.000000 0.000000 0.000000 0.000000" name="terrainGen_terrain_proc0_77">
            <geom conaffinity="1" contype="0" mass="1.000000" pos="0.000000 0.000000 0.000000" quat="1.000000 0.000000 0.000000 0.000000" size="0.250000 1.000000 0.012500" name="terrainGen_terrain_proc0_77" type="box"/>
        </body>
        <body pos="0.000000 0.000000 179.949997" quat="1.000000 0.000000 0.000000 0.000000" name="terrainGen_terrain_proc0_78">
            <geom conaffinity="1" contype="0" mass="1.000000" pos="0.000000 0.000000 0.000000" quat="1.000000 0.000000 0.000000 0.000000" size="0.250000 1.000000 0.012500" name="terrainGen_terrain_proc0_78" type="box"/>
        </body>
        <body pos="0.000000 0.000000 180.975006" quat="1.000000 0.000000 0.000000 0.000000" name="terrainGen_terrain_proc0_79">
            <geom conaffinity="1" contype="0" mass="1.000000" pos="0.000000 0.000000 0.000000" quat="1.000000 0.000000 0.000000 0.000000" size="0.250000 1.000000 0.012500" name="terrainGen_terrain_proc0_79" type="box"/>
        </body>
        <body pos="0.000000 0.000000 182.000000" quat="1.000000 0.000000 0.000000 0.000000" name="terrainGen_terrain_proc0_80">
            <geom conaffinity="1" contype="0" mass="1.000000" pos="0.000000 0.000000 0.000000" quat="1.000000 0.000000 0.000000 0.000000" size="0.250000 1.000000 0.012500" name="terrainGen_terrain_proc0_80" type="box"/>
        </body>
        <body pos="0.000000 0.000000 183.024994" quat="1.000000 0.000000 0.000000 0.000000" name="terrainGen_terrain_proc0_81">
            <geom conaffinity="1" contype="0" mass="1.000000" pos="0.000000 0.000000 0.000000" quat="1.000000 0.000000 0.000000 0.000000" size="0.250000 1.000000 0.012500" name="terrainGen_terrain_proc0_81" type="box"/>
        </body>
        <body pos="0.000000 0.000000 184.049988" quat="1.000000 0.000000 0.000000 0.000000" name="terrainGen_terrain_proc0_82">
            <geom conaffinity="1" contype="0" mass="1.000000" pos="0.000000 0.000000 0.000000" quat="1.000000 0.000000 0.000000 0.000000" size="0.250000 1.000000 0.012500" name="terrainGen_terrain_proc0_82" type="box"/>
        </body>
        <body pos="0.000000 0.000000 185.074997" quat="1.000000 0.000000 0.000000 0.000000" name="terrainGen_terrain_proc0_83">
            <geom conaffinity="1" contype="0" mass="1.000000" pos="0.000000 0.000000 0.000000" quat="1.000000 0.000000 0.000000 0.000000" size="0.250000 1.000000 0.012500" name="terrainGen_terrain_proc0_83" type="box"/>
        </body>
        <body pos="0.000000 0.000000 186.100006" quat="1.000000 0.000000 0.000000 0.000000" name="terrainGen_terrain_proc0_84">
            <geom conaffinity="1" contype="0" mass="1.000000" pos="0.000000 0.000000 0.000000" quat="1.000000 0.000000 0.000000 0.000000" size="0.250000 1.000000 0.012500" name="terrainGen_terrain_proc0_84" type="box"/>
        </body>
        <body pos="0.000000 0.000000 187.125000" quat="1.000000 0.000000 0.000000 0.000000" name="terrainGen_terrain_proc0_85">
            <geom conaffinity="1" contype="0" mass="1.000000" pos="0.000000 0.000000 0.000000" quat="1.000000 0.000000 0.000000 0.000000" size="0.250000 1.000000 0.012500" name="terrainGen_terrain_proc0_85" type="box"/>
        </body>
        <body pos="0.000000 0.000000 188.149994" quat="1.000000 0.000000 0.000000 0.000000" name="terrainGen_terrain_proc0_86">
            <geom conaffinity="1" contype="0" mass="1.000000" pos="0.000000 0.000000 0.000000" quat="1.000000 0.000000 0.000000 0.000000" size="0.250000 1.000000 0.012500" name="terrainGen_terrain_proc0_86" type="box"/>
        </body>
        <body pos="0.000000 0.000000 189.174988" quat="1.000000 0.000000 0.000000 0.000000" name="terrainGen_terrain_proc0_87">
            <geom conaffinity="1" contype="0" mass="1.000000" pos="0.000000 0.000000 0.000000" quat="1.000000 0.000000 0.000000 0.000000" size="0.250000 1.000000 0.012500" name="terrainGen_terrain_proc0_87" type="box"/>
        </body>
        <body pos="0.000000 0.000000 190.199997" quat="1.000000 0.000000 0.000000 0.000000" name="terrainGen_terrain_proc0_88">
            <geom conaffinity="1" contype="0" mass="1.000000" pos="0.000000 0.000000 0.000000" quat="1.000000 0.000000 0.000000 0.000000" size="0.250000 1.000000 0.012500" name="terrainGen_terrain_proc0_88" type="box"/>
        </body>
        <body pos="0.000000 0.000000 191.225006" quat="1.000000 0.000000 0.000000 0.000000" name="terrainGen_terrain_proc0_89">
            <geom conaffinity="1" contype="0" mass="1.000000" pos="0.000000 0.000000 0.000000" quat="1.000000 0.000000 0.000000 0.000000" size="0.250000 1.000000 0.012500" name="terrainGen_terrain_proc0_89" type="box"/>
        </body>
        <body pos="0.000000 0.000000 192.250000" quat="1.000000 0.000000 0.000000 0.000000" name="terrainGen_terrain_proc0_90">
            <geom conaffinity="1" contype="0" mass="1.000000" pos="0.000000 0.000000 0.000000" quat="1.000000 0.000000 0.000000 0.000000" size="0.250000 1.000000 0.012500" name="terrainGen_terrain_proc0_90" type="box"/>
        </body>
        <body pos="0.000000 0.000000 193.274994" quat="1.000000 0.000000 0.000000 0.000000" name="terrainGen_terrain_proc0_91">
            <geom conaffinity="1" contype="0" mass="1.000000" pos="0.000000 0.000000 0.000000" quat="1.000000 0.000000 0.000000 0.000000" size="0.250000 1.000000 0.012500" name="terrainGen_terrain_proc0_91" type="box"/>
        </body>
        <body pos="0.000000 0.000000 194.299988" quat="1.000000 0.000000 0.000000 0.000000" name="terrainGen_terrain_proc0_92">
            <geom conaffinity="1" contype="0" mass="1.000000" pos="0.000000 0.000000 0.000000" quat="1.000000 0.000000 0.000000 0.000000" size="0.250000 1.000000 0.012500" name="terrainGen_terrain_proc0_92" type="box"/>
        </body>
        <body pos="0.000000 0.000000 195.324997" quat="1.000000 0.000000 0.000000 0.000000" name="terrainGen_terrain_proc0_93">
            <geom conaffinity="1" contype="0" mass="1.000000" pos="0.000000 0.000000 0.000000" quat="1.000000 0.000000 0.000000 0.000000" size="0.250000 1.000000 0.012500" name="terrainGen_terrain_proc0_93" type="box"/>
        </body>
        <body pos="0.000000 0.000000 196.350006" quat="1.000000 0.000000 0.000000 0.000000" name="terrainGen_terrain_proc0_94">
            <geom conaffinity="1" contype="0" mass="1.000000" pos="0.000000 0.000000 0.000000" quat="1.000000 0.000000 0.000000 0.000000" size="0.250000 1.000000 0.012500" name="terrainGen_terrain_proc0_94" type="box"/>
        </body>
        <body pos="0.000000 0.000000 197.375000" quat="1.000000 0.000000 0.000000 0.000000" name="terrainGen_terrain_proc0_95">
            <geom conaffinity="1" contype="0" mass="1.000000" pos="0.000000 0.000000 0.000000" quat="1.000000 0.000000 0.000000 0.000000" size="0.250000 1.000000 0.012500" name="terrainGen_terrain_proc0_95" type="box"/>
        </body>
        <body pos="0.000000 0.000000 198.399994" quat="1.000000 0.000000 0.000000 0.000000" name="terrainGen_terrain_proc0_96">
            <geom conaffinity="1" contype="0" mass="1.000000" pos="0.000000 0.000000 0.000000" quat="1.000000 0.000000 0.000000 0.000000" size="0.250000 1.000000 0.012500" name="terrainGen_terrain_proc0_96" type="box"/>
        </body>
        <body pos="0.000000 0.000000 199.424988" quat="1.000000 0.000000 0.000000 0.000000" name="terrainGen_terrain_proc0_97">
            <geom conaffinity="1" contype="0" mass="1.000000" pos="0.000000 0.000000 0.000000" quat="1.000000 0.000000 0.000000 0.000000" size="0.250000 1.000000 0.012500" name="terrainGen_terrain_proc0_97" type="box"/>
        </body>
        <body pos="0.000000 0.000000 200.449997" quat="1.000000 0.000000 0.000000 0.000000" name="terrainGen_terrain_proc0_98">
            <geom conaffinity="1" contype="0" mass="1.000000" pos="0.000000 0.000000 0.000000" quat="1.000000 0.000000 0.000000 0.000000" size="0.250000 1.000000 0.012500" name="terrainGen_terrain_proc0_98" type="box"/>
        </body>
    </worldbody>
    <worldbody>
        <body pos="2.000000 0.000000 1.500000" quat="1.000000 0.000000 0.000000 0.000000" name="body_biped3d0_root">
            <geom conaffinity="0" contype="1" pos="0.000000 0.020000 0.000000" quat="1.000000 0.000000 0.000000 0.000000" rgba="0.225300 0.284500 0.503150 1.000000" size="0.060000 0.065000 0.139000" name="geom_biped3d0_root" type="box"/>
            <body pos="0.000000 0.080000 0.000000" quat="1.000000 0.000000 0.000000 0.000000" name="body_biped3d0_torso">
                <joint damping="0.300000" stiffness="0.500000" axis="0.000000 0.000000 1.000000" pos="0.000000 0.000000 0.000000" range="0.000000 28.647890" limited="true" name="joint_biped3d0_torso" type="ball"/>
                <geom conaffinity="0" contype="1" pos="0.000000 0.170000 0.000000" quat="1.000000 0.000000 0.000000 0.000000" rgba="0.225300 0.284500 0.503150 1.000000" size="0.065000 0.165000 0.145000" name="geom_biped3d0_torso" type="box"/>
            </body>
            <body pos="0.000000 0.000000 0.100000" quat="1.000000 0.000000 0.000000 0.000000" name="body_biped3d0_right_hip">
                <joint damping="0.300000" stiffness="0.500000" axis="0.000000 0.000000 1.000000" pos="0.000000 0.000000 0.000000" range="0.000000 68.754936" limited="true" name="joint_biped3d0_right_hip" type="ball"/>
                <geom conaffinity="0" contype="1" pos="0.000000 -0.174500 0.000000" quat="1.000000 0.000000 0.000000 0.000000" rgba="0.439600 0.537050 0.538600 1.000000" size="0.045000 0.200000 0.042500" name="geom_biped3d0_right_hip" type="box"/>
                <body pos="0.000000 -0.352000 0.000000" quat="1.000000 0.000000 0.000000 0.000000" name="body_biped3d0_right_knee">
                    <joint damping="0.300000" stiffness="0.500000" axis="0.000000 0.000000 1.000000" pos="0.000000 0.000000 0.000000" range="-179.908752 0.000000" limited="true" name="joint_biped3d0_right_knee" type="hinge"/>
                    <geom conaffinity="0" contype="1" pos="0.000000 -0.183000 0.000000" quat="1.000000 0.000000 0.000000 0.000000" rgba="0.409600 0.507050 0.508600 1.000000" size="0.035000 0.208000 0.032500" name="geom_biped3d0_right_knee" type="box"/>
                    <body pos="0.000000 -0.391000 0.000000" quat="1.000000 0.000000 0.000000 0.000000" name="body_biped3d0_right_ankle">
                        <joint damping="0.300000" stiffness="0.500000" axis="0.000000 0.000000 1.000000" pos="0.000000 0.000000 0.000000" range="0.000000 57.295780" limited="true" name="joint_biped3d0_right_ankle" type="ball"/>
                        <geom conaffinity="0" contype="1" pos="0.051800 -0.022400 0.000000" quat="1.000000 0.000000 0.000000 0.000000" rgba="0.389600 0.487050 0.488600 1.000000" size="0.088500 0.025000 0.042500" name="geom_biped3d0_right_ankle" type="box"/>
                    </body>
                </body>
            </body>
            <body pos="0.000000 0.000000 -0.100000" quat="1.000000 0.000000 0.000000 0.000000" name="body_biped3d0_left_hip">
                <joint damping="0.300000" stiffness="0.500000" axis="0.000000 0.000000 1.000000" pos="0.000000 0.000000 0.000000" range="0.000000 68.754936" limited="true" name="joint_biped3d0_left_hip" type="ball"/>
                <geom conaffinity="0" contype="1" pos="0.000000 -0.174500 0.000000" quat="1.000000 0.000000 0.000000 0.000000" rgba="0.351680 0.429640 0.440880 1.000000" size="0.045000 0.200000 0.042500" name="geom_biped3d0_left_hip" type="box"/>
                <body pos="0.000000 -0.352000 0.000000" quat="1.000000 0.000000 0.000000 0.000000" name="body_biped3d0_left_knee">
                    <joint damping="0.300000" stiffness="0.500000" axis="0.000000 0.000000 1.000000" pos="0.000000 0.000000 0.000000" range="-179.908752 0.000000" limited="true" name="joint_biped3d0_left_knee" type="hinge"/>
                    <geom conaffinity="0" contype="1" pos="0.000000 -0.183000 0.000000" quat="1.000000 0.000000 0.000000 0.000000" rgba="0.327680 0.405640 0.416880 1.000000" size="0.035000 0.208000 0.032500" name="geom_biped3d0_left_knee" type="box"/>
                    <body pos="0.000000 -0.391000 0.000000" quat="1.000000 0.000000 0.000000 0.000000" name="body_biped3d0_left_ankle">
                        <joint damping="0.300000" stiffness="0.500000" axis="0.000000 0.000000 1.000000" pos="0.000000 0.000000 0.000000" range="0.000000 57.295780" limited="true" name="joint_biped3d0_left_ankle" type="ball"/>
                        <geom conaffinity="0" contype="1" pos="0.051800 -0.022400 0.000000" quat="1.000000 0.000000 0.000000 0.000000" rgba="0.311680 0.389640 0.400880 1.000000" size="0.088500 0.025000 0.042500" name="geom_biped3d0_left_ankle" type="box"/>
                    </body>
                </body>
            </body>
        </body>
    </worldbody>
    <actuator>
        <motor ctrlrange="-1.000000 1.000000" gear="2.000000" ctrllimited="true" joint="joint_biped3d0_torso" name="actuator_biped3d0_joint_biped3d0_torso"/>
        <motor ctrlrange="-1.000000 1.000000" gear="2.000000" ctrllimited="true" joint="joint_biped3d0_right_hip" name="actuator_biped3d0_joint_biped3d0_right_hip"/>
        <motor ctrlrange="-1.000000 1.000000" gear="2.000000" ctrllimited="true" joint="joint_biped3d0_right_knee" name="actuator_biped3d0_joint_biped3d0_right_knee"/>
        <motor ctrlrange="-1.000000 1.000000" gear="2.000000" ctrllimited="true" joint="joint_biped3d0_right_ankle" name="actuator_biped3d0_joint_biped3d0_right_ankle"/>
        <motor ctrlrange="-1.000000 1.000000" gear="2.000000" ctrllimited="true" joint="joint_biped3d0_left_hip" name="actuator_biped3d0_joint_biped3d0_left_hip"/>
        <motor ctrlrange="-1.000000 1.000000" gear="2.000000" ctrllimited="true" joint="joint_biped3d0_left_knee" name="actuator_biped3d0_joint_biped3d0_left_knee"/>
        <motor ctrlrange="-1.000000 1.000000" gear="2.000000" ctrllimited="true" joint="joint_biped3d0_left_ankle" name="actuator_biped3d0_joint_biped3d0_left_ankle"/>
    </actuator>
    <sensor>
        <jointpos joint="joint_biped3d0_right_knee" name="sensor_biped3d0_joint_biped3d0_right_knee_jointpos"/>
        <jointvel joint="joint_biped3d0_right_knee" name="sensor_biped3d0_joint_biped3d0_right_knee_jointvel"/>
        <jointpos joint="joint_biped3d0_left_knee" name="sensor_biped3d0_joint_biped3d0_left_knee_jointpos"/>
        <jointvel joint="joint_biped3d0_left_knee" name="sensor_biped3d0_joint_biped3d0_left_knee_jointvel"/>
        <framelinvel name="sensorbiped3d0_body_biped3d0_root_framelinvel" objname="body_biped3d0_root" objtype="body"/>
        <framelinacc name="sensorbiped3d0_body_biped3d0_root_framelinacc" objname="body_biped3d0_root" objtype="body"/>
        <framelinvel name="sensorbiped3d0_body_biped3d0_torso_framelinvel" objname="body_biped3d0_torso" objtype="body"/>
        <framelinacc name="sensorbiped3d0_body_biped3d0_torso_framelinacc" objname="body_biped3d0_torso" objtype="body"/>
        <framelinvel name="sensorbiped3d0_body_biped3d0_right_hip_framelinvel" objname="body_biped3d0_right_hip" objtype="body"/>
        <framelinacc name="sensorbiped3d0_body_biped3d0_right_hip_framelinacc" objname="body_biped3d0_right_hip" objtype="body"/>
        <framelinvel name="sensorbiped3d0_body_biped3d0_right_knee_framelinvel" objname="body_biped3d0_right_knee" objtype="body"/>
        <framelinacc name="sensorbiped3d0_body_biped3d0_right_knee_framelinacc" objname="body_biped3d0_right_knee" objtype="body"/>
        <framelinvel name="sensorbiped3d0_body_biped3d0_right_ankle_framelinvel" objname="body_biped3d0_right_ankle" objtype="body"/>
        <framelinacc name="sensorbiped3d0_body_biped3d0_right_ankle_framelinacc" objname="body_biped3d0_right_ankle" objtype="body"/>
        <framelinvel name="sensorbiped3d0_body_biped3d0_left_hip_framelinvel" objname="body_biped3d0_left_hip" objtype="body"/>
        <framelinacc name="sensorbiped3d0_body_biped3d0_left_hip_framelinacc" objname="body_biped3d0_left_hip" objtype="body"/>
        <framelinvel name="sensorbiped3d0_body_biped3d0_left_knee_framelinvel" objname="body_biped3d0_left_knee" objtype="body"/>
        <framelinacc name="sensorbiped3d0_body_biped3d0_left_knee_framelinacc" objname="body_biped3d0_left_knee" objtype="body"/>
        <framelinvel name="sensorbiped3d0_body_biped3d0_left_ankle_framelinvel" objname="body_biped3d0_left_ankle" objtype="body"/>
        <framelinacc name="sensorbiped3d0_body_biped3d0_left_ankle_framelinacc" objname="body_biped3d0_left_ankle" objtype="body"/>
    </sensor>
</mujoco>
