<mujoco model="physics">
    <compiler angle="radian" />
    <size njmax="500" nconmax="100" />
    <asset>
        <mesh name="l_finger" file="l_finger.stl" />
        <mesh name="l_finger_tip" file="l_finger_tip.stl" />
    </asset>
    <worldbody>
        <geom size="0.17 0.3" type="cylinder" rgba="0 0 0.8 1" />
        <geom size="0.3 0.1 0.05" pos="0.22 0 -0.05" quat="0.707123 0 0.70709 0" type="box" rgba="1 1 1 1" />
        <geom size="0.05 0.2 0.05" pos="0.22 0 -0.35" type="box" rgba="1 1 1 1" />
        <geom size="0.3 0.1 0.05" pos="-0.22 0 -0.05" quat="0.707123 0 0.70709 0" type="box" rgba="1 1 1 1" />
        <geom size="0.05 0.2 0.05" pos="-0.22 0 -0.35" type="box" rgba="1 1 1 1" />
        <body name="right_front_wheel" pos="0.22 0.133333 -0.435" quat="0.707123 0 0.70709 0">
            <inertial pos="0 0 0" mass="1" diaginertia="1 1 1" />
            <joint name="right_front_wheel_joint" pos="0 0 0" axis="0 0 1" />
            <geom size="0.035 0.05" type="cylinder" />
        </body>
        <body name="right_back_wheel" pos="0.22 -0.133333 -0.435" quat="0.707123 0 0.70709 0">
            <inertial pos="0 0 0" mass="1" diaginertia="1 1 1" />
            <joint name="right_back_wheel_joint" pos="0 0 0" axis="0 0 1" />
            <geom size="0.035 0.05" type="cylinder" />
        </body>
        <body name="left_front_wheel" pos="-0.22 0.133333 -0.435" quat="0.707123 0 0.70709 0">
            <inertial pos="0 0 0" mass="1" diaginertia="1 1 1" />
            <joint name="left_front_wheel_joint" pos="0 0 0" axis="0 0 1" />
            <geom size="0.035 0.05" type="cylinder" />
        </body>
        <body name="left_back_wheel" pos="-0.22 -0.133333 -0.435" quat="0.707123 0 0.70709 0">
            <inertial pos="0 0 0" mass="1" diaginertia="1 1 1" />
            <joint name="left_back_wheel_joint" pos="0 0 0" axis="0 0 1" />
            <geom size="0.035 0.05" type="cylinder" />
        </body>
        <body name="gripper_pole" pos="0 0.19 0.2" quat="0.707123 0 0 0.70709">
            <inertial pos="0 0 0" mass="0.05" diaginertia="1 1 1" />
            <joint name="gripper_extension" pos="0 0 0" axis="1 0 0" type="slide" limited="true" range="-0.38 0" />
            <geom size="0.01 0.1" pos="0.1 0 0" quat="0.707123 0 0.70709 0" type="cylinder" rgba="0.7 0.7 0.7 1" />
            <body name="left_gripper" pos="0.2 0.02 0">
                <inertial pos="0 0 0" mass="0.1" diaginertia="2 2 2" />
                <joint name="left_gripper_joint" pos="0 0 0" axis="0 0 1" limited="true" range="0 0.548" />
                <geom type="mesh" mesh="l_finger" />
                <geom pos="0.09137 0.00495 0" type="mesh" mesh="l_finger_tip" />
            </body>
            <body name="right_gripper" pos="0.2 -0.02 0">
                <inertial pos="0 0 0" mass="0.1" diaginertia="2 2 2" />
                <joint name="right_gripper_joint" pos="0 0 0" axis="0 0 -1" limited="true" range="0 0.548" />
                <geom quat="4.63268e-05 -1 0 0" type="mesh" mesh="l_finger" />
                <geom pos="0.09137 0.00495 0" quat="4.63268e-05 -1 0 0" type="mesh" mesh="l_finger_tip" />
            </body>
        </body>
        <body name="head" pos="0 0 0.3">
            <inertial pos="0 0.0110364 0.0110364" quat="0.653281 -0.270598 0.270598 0.653281" mass="11" diaginertia="2.0268 2.0268 2" />
            <joint name="head_swivel" pos="0 0 0" axis="0 0 1" limited="true" range="-0.38 0" />
            <geom size="0.16" rgba="1 1 1 1" />
            <geom size="0.04 0.04 0.04" pos="0 0.1214 0.1214" type="box" rgba="0 0 0.8 1" />
        </body>
    </worldbody>


    <worldbody>
        <body pos="2.000000 0.000000 2.500000" quat="1.000000 0.000000 0.000000 0.000000" name="body_r2d20_base_link">
            <geom pos="0.000000 0.000000 0.000000" quat="1.000000 0.000000 0.000000 0.000000" size="0.200000 0.300000 0.000000" name="geom_r2d20_0" type="cylinder"/>
            <inertial mass="10.000000" diaginertia="1.010000 1.010000 1.010000" pos="0.000000 0.000000 0.000000" quat="1.000000 0.000000 0.000000 0.000000"/>
            <body pos="-0.220000 0.000000 0.250000" quat="1.000000 0.000000 0.000000 0.000000" name="body_r2d20_left_leg">
                <geom pos="0.000000 0.000000 -0.300000" quat="0.707123 0.000000 0.707090 0.000000" rgba="1.000000 1.000000 1.000000 1.000000" size="0.300000 0.100000 0.050000" name="geom_r2d20_8" type="box"/>
                <inertial mass="10.000000" diaginertia="1.010000 1.010000 1.010000" pos="0.000000 0.000000 -0.300000" quat="0.707123 0.000000 0.707090 0.000000"/>
                <body pos="0.000000 0.000000 -0.600000" quat="1.000000 0.000000 0.000000 0.000000" name="body_r2d20_left_base">
                    <geom pos="0.000000 0.000000 0.000000" quat="1.000000 0.000000 0.000000 0.000000" rgba="1.000000 1.000000 1.000000 1.000000" size="0.050000 0.200000 0.050000" name="geom_r2d20_5" type="box"/>
                    <inertial mass="10.000000" diaginertia="1.010000 1.010000 1.010000" pos="0.000000 0.000000 0.000000" quat="1.000000 0.000000 0.000000 0.000000"/>
                    <body pos="0.000000 -0.133333 -0.085000" quat="0.707123 0.000000 0.707090 0.000000" name="body_r2d20_left_back_wheel">
                        <joint axis="0.000000 0.000000 1.000000" pos="0.000000 -0.133333 -0.085000" limited="false" name="joint_r2d20_left_back_wheel_joint" type="hinge"/>
                        <geom pos="0.000000 0.000000 0.000000" quat="1.000000 0.000000 0.000000 0.000000" rgba="0.500000 0.500000 0.500000 1.000000" size="0.035000 0.050000 0.000000" name="geom_r2d20_4" type="cylinder"/>
                        <inertial mass="1.000000" diaginertia="1.010000 1.010000 1.010000" pos="0.000000 0.000000 0.000000" quat="1.000000 0.000000 0.000000 0.000000"/>
                    </body>
                    <body pos="0.000000 0.133333 -0.085000" quat="0.707123 0.000000 0.707090 0.000000" name="body_r2d20_left_front_wheel">
                        <joint axis="0.000000 0.000000 1.000000" pos="0.000000 0.133333 -0.085000" limited="false" name="joint_r2d20_left_front_wheel_joint" type="hinge"/>
                        <geom pos="0.000000 0.000000 0.000000" quat="1.000000 0.000000 0.000000 0.000000" rgba="0.500000 0.500000 0.500000 1.000000" size="0.035000 0.050000 0.000000" name="geom_r2d20_6" type="cylinder"/>
                        <inertial mass="1.000000" diaginertia="1.010000 1.010000 1.010000" pos="0.000000 0.000000 0.000000" quat="1.000000 0.000000 0.000000 0.000000"/>
                    </body>
                </body>
            </body>
            <body pos="0.220000 0.000000 0.250000" quat="1.000000 0.000000 0.000000 0.000000" name="body_r2d20_right_leg">
                <geom pos="0.000000 0.000000 -0.300000" quat="0.707123 0.000000 0.707090 0.000000" rgba="1.000000 1.000000 1.000000 1.000000" size="0.300000 0.100000 0.050000" name="geom_r2d20_14" type="box"/>
                <inertial mass="10.000000" diaginertia="1.010000 1.010000 1.010000" pos="0.000000 0.000000 -0.300000" quat="0.707123 0.000000 0.707090 0.000000"/>
                <body pos="0.000000 0.000000 -0.600000" quat="1.000000 0.000000 0.000000 0.000000" name="body_r2d20_right_base">
                    <geom pos="0.000000 0.000000 0.000000" quat="1.000000 0.000000 0.000000 0.000000" rgba="1.000000 1.000000 1.000000 1.000000" size="0.050000 0.200000 0.050000" name="geom_r2d20_11" type="box"/>
                    <inertial mass="10.000000" diaginertia="1.010000 1.010000 1.010000" pos="0.000000 0.000000 0.000000" quat="1.000000 0.000000 0.000000 0.000000"/>
                    <body pos="0.000000 -0.133333 -0.085000" quat="0.707123 0.000000 0.707090 0.000000" name="body_r2d20_right_back_wheel">
                        <joint axis="0.000000 0.000000 1.000000" pos="0.000000 -0.133333 -0.085000" limited="false" name="joint_r2d20_right_back_wheel_joint" type="hinge"/>
                        <geom pos="0.000000 0.000000 0.000000" quat="1.000000 0.000000 0.000000 0.000000" rgba="0.500000 0.500000 0.500000 1.000000" size="0.035000 0.050000 0.000000" name="geom_r2d20_10" type="cylinder"/>
                        <inertial mass="1.000000" diaginertia="1.010000 1.010000 1.010000" pos="0.000000 0.000000 0.000000" quat="1.000000 0.000000 0.000000 0.000000"/>
                    </body>
                    <body pos="0.000000 0.133333 -0.085000" quat="0.707123 0.000000 0.707090 0.000000" name="body_r2d20_right_front_wheel">
                        <joint axis="0.000000 0.000000 1.000000" pos="0.000000 0.133333 -0.085000" limited="false" name="joint_r2d20_right_front_wheel_joint" type="hinge"/>
                        <geom pos="0.000000 0.000000 0.000000" quat="1.000000 0.000000 0.000000 0.000000" rgba="0.500000 0.500000 0.500000 1.000000" size="0.035000 0.050000 0.000000" name="geom_r2d20_12" type="cylinder"/>
                        <inertial mass="1.000000" diaginertia="1.010000 1.010000 1.010000" pos="0.000000 0.000000 0.000000" quat="1.000000 0.000000 0.000000 0.000000"/>
                    </body>
                </body>
            </body>
            <body pos="0.000000 0.190000 0.200000" quat="0.707123 0.000000 0.000000 0.707090" name="body_r2d20_gripper_pole">
                <joint axis="1.000000 0.000000 0.000000" pos="0.000000 0.190000 0.200000" range="-0.380000 0.000000" limited="true" name="joint_r2d20_gripper_extension" type="slide"/>
                <geom pos="0.100000 0.000000 0.000000" quat="0.707123 0.000000 0.707090 0.000000" rgba="0.700000 0.700000 0.700000 1.000000" size="0.010000 0.100000 0.000000" name="geom_r2d20_2" type="cylinder"/>
                <inertial mass="0.050000" diaginertia="1.010000 1.010000 1.010000" pos="0.000000 0.000000 0.000000" quat="1.000000 0.000000 0.000000 0.000000"/>
                <body pos="0.200000 0.020000 0.000000" quat="1.000000 0.000000 0.000000 0.000000" name="body_r2d20_left_gripper">
                    <joint axis="0.000000 0.000000 1.000000" pos="0.200000 0.020000 0.000000" range="0.000000 0.548000" limited="true" name="joint_r2d20_left_gripper_joint" type="hinge"/>
                    <geom pos="0.000000 0.000000 0.000000" quat="1.000000 0.000000 0.000000 0.000000" rgba="0.800000 0.800000 0.800000 1.000000" size="0.000000 0.000000 0.000000" mesh="r2d2_meshes/l_finger" name="geom_r2d20_7" type="mesh"/>
                    <inertial mass="0.050000" diaginertia="1.010000 1.010000 1.010000" pos="0.000000 0.000000 0.000000" quat="1.000000 0.000000 0.000000 0.000000"/>
                    <body pos="0.000000 0.000000 0.000000" quat="1.000000 0.000000 0.000000 0.000000" name="body_r2d20_left_tip">
                        <geom pos="0.091370 0.004950 0.000000" quat="1.000000 0.000000 0.000000 0.000000" rgba="0.800000 0.800000 0.800000 1.000000" size="0.000000 0.000000 0.000000" mesh="r2d2_meshes/l_finger_tip" name="geom_r2d20_9" type="mesh"/>
                        <inertial mass="0.050000" diaginertia="1.010000 1.010000 1.010000" pos="0.000000 0.000000 0.000000" quat="1.000000 0.000000 0.000000 0.000000"/>
                    </body>
                </body>
                <body pos="0.200000 -0.020000 0.000000" quat="1.000000 0.000000 0.000000 0.000000" name="body_r2d20_right_gripper">
                    <joint axis="0.000000 0.000000 -1.000000" pos="0.200000 -0.020000 0.000000" range="0.000000 0.548000" limited="true" name="joint_r2d20_right_gripper_joint" type="hinge"/>
                    <geom pos="0.000000 0.000000 0.000000" quat="-0.000046 1.000000 0.000000 -0.000000" rgba="0.800000 0.800000 0.800000 1.000000" size="0.000000 0.000000 0.000000" mesh="r2d2_meshes/l_finger" name="geom_r2d20_13" type="mesh"/>
                    <inertial mass="0.050000" diaginertia="1.010000 1.010000 1.010000" pos="0.000000 0.000000 0.000000" quat="1.000000 0.000000 0.000000 0.000000"/>
                    <body pos="0.000000 0.000000 0.000000" quat="1.000000 0.000000 0.000000 0.000000" name="body_r2d20_right_tip">
                        <geom pos="0.091370 0.004950 0.000000" quat="-0.000046 1.000000 0.000000 -0.000000" rgba="0.800000 0.800000 0.800000 1.000000" size="0.000000 0.000000 0.000000" mesh="r2d2_meshes/l_finger_tip" name="geom_r2d20_15" type="mesh"/>
                        <inertial mass="0.050000" diaginertia="1.010000 1.010000 1.010000" pos="0.000000 0.000000 0.000000" quat="1.000000 0.000000 0.000000 0.000000"/>
                    </body>
                </body>
            </body>
            <body pos="0.000000 0.000000 0.300000" quat="1.000000 0.000000 0.000000 0.000000" name="body_r2d20_head">
                <joint axis="0.000000 0.000000 1.000000" pos="0.000000 0.000000 0.300000" range="-0.380000 0.000000" limited="true" name="joint_r2d20_head_swivel" type="hinge"/>
                <geom pos="0.000000 0.000000 0.000000" quat="1.000000 0.000000 0.000000 0.000000" rgba="1.000000 1.000000 1.000000 1.000000" size="0.160000 0.000000 0.000000" name="geom_r2d20_3" type="sphere"/>
                <inertial mass="10.000000" diaginertia="1.010000 1.010000 1.010000" pos="0.000000 0.000000 0.000000" quat="1.000000 0.000000 0.000000 0.000000"/>
                <body pos="0.000000 0.121400 0.121400" quat="1.000000 0.000000 0.000000 0.000000" name="body_r2d20_box">
                    <geom pos="0.000000 0.000000 0.000000" quat="1.000000 0.000000 0.000000 0.000000" size="0.040000 0.040000 0.040000" name="geom_r2d20_1" type="box"/>
                    <inertial mass="1.000000" diaginertia="1.010000 1.010000 1.010000" pos="0.000000 0.000000 0.000000" quat="1.000000 0.000000 0.000000 0.000000"/>
                </body>
            </body>
        </body>
    </worldbody>
</mujoco>
