<mujoco model="baxter">

  <asset>
    <mesh name="baxter_base_link"                 file="baxter_meshes/torso/base_link.STL" />
    <mesh name="baxter_link_collision"            file="baxter_meshes/torso/base_link_collision.STL" />
    <mesh name="baxter_pedestal"                  file="baxter_meshes/base/PEDESTAL.STL" />
    <mesh name="baxter_pedestal_link_collision"   file="baxter_meshes/base/pedestal_link_collision.STL" />
    <mesh name="baxter_h0"                        file="baxter_meshes/head/H0.STL" />
    <mesh name="baxter_h1"                        file="baxter_meshes/head/H1.STL" />
    <mesh name="baxter_s0"                        file="baxter_meshes/upper_shoulder/S0.STL" />
    <mesh name="baxter_s1"                        file="baxter_meshes/lower_shoulder/S1.STL" />
    <mesh name="baxter_e0"                        file="baxter_meshes/upper_elbow/E0.STL" />
    <mesh name="baxter_e1"                        file="baxter_meshes/lower_elbow/E1.STL" />
    <mesh name="baxter_w0"                        file="baxter_meshes/upper_forearm/W0.STL" />
    <mesh name="baxter_w1"                        file="baxter_meshes/lower_forearm/W1.STL" />
    <mesh name="baxter_w2"                        file="baxter_meshes/wrist/W2.STL" />
    <mesh name="baxter_paddle_tip"                file="baxter_meshes/electric_gripper/fingers/paddle_tip.STL" />
  </asset>

  <contact>
    <exclude body1="right_upper_shoulder"   body2="torso" />
    <exclude body1="right_upper_shoulder"   body2="right_upper_elbow" />
    <exclude body1="right_lower_shoulder"   body2="torso" />
    <exclude body1="left_upper_shoulder"    body2="torso" />
    <exclude body1="left_upper_shoulder"    body2="left_upper_elbow" />
    <exclude body1="left_lower_shoulder"    body2="torso" />
    <!--<exclude body1="collision_head_link_1"  body2="torso" />-->
    <!--<exclude body1="collision_head_link_2"  body2="torso" />-->
  </contact>

  <worldbody>
    <body name="tmjcroot" pos="0 0 0">
      <joint name="root" type="free" />
      <inertial pos="0 0 0" mass="10" diaginertia="0.001 0.001 0.001" />
      <body name="torso" pos="0 0 0">
        <inertial pos="0 0 0" quat="0.997433 0.00167178 0.0715546 -0.00209003" mass="35.3365" diaginertia="1.87139 1.66268 0.779991" />
        <geom name="torso_1" margin="0.001" contype="0" conaffinity="0" group="1" type="mesh" mesh="baxter_base_link" rgba="0.37 0.37 0.37 1" />
        <geom name="torso_2" margin="0.001" type="mesh" mesh="baxter_link_collision" contype="0" conaffinity="0" group="1" rgba="0.37 0.37 0.37 1" />
        <body name="pedestal" pos="0 0 0">
          <inertial pos="0 0 0" quat="0.659267 -0.259505 -0.260945 0.655692" mass="60.864" diaginertia="6.0869 5.81635 4.20915" />
          <geom name="pedestal_1" margin="0.001" contype="0" conaffinity="0" group="1" type="mesh" rgba="0.2 0.2 0.2 1" mesh="baxter_pedestal" />
          <geom name="pedestal_2" margin="0.001" pos="-.04 0 -.8" rgba="0.2 0.2 0.2 1" type="box" size=".46 .425 .16" />
          <geom name="pedestal_3" margin="0.001" pos="0 0 -.35" rgba="0.2 0.2 0.2 1" type="capsule" size=".165 .25" />
        </body>
        <body name="head" pos="0.06 0 0.686">
          <inertial pos="0 0 0" quat="0.339345 0.850736 -0.347392 0.201027" mass="0.547767" diaginertia="0.00474065 0.00461087 0.00199949" />
          <joint limited="true" damping="0" armature=".01" name="head_pan" type="hinge" pos="0 0 0" axis="0 0 1" range="-90 90" />
          <geom name="head" margin="0.001" contype="0" conaffinity="0" group="1" type="mesh" rgba="0.2 0.2 0.2 1" mesh="baxter_h0" />
          <body name="screen" pos="0.1227 0 0" quat="0.453099 0.542864 0.542864 0.453099">
            <inertial pos="0 0 0" quat="0.995785 0.0113501 -0.000390852 0.0910132" mass="0.440171" diaginertia="0.0040484 0.00275826 0.00150834" />
            <geom margin="0.001" contype="0" conaffinity="0" group="1" name="display_1" type="mesh" mesh="baxter_h1" rgba="0.5 0.1 0.1 1" pos="0 0 -.03" euler="0 -90 0" />
            <geom margin="0.001" contype="0" conaffinity="0" group="1" name="display_2" type="box" size="0.109 0.08 0.002" rgba=".9 .9 .9 1" pos="0 -0.016 0" quat="0.991445 0.130526 0 0" />
          </body>
        </body>
        <body name="right_arm_mount" pos="0.024645 -0.219645 0.118588" quat="0.923879 0 0 -0.382684">
          <inertial pos="0 0 0" mass="0.0001" diaginertia="1e-008 1e-008 1e-008" />
          <body name="right_upper_shoulder" pos="0.055695 0 0.011038">
            <inertial pos="0.01783 0.00086 0.19127" quat="0.975667 0.0673303 -0.206117 0.0325173" mass="5.70044" diaginertia="0.0498344 0.0377511 0.0331351" />
            <joint limited="true" damping="0" armature=".01" name="right_s0" type="hinge" pos="0 0 0" axis="0 0 1" range="-97.5 97.5" />
            <geom name="upper_shoulder_1" margin="0.001" contype="0" conaffinity="0" group="1" type="mesh" rgba="0.5 0.1 0.1 1" mesh="baxter_s0" />
            <geom name="upper_shoulder_2" margin="0.001" type="cylinder" size="0.06 0.1361" rgba="0.5 0.1 0.1 1" pos="0 0 0.1361"/>
            <body name="right_lower_shoulder" pos="0.069 0 0.27035" quat="0.707107 -0.707107 0 0">
              <inertial pos="0.06845 0.00269 -0.00529" quat="0.447487 0.536948 0.56425 0.439391" mass="3.22698" diaginertia="0.0278991 0.0212327 0.0112937" />
              <joint limited="true" damping="0" armature=".01" name="right_s1" type="hinge" pos="0 0 0" axis="0 0 1" range="-123 60" />
              <geom name="right_lower_shoulder_1" margin="0.001" contype="0" conaffinity="0" group="1" type="mesh" rgba="0.5 0.1 0.1 1" mesh="baxter_s1" />
              <geom name="right_lower_shoulder_2" margin="0.001" type="cylinder" size="0.06 0.06" rgba="0.5 0.1 0.1 1" pos="0 0 0" />
              <body name="right_upper_elbow" pos="0.102 0 0" quat="0.5 0.5 0.5 0.5">
                <inertial pos="-0.00276 0.00132 0.18086" quat="0.838995 -0.0423128 -0.121287 0.52876" mass="4.31272" diaginertia="0.0287695 0.0273625 0.011409" />
                <joint limited="true" damping="0" armature=".01" name="right_e0" type="hinge" pos="0 0 0" axis="0 0 1" range="-175 175" />
                <geom name="right_upper_elbow_1" margin="0.001" contype="0" conaffinity="0" group="1" type="mesh" rgba="0.5 0.1 0.1 1" mesh="baxter_e0" />
                <geom name="right_upper_elbow_2" margin="0.001" type="cylinder" size="0.06 0.0535" rgba="0.5 0.1 0.1 1" pos="0 0 -0.0535"/>
                <geom name="right_upper_elbow_3" margin="0.001" type="cylinder" size="0.06 0.1365" pos="0 0 0.1365" contype="0" conaffinity="0" group="1" rgba="0.37 0.37 0.37 1" />
                <body name="right_lower_elbow" pos="0.069 0 0.26242" quat="0.5 -0.5 -0.5 -0.5">
                  <inertial pos="0.02611 0.00159 -0.01117" quat="0.440433 0.577149 0.562777 0.395221" mass="2.07206" diaginertia="0.0132096 0.00950002 0.00685697" />
                  <joint limited="true" damping="0" armature=".01" name="right_e1" type="hinge" pos="0 0 0" axis="0 0 1" range="-2.865 150" />
                  <geom name="right_lower_elbow_1" margin="0.001" contype="0" conaffinity="0" group="1" type="mesh" rgba="0.5 0.1 0.1 1" mesh="baxter_e1" />
                  <geom name="right_lower_elbow_2" margin="0.001" type="cylinder" size="0.06 0.05" rgba="0.5 0.1 0.1 1" pos="0 0 0" />
                  <body name="right_upper_forearm" pos="0.10359 0 0" quat="0.5 0.5 0.5 0.5">
                    <inertial pos="-0.00168 0.0046 0.13952" quat="0.892709 -0.0256256 0.00446984 0.449882" mass="2.24665" diaginertia="0.016916 0.0165511 0.00371123" />
                    <joint limited="true" damping="0" armature=".01" name="right_w0" type="hinge" pos="0 0 0" axis="0 0 1" range="-175.27 175.27" />
                    <geom name="right_upper_forearm_1" margin="0.001" contype="0" conaffinity="0" group="1" type="mesh" rgba="0.5 0.1 0.1 1" mesh="baxter_w0" />
                    <geom name="right_upper_forearm_2" margin="0.001" type="cylinder" size="0.06 0.044" rgba="0.5 0.1 0.1 1" pos="0 0 -0.044" />
                    <geom name="right_upper_forearm_3" margin="0.001" type="cylinder" size="0.06 0.1036" pos="0 0 0.1" contype="0" conaffinity="0" group="1" rgba="0.37 0.37 0.37 1" />
                    <body name="right_lower_forearm" pos="0.01 0 0.2707" quat="0.5 -0.5 -0.5 -0.5">
                      <inertial pos="0.06041 0.00697 0.006" quat="0.456911 0.468526 0.475683 0.587743" mass="1.60979" diaginertia="0.00708828 0.00552689 0.00379383" />
                      <joint limited="true" damping="0" armature=".01" name="right_w1" type="hinge" pos="0 0 0" axis="0 0 1" range="-90 120" />
                      <geom name="right_lower_forearm_1" margin="0.001" contype="0" conaffinity="0" group="1" type="mesh" rgba="0.5 0.1 0.1 1" mesh="baxter_w1" />
                      <geom name="right_lower_forearm_2" margin="0.001" type="cylinder" size="0.06 0.05" rgba="0.5 0.1 0.1 1" pos="0 0 0" />
                      <body name="right_wrist" pos="0.115975 0 0" quat="0.5 0.5 0.5 0.5">
                        <inertial pos="0.00198 0.00125 0.01855" quat="0.0594843 0.68926 -0.16016 0.704082" mass="0.35093" diaginertia="0.0003082 0.000269928 0.000251035" />
                        <joint limited="true" damping="0" armature=".01" name="right_w2" type="hinge" pos="0 0 0" axis="0 0 1" range="-175.27 175.27" />
                        <geom name="right_wrist_1" margin="0.001" contype="0" conaffinity="0" group="1" type="mesh" rgba="0.1 0.1 0.1 1" mesh="baxter_w2" />
                        <geom name="right_wrist_2" margin="0.001" type="cylinder" size="0.06 0.0825" rgba="0.1 0.1 0.1 1" pos="0 0 0" />
                        <body name="right_hand" pos="0 0 0.11355">
                <!-- right gripper gets added here -->
                        </body>
                      </body>
                    </body>
                  </body>
                </body>
              </body>
            </body>
          </body>
        </body>
        <body name="left_arm_mount" pos="0.024645 0.219645 0.118588" quat="0.923879 0 0 0.382684">
          <inertial pos="0 0 0" mass="0.0001" diaginertia="1e-008 1e-008 1e-008" />
          <body name="left_upper_shoulder" pos="0.055695 0 0.011038">
            <inertial pos="0.01783 0.00086 0.19127" quat="0.975667 0.0673303 -0.206117 0.0325173" mass="5.70044" diaginertia="0.0498344 0.0377511 0.0331351" />
            <joint limited="true" damping="0" armature=".01" name="left_s0" type="hinge" pos="0 0 0" axis="0 0 1" range="-97.5 97.5" />
            <geom name="left_upper_shoulder_1" margin="0.001" contype="0" conaffinity="0" group="1" type="mesh" rgba="0.5 0.1 0.1 1" mesh="baxter_s0" />
            <geom name="left_upper_shoulder_2" margin="0.001" type="cylinder" size="0.06 0.1361" rgba="0.5 0.1 0.1 1" pos="0 0 0.1361" />
            <body name="left_lower_shoulder" pos="0.069 0 0.27035" quat="0.707107 -0.707107 0 0">
              <inertial pos="0.06845 0.00269 -0.00529" quat="0.447487 0.536948 0.56425 0.439391" mass="3.22698" diaginertia="0.0278991 0.0212327 0.0112937" />
              <joint limited="true" damping="0" armature=".01" name="left_s1" type="hinge" pos="0 0 0" axis="0 0 1" range="-123.014 60" />
              <geom name="left_lower_shoulder_1" margin="0.001" contype="0" conaffinity="0" group="1" type="mesh" rgba="0.5 0.1 0.1 1" mesh="baxter_s1" />
              <geom name="left_lower_shoulder_2" margin="0.001" type="cylinder" size="0.06 0.06" rgba="0.5 0.1 0.1 1" pos="0 0 0" />
              <body name="left_upper_elbow" pos="0.102 0 0" quat="0.5 0.5 0.5 0.5">
                <inertial pos="-0.00276 0.00132 0.18086" quat="0.838995 -0.0423128 -0.121287 0.52876" mass="4.31272" diaginertia="0.0287695 0.0273625 0.011409" />
                <joint limited="true" damping="0" armature=".01" name="left_e0" type="hinge" pos="0 0 0" axis="0 0 1" range="-175 175" />
                <geom name="left_upper_elbow_1" margin="0.001" contype="0" conaffinity="0" group="1" type="mesh" rgba="0.5 0.1 0.1 1" mesh="baxter_e0" />
                <geom name="left_upper_elbow_2" margin="0.001" type="cylinder" size="0.06 0.0535" rgba="0.5 0.1 0.1 1" pos="0 0 -0.0535" />
                <geom name="left_upper_elbow_3" margin="0.001" type="cylinder" size="0.06 0.1365" pos="0 0 0.1365" contype="0" conaffinity="0" group="1" rgba="0.37 0.37 0.37 1" />
                <body name="left_lower_elbow" pos="0.069 0 0.26242" quat="0.5 -0.5 -0.5 -0.5">
                  <inertial pos="0.02611 0.00159 -0.01117" quat="0.440433 0.577149 0.562777 0.395221" mass="2.07206" diaginertia="0.0132096 0.00950002 0.00685697" />
                  <joint limited="true" damping="0" armature=".01" name="left_e1" type="hinge" pos="0 0 0" axis="0 0 1" range="-2.8647 150" />
                  <geom name="left_lower_elbow_1" margin="0.001" contype="0" conaffinity="0" group="1" type="mesh" rgba="0.5 0.1 0.1 1" mesh="baxter_e1" />
                  <geom name="left_lower_elbow_2" margin="0.001" type="cylinder" size="0.06 0.05" rgba="0.5 0.1 0.1 1" pos="0 0 0" />
                  <body name="left_upper_forearm" pos="0.10359 0 0" quat="0.5 0.5 0.5 0.5">
                    <inertial pos="-0.00168 0.0046 0.13952" quat="0.892709 -0.0256256 0.00446984 0.449882" mass="2.24665" diaginertia="0.016916 0.0165511 0.00371123" />
                    <joint limited="true" damping="0" armature=".01" name="left_w0" type="hinge" pos="0 0 0" axis="0 0 1" range="-175.26 175.26" />
                    <geom name="left_upper_forearm_1" margin="0.001" contype="0" conaffinity="0" group="1" type="mesh" rgba="0.5 0.1 0.1 1" mesh="baxter_w0" />
                    <geom name="left_upper_forearm_2" margin="0.001" type="cylinder" size="0.06 0.044" rgba="0.5 0.1 0.1 1" pos="0 0 -0.044" />
                    <geom name="left_upper_forearm_3" margin="0.001" type="cylinder" size="0.06 0.136" pos="0 0 0.136" contype="0" conaffinity="0" group="1" rgba="0.37 0.37 0.37 1" />
                    <body name="left_lower_forearm" pos="0.01 0 0.2707" quat="0.5 -0.5 -0.5 -0.5">
                      <inertial pos="0.06041 0.00697 0.006" quat="0.456911 0.468526 0.475683 0.587743" mass="1.60979" diaginertia="0.00708828 0.00552689 0.00379383" />
                      <joint limited="true" damping="0" armature=".01" name="left_w1" type="hinge" pos="0 0 0" axis="0 0 1" range="-90 120" />
                      <geom name="left_lower_forearm_1" margin="0.001" contype="0" conaffinity="0" group="1" type="mesh" rgba="0.5 0.1 0.1 1" mesh="baxter_w1" />
                      <geom name="left_lower_forearm_2" margin="0.001" type="cylinder" size="0.06 0.05" rgba="0.5 0.1 0.1 1" pos="0 0 0" />
                      <body name="left_wrist" pos="0.115975 0 0" quat="0.5 0.5 0.5 0.5">
                        <inertial pos="0.00198 0.00125 0.01855" quat="0.0594843 0.68926 -0.16016 0.704082" mass="0.35093" diaginertia="0.0003082 0.000269928 0.000251035" />
                        <joint limited="true" damping="0" armature=".01" name="left_w2" type="hinge" pos="0 0 0" axis="0 0 1" range="-175.26 175.26" />
                        <geom name="left_wrist_1" margin="0.001" contype="0" conaffinity="0" group="1" type="mesh" rgba="0.1 0.1 0.1 1" mesh="baxter_w2" />
                        <geom name="left_wrist_2" margin="0.001" type="cylinder" size="0.06 0.0825" rgba="0.1 0.1 0.1 1" pos="0 0 0" />
                        <body name="left_hand" pos="0 0 0.11355">
                    <!-- left gripper gets added here --> 
                        </body>
                      </body>
                    </body>
                  </body>
                </body>
              </body>
            </body>
          </body>
        </body>
      </body>
    </body>
  </worldbody>
  <actuator>
    <velocity name="right_s0" joint="right_s0" ctrlrange="-2 2" ctrllimited="true" kv="60"/>
    <velocity name="right_s1" joint="right_s1" ctrlrange="-2 2" ctrllimited="true" kv="50"/>
    <velocity name="right_e0" joint="right_e0" ctrlrange="-2 2" ctrllimited="true" kv="20"/>
    <velocity name="right_e1" joint="right_e1" ctrlrange="-2 2" ctrllimited="true" kv="20"/>
    <velocity name="right_w0" joint="right_w0" ctrlrange="-4 4" ctrllimited="true" kv="5" />
    <velocity name="right_w1" joint="right_w1" ctrlrange="-4 4" ctrllimited="true" kv="5" />
    <velocity name="right_w2" joint="right_w2" ctrlrange="-4 4" ctrllimited="true" kv="5" />

    <velocity name="left_s0" joint="left_s0" ctrlrange="-2 2" ctrllimited="true" kv="60"/>
    <velocity name="left_s1" joint="left_s1" ctrlrange="-2 2" ctrllimited="true" kv="50"/>
    <velocity name="left_e0" joint="left_e0" ctrlrange="-2 2" ctrllimited="true" kv="20"/>
    <velocity name="left_e1" joint="left_e1" ctrlrange="-2 2" ctrllimited="true" kv="20"/>
    <velocity name="left_w0" joint="left_w0" ctrlrange="-4 4" ctrllimited="true" kv="5" />
    <velocity name="left_w1" joint="left_w1" ctrlrange="-4 4" ctrllimited="true" kv="5" />
    <velocity name="left_w2" joint="left_w2" ctrlrange="-4 4" ctrllimited="true" kv="5" />

</actuator>
</mujoco>
