<mujoco model="Humanoid">

    <asset>
        <mesh name="l_finger" file="r2d2_meshes/l_finger.stl" />
        <mesh name="l_finger_tip" file="r2d2_meshes/l_finger_tip.stl" />
    </asset>
    <worldbody>
        <body name="broot" pos="0 0 1.0">
            <joint name="root" type="free" />
            <geom size="0.17 0.3" type="cylinder" rgba="0 0 0.8 1" />
            <geom size="0.3 0.1 0.05" pos="0.22 0 -0.05" quat="0.707123 0 0.70709 0" type="box" rgba="1 1 1 1" />
            <geom size="0.05 0.2 0.05" pos="0.22 0 -0.35" type="box" rgba="1 1 1 1" />
            <geom size="0.3 0.1 0.05" pos="-0.22 0 -0.05" quat="0.707123 0 0.70709 0" type="box" rgba="1 1 1 1" />
            <geom size="0.05 0.2 0.05" pos="-0.22 0 -0.35" type="box" rgba="1 1 1 1" />
            <body name="right_front_wheel" pos="0.22 0.133333 -0.435" quat="0.707123 0 0.70709 0">
                <inertial pos="0 0 0" mass="1" diaginertia="1 1 1" />
                <joint name="right_front_wheel_joint" pos="0 0 0" axis="0 0 1" />
                <geom size="0.035 0.05" type="cylinder" />
            </body>
            <body name="right_back_wheel" pos="0.22 -0.133333 -0.435" quat="0.707123 0 0.70709 0">
                <inertial pos="0 0 0" mass="1" diaginertia="1 1 1" />
                <joint name="right_back_wheel_joint" pos="0 0 0" axis="0 0 1" />
                <geom size="0.035 0.05" type="cylinder" />
            </body>
            <body name="left_front_wheel" pos="-0.22 0.133333 -0.435" quat="0.707123 0 0.70709 0">
                <inertial pos="0 0 0" mass="1" diaginertia="1 1 1" />
                <joint name="left_front_wheel_joint" pos="0 0 0" axis="0 0 1" />
                <geom size="0.035 0.05" type="cylinder" />
            </body>
            <body name="left_back_wheel" pos="-0.22 -0.133333 -0.435" quat="0.707123 0 0.70709 0">
                <inertial pos="0 0 0" mass="1" diaginertia="1 1 1" />
                <joint name="left_back_wheel_joint" pos="0 0 0" axis="0 0 1" />
                <geom size="0.035 0.05" type="cylinder" />
            </body>
            <body name="gripper_pole" pos="0 0.19 0.2" quat="0.707123 0 0 0.70709">
                <inertial pos="0 0 0" mass="0.05" diaginertia="1 1 1" />
                <joint name="gripper_extension" pos="0 0 0" axis="1 0 0" type="slide" limited="true" range="-0.38 0" />
                <geom size="0.01 0.1" pos="0.1 0 0" quat="0.707123 0 0.70709 0" type="cylinder" rgba="0.7 0.7 0.7 1" />
                <body name="left_gripper" pos="0.2 0.02 0">
                    <inertial pos="0 0 0" mass="0.1" diaginertia="2 2 2" />
                    <joint name="left_gripper_joint" pos="0 0 0" axis="0 0 1" limited="true" range="0 0.548" />
                    <geom type="mesh" mesh="l_finger" />
                    <geom pos="0.09137 0.00495 0" type="mesh" mesh="l_finger_tip" />
                </body>
                <body name="right_gripper" pos="0.2 -0.02 0">
                    <inertial pos="0 0 0" mass="0.1" diaginertia="2 2 2" />
                    <joint name="right_gripper_joint" pos="0 0 0" axis="0 0 -1" limited="true" range="0 0.548" />
                    <geom quat="4.63268e-05 -1 0 0" type="mesh" mesh="l_finger" />
                    <geom pos="0.09137 0.00495 0" quat="4.63268e-05 -1 0 0" type="mesh" mesh="l_finger_tip" />
                </body>
            </body>
            <body name="head" pos="0 0 0.3">
                <inertial pos="0 0.0110364 0.0110364" quat="0.653281 -0.270598 0.270598 0.653281" mass="11" diaginertia="2.0268 2.0268 2" />
                <joint name="head_swivel" pos="0 0 0" axis="0 0 1" limited="true" range="-0.38 0" />
                <geom size="0.16" rgba="1 1 1 1" type="sphere" />
                <geom size="0.04 0.04 0.04" pos="0 0.1214 0.1214" type="box" rgba="0 0 0.8 1" />
            </body>
        </body>
    </worldbody>

    <actuator>
        <velocity name="left_front_wheel" joint="left_front_wheel_joint" ctrlrange="-10 10" ctrllimited="true" kv="60"/>
        <velocity name="left_back_wheel" joint="left_back_wheel_joint" ctrlrange="-10 10" ctrllimited="true" kv="60"/>
        <velocity name="right_front_wheel" joint="right_front_wheel_joint" ctrlrange="-10 10" ctrllimited="true" kv="60"/>
        <velocity name="right_back_wheel" joint="right_back_wheel_joint" ctrlrange="-10 10" ctrllimited="true" kv="60"/>
    </actuator>

</mujoco>