<mujoco model="template_walker">

  <worldbody>
    <!--<geom name="floor" type="plane" contype="1" conaffinity="1" pos="0 0 0" size="1 1 .2" material="grid" zaxis="0 0 1" friction=".7 .1 .1"/>-->
    <body name="tmjcroot" pos="0 0 1.3" >
      <!--<joint name="root" type="free" />-->
      <joint name="tmjcrootz" axis="0 0 1" type="slide" limited="false" armature="0" damping="0" solimplimit="0 .99 .01"/>
      <joint name="tmjcrootx" axis="1 0 0" type="slide" limited="false" armature="0" damping="0" solimplimit="0 .99 .01"/>
      <joint name="tmjcrooty" axis="0 1 0" type="hinge" limited="false" armature="0" damping="0" solimplimit="0 .99 .01"/>
      <geom name="tmjcroot" material="self" type="capsule" size="0.07 0.3" contype="1" conaffinity="0" friction=".7 .1 .1"/>
      <body name="right_thigh" pos="0 -.05 -0.3">
        <joint name="right_hip" axis="0 -1 0" range="-20 100" damping=".1" armature="0.01" limited="true" solimplimit="0 .99 .01"/>
        <geom name="right_thigh" material="self" type="capsule" pos="0 0 -0.225" size="0.05 0.225" contype="1" conaffinity="0" friction=".7 .1 .1"/>
        <body name="right_leg" pos="0 0 -0.7">
          <joint name="right_knee" axis="0 -1 0" pos="0 0 0.25" range="-150 0" damping=".1" armature="0.01" limited="true" solimplimit="0 .99 .01"/>
          <geom name="right_leg" material="self" type="capsule" size="0.04 0.25" contype="1" conaffinity="0" friction=".7 .1 .1"/>
          <body name="right_foot" pos="0.06 0 -0.25">
            <joint name="right_ankle" axis="0 -1 0" pos="-0.06 0 0" range="-45 45" damping=".1" armature="0.01" limited="true" solimplimit="0 .99 .01"/>
            <geom name="right_foot" material="self" type="capsule" zaxis="1 0 0" size="0.05 0.1" contype="1" conaffinity="0" friction=".7 .1 .1"/>
          </body>
        </body>
      </body>
      <body name="left_thigh" pos="0 .05 -0.3" >
        <joint name="left_hip" axis="0 -1 0" range="-20 100" damping=".1" armature="0.01" limited="true" solimplimit="0 .99 .01"/>
        <geom name="left_thigh" material="self" type="capsule" pos="0 0 -0.225" size="0.05 0.225" contype="1" conaffinity="0" friction=".7 .1 .1"/>
        <body name="left_leg" pos="0 0 -0.7">
          <joint name="left_knee" axis="0 -1 0" pos="0 0 0.25" range="-150 0" damping=".1" armature="0.01" limited="true" solimplimit="0 .99 .01"/>
          <geom name="left_leg" material="self" type="capsule" size="0.04 0.25" contype="1" conaffinity="0" friction=".7 .1 .1"/>
          <body name="left_foot" pos="0.06 0 -0.25">
            <joint name="left_ankle" axis="0 -1 0" pos="-0.06 0 0" range="-45 45" damping=".1" armature="0.01" limited="true" solimplimit="0 .99 .01"/>
            <geom name="left_foot" material="self" type="capsule" zaxis="1 0 0" size="0.05 0.1" contype="1" conaffinity="0" friction=".7 .1 .1"/>
          </body>
        </body>
      </body>
    </body>
  </worldbody>

  <actuator>
    <motor name="right_hip" joint="right_hip" gear="100" ctrlrange="-1 1" ctrllimited="true"/>
    <motor name="right_knee" joint="right_knee" gear="50" ctrlrange="-1 1" ctrllimited="true"/>
    <motor name="right_ankle" joint="right_ankle" gear="20" ctrlrange="-1 1" ctrllimited="true"/>
    <motor name="left_hip" joint="left_hip" gear="100" ctrlrange="-1 1" ctrllimited="true"/>
    <motor name="left_knee" joint="left_knee" gear="50" ctrlrange="-1 1" ctrllimited="true"/>
    <motor name="left_ankle" joint="left_ankle" gear="20" ctrlrange="-1 1" ctrllimited="true"/>
  </actuator>

</mujoco>