<mujoco model="Humanoid">

    <worldbody>
        <body name="tmjcroot" pos="0 0 1.4">
            <joint name="root" type="free" /><!--armature="0"-->
            <geom condim="1" material="matgeom" name="tmjcroot" type="capsule" fromto="0 -0.07 0 0 .07 0"  size="0.07"/>
            <geom condim="1" material="matgeom" name="head" type="sphere" pos="0 0 .19" size=".09"/>
            <geom condim="1" material="matgeom" name="uwaist" type="capsule" fromto="-0.01 -0.06 -0.12 -0.01 .06 -0.12" size="0.06"/>
            <body name="lwaist" pos="-0.01 0 -0.260" quat="1.000 0 -0.002 0" >
                <geom condim="1" material="matgeom" name="lwaist" type="capsule" fromto="0 -0.06 0 0 .06 0"  size="0.06" />
                <joint name="abdomen_z" type="hinge" pos="0 0 0.065" axis="0 0 1" range="-45 45" damping="5" stiffness="20" armature="0.02" limited="true" />
                <joint name="abdomen_y" type="hinge" pos="0 0 0.065" axis="0 1 0" range="-75 30" damping="5" stiffness="10" armature="0.02" limited="true" />
                <body name="pelvis" pos="0 0 -0.165" quat="1.000 0 -0.002 0" >
                    <joint name="abdomen_x" type="hinge" pos="0 0 0.1" axis="1 0 0" range="-35 35" damping="5" stiffness="10" armature="0.02" limited="true" />
                    <geom condim="1" material="matgeom" name="butt" type="capsule" fromto="-0.02 -0.07 0 -0.02 .07 0"  size="0.09" />
                    <body name="right_thigh" pos="0 -0.1 -0.04" >
                        <joint name="right_hip_x" type="hinge" pos="0 0 0" axis="1 0 0" range="-25 5"   damping="5" stiffness="10" armature="0.01" limited="true" />
                        <joint name="right_hip_z" type="hinge" pos="0 0 0" axis="0 0 1" range="-60 35"  damping="5" stiffness="10" armature="0.01" limited="true" />
                        <joint name="right_hip_y" type="hinge" pos="0 0 0" axis="0 1 0" range="-120 20" damping="5" stiffness="20" armature="0.01" limited="true" />
                        <geom condim="1" material="matgeom" name="right_thigh1" type="capsule" fromto="0 0 0 0 0.01 -0.34"  size="0.06" />
                        <body name="right_shin" pos="0 0.01 -0.403" >
                            <joint name="right_knee" type="hinge" pos="0 0 .02" axis="0 -1 0" range="-160 -2" stiffness="1" armature="0.0060" limited="true" damping="1" />
                            <geom condim="1" material="matgeom" name="right_shin1" type="capsule" fromto="0 0 0 0 0 -0.3"   size="0.049" />
                            <body name="right_foot" pos="0 0 -0.39" >
                                <joint name="right_ankle_y" type="hinge" pos="0 0 0.08" axis="0 1 0"   range="-50 50" stiffness="4" armature="0.0008" limited="true" damping="1" />
                                <joint name="right_ankle_x" type="hinge" pos="0 0 0.04" axis="1 0 0.5" range="-50 50" stiffness="1"  armature="0.0006" limited="true" damping="1" />
                                <geom condim="1" material="matgeom" name="right_foot_cap1" type="capsule" fromto="-0.07 -0.02 0 0.14 -0.04 0"  size="0.027" />
                                <geom condim="1" material="matgeom" name="right_foot_cap2" type="capsule" fromto="-0.07 0 0 0.14  0.02 0"  size="0.027" />
                            </body>
                        </body>
                    </body>
                    <body name="left_thigh" pos="0 0.1 -0.04" >
                        <joint name="left_hip_x" type="hinge" pos="0 0 0" axis="-1 0 0" range="-25 5"  damping="5" stiffness="10" armature="0.01" limited="true" />
                        <joint name="left_hip_z" type="hinge" pos="0 0 0" axis="0 0 -1" range="-60 35" damping="5" stiffness="10" armature="0.01" limited="true" />
                        <joint name="left_hip_y" type="hinge" pos="0 0 0" axis="0 1 0" range="-120 20" damping="5" stiffness="20" armature="0.01" limited="true" />
                        <geom condim="1" material="matgeom" name="left_thigh1" type="capsule" fromto="0 0 0 0 -0.01 -0.34"  size="0.06" />
                        <body name="left_shin" pos="0 -0.01 -0.403" >
                            <joint name="left_knee" type="hinge" pos="0 0 .02" axis="0 -1 0" range="-160 -2" stiffness="1" armature="0.0060" limited="true" damping="1" />
                            <geom condim="1" material="matgeom" name="left_shin1" type="capsule" fromto="0 0 0 0 0 -0.3"   size="0.049" />
                            <body name="left_foot" pos="0 0 -0.39" >
                                <joint name="left_ankle_y" type="hinge" pos="0 0 0.08" axis="0 1 0"   range="-50 50"  stiffness="4" armature="0.0008" limited="true" damping="1" />
                                <joint name="left_ankle_x" type="hinge" pos="0 0 0.04" axis="1 0 0.5" range="-50 50"  stiffness="1"  armature="0.0006" limited="true" damping="1" />
                                <geom condim="1" material="matgeom" name="left_foot_cap1" type="capsule" fromto="-0.07 0.02 0 0.14 0.04 0"  size="0.027" />
                                <geom condim="1" material="matgeom" name="left_foot_cap2" type="capsule" fromto="-0.07 0 0 0.14  -0.02 0"  size="0.027" />
                            </body>
                        </body>
                    </body>
                </body>
            </body>
            <body name="right_upper_arm" pos="0 -0.17 0.06" >
                <joint name="right_shoulder1" type="hinge" pos="0 0 0" axis="2 1 1"  range="-85 60" stiffness="1" armature="0.0068" limited="true" damping="1" />
                <joint name="right_shoulder2" type="hinge" pos="0 0 0" axis="0 -1 1" range="-85 60" stiffness="1"  armature="0.0051" limited="true" damping="1" />
                <geom condim="1" material="matgeom" name="right_uarm1" type="capsule" fromto="0 0 0 .16 -0.16 -0.16"  size="0.04 0.16" />
                <body name="right_lower_arm" pos=".18 -0.18 -0.18" >
                    <joint name="right_elbow" type="hinge" pos="0 0 0" axis="0 -1 1" range="-90 50"  stiffness="0" armature="0.0028" limited="true" damping="1" />
                    <geom condim="1" material="matgeom" name="right_larm" type="capsule" fromto="0.01 0.01 0.01 .17 .17 .17"  size="0.031" />
                    <geom condim="1" material="matgeom" name="right_hand" type="sphere" pos=".18 .18 .18"  size="0.04"/>
                </body>
            </body>
            <body name="left_upper_arm" pos="0 0.17 0.06" >
                <joint name="left_shoulder1" type="hinge" pos="0 0 0" axis="2 -1 1" range="-60 85" stiffness="1" armature="0.0068" limited="true" damping="1" />
                <joint name="left_shoulder2" type="hinge" pos="0 0 0" axis="0 1 1" range="-60 85"  stiffness="1" armature="0.0051" limited="true" damping="1" />
                <geom condim="1" material="matgeom" name="left_uarm1" type="capsule" fromto="0 0 0 .16 .16 -0.16"  size="0.04 0.16" />
                <body name="left_lower_arm" pos=".18 .18 -0.18" >
                    <joint name="left_elbow" type="hinge" pos="0 0 0" axis="0 -1 -1" range="-90 50" stiffness="0" armature="0.0028" limited="true" damping="1" />
                    <geom condim="1" material="matgeom" name="left_larm" type="capsule" fromto="0.01 -0.01 0.01 .17 -0.17 .17"  size="0.031" />
                    <geom condim="1" material="matgeom" name="left_hand" type="sphere" pos=".18 -0.18 .18"  size="0.04"/>
                </body>
            </body>
        </body>
    </worldbody>

    <actuator>
        <motor name="abdomen_y"       gear="200" joint="abdomen_y"       ctrlrange="-0.4 .4" ctrllimited="true" />
        <motor name="abdomen_z"       gear="200" joint="abdomen_z"       ctrlrange="-0.4 .4" ctrllimited="true" />
        <motor name="abdomen_x"       gear="200" joint="abdomen_x"       ctrlrange="-0.4 .4" ctrllimited="true" />
        <motor name="right_hip_x"     gear="200" joint="right_hip_x"     ctrlrange="-0.4 .4" ctrllimited="true" />
        <motor name="right_hip_z"     gear="200" joint="right_hip_z"     ctrlrange="-0.4 .4" ctrllimited="true" />
        <motor name="right_hip_y"     gear="600" joint="right_hip_y"     ctrlrange="-0.4 .4" ctrllimited="true" />
        <motor name="right_knee"      gear="400" joint="right_knee"      ctrlrange="-0.4 .4" ctrllimited="true" />
        <motor name="right_ankle_x"   gear="100" joint="right_ankle_x"   ctrlrange="-0.4 .4" ctrllimited="true" />
        <motor name="right_ankle_y"   gear="100" joint="right_ankle_y"   ctrlrange="-0.4 .4" ctrllimited="true" />
        <motor name="left_hip_x"      gear="200" joint="left_hip_x"      ctrlrange="-0.4 .4" ctrllimited="true" />
        <motor name="left_hip_z"      gear="200" joint="left_hip_z"      ctrlrange="-0.4 .4" ctrllimited="true" />
        <motor name="left_hip_y"      gear="600" joint="left_hip_y"      ctrlrange="-0.4 .4" ctrllimited="true" />
        <motor name="left_knee"       gear="400" joint="left_knee"       ctrlrange="-0.4 .4" ctrllimited="true" />
        <motor name="left_ankle_x"    gear="100" joint="left_ankle_x"    ctrlrange="-0.4 .4" ctrllimited="true" />
        <motor name="left_ankle_y"    gear="100" joint="left_ankle_y"    ctrlrange="-0.4 .4" ctrllimited="true" />
        <motor name="right_shoulder1" gear="100" joint="right_shoulder1" ctrlrange="-0.4 .4" ctrllimited="true" />
        <motor name="right_shoulder2" gear="100" joint="right_shoulder2" ctrlrange="-0.4 .4" ctrllimited="true" />
        <motor name="right_elbow"     gear="200" joint="right_elbow"     ctrlrange="-0.4 .4" ctrllimited="true" />
        <motor name="left_shoulder1"  gear="100" joint="left_shoulder1"  ctrlrange="-0.4 .4" ctrllimited="true" />
        <motor name="left_shoulder2"  gear="100" joint="left_shoulder2"  ctrlrange="-0.4 .4" ctrllimited="true" />
        <motor name="left_elbow"      gear="200" joint="left_elbow"      ctrlrange="-0.4 .4" ctrllimited="true" />
    </actuator>

</mujoco>